2022-02-06 10:26:13,084 INFO: logging in using static token
2022-02-06 10:26:13,318 INFO: Shard ID None has sent the IDENTIFY payload.
2022-02-06 10:26:13,425 INFO: Shard ID None has connected to Gateway: ["gateway-prd-main-ds4t",{"micros":68523,"calls":["discord-sessions-blue-prd-2-74",{"micros":62163,"calls":["start_session",{"micros":44435,"calls":["api-prd-main-dpxr",{"micros":36918,"calls":["get_user",{"micros":8384},"add_authorized_ip",{"micros":1431},"get_guilds",{"micros":4991},"coros_wait",{"micros":1}]}]},"guilds_connect",{"micros":2,"calls":[]},"presence_connect",{"micros":5992,"calls":[]}]}]}] (Session ID: 23bd3fec110d0cb0b5a097e5687e55c3).
2022-02-06 10:26:15,502 INFO: 目前登入身份：神奇海螺#3847
2022-02-06 11:31:36,051 INFO: 飄飄的飄飄大仙 out 9又4分之8.7月台[打不出幹話就講出來啊]
2022-02-06 11:31:36,051 WARNING: 'zh-tw' has been deprecated, falling back to 'zh-TW'. This fallback will be removed in a future version.
2022-02-06 11:31:37,309 INFO: Connecting to voice...
2022-02-06 11:31:37,309 INFO: Starting voice handshake... (connection attempt 1)
2022-02-06 11:31:37,489 INFO: Voice handshake complete. Endpoint found us-central8666.discord.media
2022-02-06 11:31:37,600 INFO: selected the voice protocol for use (xsalsa20_poly1305_lite)
2022-02-06 11:31:37,614 INFO: received secret key for voice connection
2022-02-06 11:31:40,507 INFO: Preparing to terminate ffmpeg process 182.
2022-02-06 11:31:40,507 INFO: ffmpeg process 182 successfully terminated with return code of 0.
2022-02-06 11:31:40,693 INFO: The voice handshake is being terminated for Channel ID 428109526550708238 (Guild ID 428109526550708234)
2022-02-06 11:31:40,694 INFO: Disconnecting from voice normally, close code 1000.
2022-02-06 11:59:57,042 INFO: wan in 9又4分之8.7月台[打不出幹話就講出來啊]
2022-02-06 11:59:57,082 INFO: Connecting to voice...
2022-02-06 11:59:57,082 INFO: Starting voice handshake... (connection attempt 1)
2022-02-06 11:59:57,199 INFO: Voice handshake complete. Endpoint found singapore5202.discord.media
2022-02-06 11:59:57,425 ERROR: Exception occurred during Voice Protocol voice server update handler
Traceback (most recent call last):
  File "/opt/virtualenvs/python3/lib/python3.8/site-packages/discord/state.py", line 102, in logging_coroutine
    await coroutine
  File "/opt/virtualenvs/python3/lib/python3.8/site-packages/discord/voice_client.py", line 295, in on_voice_server_update
    await self.ws.close(4000)
AttributeError: 'NoneType' object has no attribute 'close'
2022-02-06 11:59:58,655 INFO: selected the voice protocol for use (xsalsa20_poly1305_lite)
2022-02-06 11:59:58,898 INFO: received secret key for voice connection
2022-02-06 12:00:01,442 INFO: Preparing to terminate ffmpeg process 194.
2022-02-06 12:00:01,443 INFO: ffmpeg process 194 successfully terminated with return code of 0.
2022-02-06 12:00:02,746 INFO: Preparing to terminate ffmpeg process 204.
2022-02-06 12:00:02,747 INFO: ffmpeg process 204 successfully terminated with return code of 0.
2022-02-06 12:00:04,152 INFO: The voice handshake is being terminated for Channel ID 428109526550708238 (Guild ID 428109526550708234)
2022-02-06 12:00:04,153 INFO: Disconnecting from voice normally, close code 1000.
2022-02-06 12:04:26,494 INFO: Maipool in 9又4分之8.7月台[打不出幹話就講出來啊]
2022-02-06 12:04:26,606 INFO: Connecting to voice...
2022-02-06 12:04:26,606 INFO: Starting voice handshake... (connection attempt 1)
2022-02-06 12:04:27,550 INFO: Voice handshake complete. Endpoint found singapore5202.discord.media
2022-02-06 12:04:29,006 INFO: selected the voice protocol for use (xsalsa20_poly1305_lite)
2022-02-06 12:04:29,251 INFO: received secret key for voice connection
2022-02-06 12:04:31,929 INFO: Preparing to terminate ffmpeg process 215.
2022-02-06 12:04:31,929 INFO: ffmpeg process 215 successfully terminated with return code of 0.
2022-02-06 12:04:34,461 INFO: Preparing to terminate ffmpeg process 225.
2022-02-06 12:04:34,463 INFO: ffmpeg process 225 successfully terminated with return code of 0.
2022-02-06 12:04:35,609 INFO: The voice handshake is being terminated for Channel ID 428109526550708238 (Guild ID 428109526550708234)
2022-02-06 12:04:35,610 INFO: Disconnecting from voice normally, close code 1000.
2022-02-06 12:10:47,465 INFO: 飄飄的飄飄大仙 in 9又4分之8.7月台[打不出幹話就講出來啊]
2022-02-06 12:10:49,012 INFO: Connecting to voice...
2022-02-06 12:10:49,012 INFO: Starting voice handshake... (connection attempt 1)
2022-02-06 12:10:49,292 INFO: Voice handshake complete. Endpoint found singapore5202.discord.media
2022-02-06 12:10:50,706 INFO: selected the voice protocol for use (xsalsa20_poly1305_lite)
2022-02-06 12:10:50,944 INFO: received secret key for voice connection
2022-02-06 12:10:53,981 INFO: Preparing to terminate ffmpeg process 265.
2022-02-06 12:10:53,981 INFO: ffmpeg process 265 successfully terminated with return code of 0.
2022-02-06 12:10:55,928 INFO: Preparing to terminate ffmpeg process 275.
2022-02-06 12:10:55,929 INFO: ffmpeg process 275 successfully terminated with return code of 0.
2022-02-06 12:10:57,193 INFO: The voice handshake is being terminated for Channel ID 428109526550708238 (Guild ID 428109526550708234)
2022-02-06 12:10:57,194 INFO: Disconnecting from voice normally, close code 1000.
2022-02-06 12:19:11,543 INFO: 飄飄的飄飄大仙 out 9又4分之8.7月台[打不出幹話就講出來啊]
2022-02-06 12:19:11,544 INFO: Connecting to voice...
2022-02-06 12:19:11,544 INFO: Starting voice handshake... (connection attempt 1)
2022-02-06 12:19:12,643 INFO: Voice handshake complete. Endpoint found singapore5202.discord.media
2022-02-06 12:19:12,876 INFO: 飄飄的飄飄大仙 in 9又4分之8.7月台[打不出幹話就講出來啊]
2022-02-06 12:19:15,276 INFO: selected the voice protocol for use (xsalsa20_poly1305_lite)
2022-02-06 12:19:15,517 INFO: received secret key for voice connection
2022-02-06 12:19:18,379 INFO: Preparing to terminate ffmpeg process 325.
2022-02-06 12:19:18,384 INFO: ffmpeg process 325 successfully terminated with return code of 0.
2022-02-06 12:19:18,557 INFO: The voice handshake is being terminated for Channel ID 428109526550708238 (Guild ID 428109526550708234)
2022-02-06 12:19:18,559 INFO: Disconnecting from voice normally, close code 1000.
2022-02-06 12:19:18,844 INFO: Connecting to voice...
2022-02-06 12:19:18,844 INFO: Starting voice handshake... (connection attempt 1)
2022-02-06 12:19:19,115 INFO: Voice handshake complete. Endpoint found singapore5202.discord.media
2022-02-06 12:19:20,583 INFO: selected the voice protocol for use (xsalsa20_poly1305_lite)
2022-02-06 12:19:20,834 INFO: received secret key for voice connection
2022-02-06 12:19:24,367 INFO: Preparing to terminate ffmpeg process 336.
2022-02-06 12:19:24,367 INFO: ffmpeg process 336 successfully terminated with return code of 0.
2022-02-06 12:19:25,561 INFO: Preparing to terminate ffmpeg process 346.
2022-02-06 12:19:25,561 INFO: ffmpeg process 346 successfully terminated with return code of 0.
2022-02-06 12:19:27,006 INFO: The voice handshake is being terminated for Channel ID 428109526550708238 (Guild ID 428109526550708234)
2022-02-06 12:19:27,007 INFO: Disconnecting from voice normally, close code 1000.
2022-02-06 12:22:50,202 INFO: WeIrdnA in 9又4分之8.7月台[打不出幹話就講出來啊]
2022-02-06 12:22:50,291 WARNING: 'zh-tw' has been deprecated, falling back to 'zh-TW'. This fallback will be removed in a future version.
2022-02-06 12:22:52,724 INFO: Connecting to voice...
2022-02-06 12:22:52,724 INFO: Starting voice handshake... (connection attempt 1)
2022-02-06 12:22:52,990 INFO: Voice handshake complete. Endpoint found singapore5202.discord.media
2022-02-06 12:22:54,433 INFO: selected the voice protocol for use (xsalsa20_poly1305_lite)
2022-02-06 12:22:54,674 INFO: received secret key for voice connection
2022-02-06 12:22:57,091 INFO: Preparing to terminate ffmpeg process 386.
2022-02-06 12:22:57,091 INFO: ffmpeg process 386 successfully terminated with return code of 0.
2022-02-06 12:22:57,680 INFO: Preparing to terminate ffmpeg process 396.
2022-02-06 12:22:57,683 INFO: ffmpeg process 396 successfully terminated with return code of 0.
2022-02-06 12:22:58,728 INFO: The voice handshake is being terminated for Channel ID 428109526550708238 (Guild ID 428109526550708234)
2022-02-06 12:22:58,729 INFO: Disconnecting from voice normally, close code 1000.
2022-02-06 12:23:15,558 INFO: WeIrdnA out 9又4分之8.7月台[打不出幹話就講出來啊]
2022-02-06 12:23:17,465 INFO: Connecting to voice...
2022-02-06 12:23:17,466 INFO: Starting voice handshake... (connection attempt 1)
2022-02-06 12:23:17,731 INFO: Voice handshake complete. Endpoint found singapore5202.discord.media
2022-02-06 12:23:19,173 INFO: selected the voice protocol for use (xsalsa20_poly1305_lite)
2022-02-06 12:23:19,415 INFO: received secret key for voice connection
2022-02-06 12:23:21,651 INFO: Preparing to terminate ffmpeg process 436.
2022-02-06 12:23:21,652 INFO: ffmpeg process 436 successfully terminated with return code of 0.
2022-02-06 12:23:21,844 INFO: The voice handshake is being terminated for Channel ID 428109526550708238 (Guild ID 428109526550708234)
2022-02-06 12:23:21,845 INFO: Disconnecting from voice normally, close code 1000.
2022-02-06 12:23:55,191 INFO: SparkleZ in 9又4分之8.7月台[打不出幹話就講出來啊]
2022-02-06 12:23:55,216 INFO: Connecting to voice...
2022-02-06 12:23:55,216 INFO: Starting voice handshake... (connection attempt 1)
2022-02-06 12:23:55,568 INFO: Voice handshake complete. Endpoint found singapore5202.discord.media
2022-02-06 12:23:57,022 INFO: selected the voice protocol for use (xsalsa20_poly1305_lite)
2022-02-06 12:23:57,263 INFO: received secret key for voice connection
2022-02-06 12:23:59,483 INFO: Preparing to terminate ffmpeg process 447.
2022-02-06 12:23:59,483 INFO: ffmpeg process 447 successfully terminated with return code of 0.
2022-02-06 12:24:01,297 INFO: Preparing to terminate ffmpeg process 457.
2022-02-06 12:24:01,297 INFO: ffmpeg process 457 successfully terminated with return code of 0.
2022-02-06 12:24:02,642 INFO: The voice handshake is being terminated for Channel ID 428109526550708238 (Guild ID 428109526550708234)
2022-02-06 12:24:02,645 INFO: Disconnecting from voice normally, close code 1000.
2022-02-06 12:24:53,375 INFO: SparkleZ out 9又4分之8.7月台[打不出幹話就講出來啊]
2022-02-06 12:24:53,379 INFO: Connecting to voice...
2022-02-06 12:24:53,379 INFO: Starting voice handshake... (connection attempt 1)
2022-02-06 12:24:53,838 INFO: Voice handshake complete. Endpoint found singapore5202.discord.media
2022-02-06 12:24:55,301 INFO: selected the voice protocol for use (xsalsa20_poly1305_lite)
2022-02-06 12:24:55,543 INFO: received secret key for voice connection
2022-02-06 12:24:57,795 INFO: Preparing to terminate ffmpeg process 468.
2022-02-06 12:24:57,795 INFO: ffmpeg process 468 successfully terminated with return code of 0.
2022-02-06 12:24:57,936 INFO: The voice handshake is being terminated for Channel ID 428109526550708238 (Guild ID 428109526550708234)
2022-02-06 12:24:57,937 INFO: Disconnecting from voice normally, close code 1000.
2022-02-06 13:19:59,259 INFO: Got a request to RESUME the websocket.
2022-02-06 13:19:59,333 ERROR: Attempting a reconnect in 0.92s
Traceback (most recent call last):
  File "/opt/virtualenvs/python3/lib/python3.8/site-packages/discord/http.py", line 967, in get_gateway
    data = await self.request(Route('GET', '/gateway'))
  File "/opt/virtualenvs/python3/lib/python3.8/site-packages/discord/http.py", line 216, in request
    raise HTTPException(r, data)
discord.errors.HTTPException: 429 Too Many Requests (error code: 0): You are being blocked from accessing our API temporarily due to exceeding our rate limits frequently. Please read our docs at https://discord.com/developers/docs/topics/rate-limits to prevent this moving forward.

The above exception was the direct cause of the following exception:

Traceback (most recent call last):
  File "/opt/virtualenvs/python3/lib/python3.8/site-packages/discord/client.py", line 563, in connect
    self.ws = await asyncio.wait_for(coro, timeout=60.0)
  File "/usr/lib/python3.8/asyncio/tasks.py", line 494, in wait_for
    return fut.result()
  File "/opt/virtualenvs/python3/lib/python3.8/site-packages/discord/gateway.py", line 305, in from_client
    gateway = gateway or await client.http.get_gateway()
  File "/opt/virtualenvs/python3/lib/python3.8/site-packages/discord/http.py", line 969, in get_gateway
    raise GatewayNotFound() from exc
discord.errors.GatewayNotFound: The gateway to connect to discord was not found.
2022-02-06 13:20:00,322 ERROR: Attempting a reconnect in 2.48s
Traceback (most recent call last):
  File "/opt/virtualenvs/python3/lib/python3.8/site-packages/discord/http.py", line 967, in get_gateway
    data = await self.request(Route('GET', '/gateway'))
  File "/opt/virtualenvs/python3/lib/python3.8/site-packages/discord/http.py", line 216, in request
    raise HTTPException(r, data)
discord.errors.HTTPException: 429 Too Many Requests (error code: 0): You are being blocked from accessing our API temporarily due to exceeding our rate limits frequently. Please read our docs at https://discord.com/developers/docs/topics/rate-limits to prevent this moving forward.

The above exception was the direct cause of the following exception:

Traceback (most recent call last):
  File "/opt/virtualenvs/python3/lib/python3.8/site-packages/discord/client.py", line 563, in connect
    self.ws = await asyncio.wait_for(coro, timeout=60.0)
  File "/usr/lib/python3.8/asyncio/tasks.py", line 494, in wait_for
    return fut.result()
  File "/opt/virtualenvs/python3/lib/python3.8/site-packages/discord/gateway.py", line 305, in from_client
    gateway = gateway or await client.http.get_gateway()
  File "/opt/virtualenvs/python3/lib/python3.8/site-packages/discord/http.py", line 969, in get_gateway
    raise GatewayNotFound() from exc
discord.errors.GatewayNotFound: The gateway to connect to discord was not found.
2022-02-06 13:20:02,852 ERROR: Attempting a reconnect in 7.09s
Traceback (most recent call last):
  File "/opt/virtualenvs/python3/lib/python3.8/site-packages/discord/http.py", line 967, in get_gateway
    data = await self.request(Route('GET', '/gateway'))
  File "/opt/virtualenvs/python3/lib/python3.8/site-packages/discord/http.py", line 216, in request
    raise HTTPException(r, data)
discord.errors.HTTPException: 429 Too Many Requests (error code: 0): You are being blocked from accessing our API temporarily due to exceeding our rate limits frequently. Please read our docs at https://discord.com/developers/docs/topics/rate-limits to prevent this moving forward.

The above exception was the direct cause of the following exception:

Traceback (most recent call last):
  File "/opt/virtualenvs/python3/lib/python3.8/site-packages/discord/client.py", line 563, in connect
    self.ws = await asyncio.wait_for(coro, timeout=60.0)
  File "/usr/lib/python3.8/asyncio/tasks.py", line 494, in wait_for
    return fut.result()
  File "/opt/virtualenvs/python3/lib/python3.8/site-packages/discord/gateway.py", line 305, in from_client
    gateway = gateway or await client.http.get_gateway()
  File "/opt/virtualenvs/python3/lib/python3.8/site-packages/discord/http.py", line 969, in get_gateway
    raise GatewayNotFound() from exc
discord.errors.GatewayNotFound: The gateway to connect to discord was not found.
2022-02-06 13:20:10,029 ERROR: Attempting a reconnect in 5.74s
Traceback (most recent call last):
  File "/opt/virtualenvs/python3/lib/python3.8/site-packages/discord/http.py", line 967, in get_gateway
    data = await self.request(Route('GET', '/gateway'))
  File "/opt/virtualenvs/python3/lib/python3.8/site-packages/discord/http.py", line 216, in request
    raise HTTPException(r, data)
discord.errors.HTTPException: 429 Too Many Requests (error code: 0): You are being blocked from accessing our API temporarily due to exceeding our rate limits frequently. Please read our docs at https://discord.com/developers/docs/topics/rate-limits to prevent this moving forward.

The above exception was the direct cause of the following exception:

Traceback (most recent call last):
  File "/opt/virtualenvs/python3/lib/python3.8/site-packages/discord/client.py", line 563, in connect
    self.ws = await asyncio.wait_for(coro, timeout=60.0)
  File "/usr/lib/python3.8/asyncio/tasks.py", line 494, in wait_for
    return fut.result()
  File "/opt/virtualenvs/python3/lib/python3.8/site-packages/discord/gateway.py", line 305, in from_client
    gateway = gateway or await client.http.get_gateway()
  File "/opt/virtualenvs/python3/lib/python3.8/site-packages/discord/http.py", line 969, in get_gateway
    raise GatewayNotFound() from exc
discord.errors.GatewayNotFound: The gateway to connect to discord was not found.
2022-02-06 13:20:15,842 ERROR: Attempting a reconnect in 14.66s
Traceback (most recent call last):
  File "/opt/virtualenvs/python3/lib/python3.8/site-packages/discord/http.py", line 967, in get_gateway
    data = await self.request(Route('GET', '/gateway'))
  File "/opt/virtualenvs/python3/lib/python3.8/site-packages/discord/http.py", line 216, in request
    raise HTTPException(r, data)
discord.errors.HTTPException: 429 Too Many Requests (error code: 0): You are being blocked from accessing our API temporarily due to exceeding our rate limits frequently. Please read our docs at https://discord.com/developers/docs/topics/rate-limits to prevent this moving forward.

The above exception was the direct cause of the following exception:

Traceback (most recent call last):
  File "/opt/virtualenvs/python3/lib/python3.8/site-packages/discord/client.py", line 563, in connect
    self.ws = await asyncio.wait_for(coro, timeout=60.0)
  File "/usr/lib/python3.8/asyncio/tasks.py", line 494, in wait_for
    return fut.result()
  File "/opt/virtualenvs/python3/lib/python3.8/site-packages/discord/gateway.py", line 305, in from_client
    gateway = gateway or await client.http.get_gateway()
  File "/opt/virtualenvs/python3/lib/python3.8/site-packages/discord/http.py", line 969, in get_gateway
    raise GatewayNotFound() from exc
discord.errors.GatewayNotFound: The gateway to connect to discord was not found.
2022-02-06 13:20:30,579 ERROR: Attempting a reconnect in 53.08s
Traceback (most recent call last):
  File "/opt/virtualenvs/python3/lib/python3.8/site-packages/discord/http.py", line 967, in get_gateway
    data = await self.request(Route('GET', '/gateway'))
  File "/opt/virtualenvs/python3/lib/python3.8/site-packages/discord/http.py", line 216, in request
    raise HTTPException(r, data)
discord.errors.HTTPException: 429 Too Many Requests (error code: 0): You are being blocked from accessing our API temporarily due to exceeding our rate limits frequently. Please read our docs at https://discord.com/developers/docs/topics/rate-limits to prevent this moving forward.

The above exception was the direct cause of the following exception:

Traceback (most recent call last):
  File "/opt/virtualenvs/python3/lib/python3.8/site-packages/discord/client.py", line 563, in connect
    self.ws = await asyncio.wait_for(coro, timeout=60.0)
  File "/usr/lib/python3.8/asyncio/tasks.py", line 494, in wait_for
    return fut.result()
  File "/opt/virtualenvs/python3/lib/python3.8/site-packages/discord/gateway.py", line 305, in from_client
    gateway = gateway or await client.http.get_gateway()
  File "/opt/virtualenvs/python3/lib/python3.8/site-packages/discord/http.py", line 969, in get_gateway
    raise GatewayNotFound() from exc
discord.errors.GatewayNotFound: The gateway to connect to discord was not found.
2022-02-06 13:21:23,782 ERROR: Attempting a reconnect in 71.00s
Traceback (most recent call last):
  File "/opt/virtualenvs/python3/lib/python3.8/site-packages/discord/http.py", line 967, in get_gateway
    data = await self.request(Route('GET', '/gateway'))
  File "/opt/virtualenvs/python3/lib/python3.8/site-packages/discord/http.py", line 216, in request
    raise HTTPException(r, data)
discord.errors.HTTPException: 429 Too Many Requests (error code: 0): You are being blocked from accessing our API temporarily due to exceeding our rate limits frequently. Please read our docs at https://discord.com/developers/docs/topics/rate-limits to prevent this moving forward.

The above exception was the direct cause of the following exception:

Traceback (most recent call last):
  File "/opt/virtualenvs/python3/lib/python3.8/site-packages/discord/client.py", line 563, in connect
    self.ws = await asyncio.wait_for(coro, timeout=60.0)
  File "/usr/lib/python3.8/asyncio/tasks.py", line 494, in wait_for
    return fut.result()
  File "/opt/virtualenvs/python3/lib/python3.8/site-packages/discord/gateway.py", line 305, in from_client
    gateway = gateway or await client.http.get_gateway()
  File "/opt/virtualenvs/python3/lib/python3.8/site-packages/discord/http.py", line 969, in get_gateway
    raise GatewayNotFound() from exc
discord.errors.GatewayNotFound: The gateway to connect to discord was not found.
2022-02-06 13:22:34,924 ERROR: Attempting a reconnect in 53.04s
Traceback (most recent call last):
  File "/opt/virtualenvs/python3/lib/python3.8/site-packages/discord/http.py", line 967, in get_gateway
    data = await self.request(Route('GET', '/gateway'))
  File "/opt/virtualenvs/python3/lib/python3.8/site-packages/discord/http.py", line 216, in request
    raise HTTPException(r, data)
discord.errors.HTTPException: 429 Too Many Requests (error code: 0): You are being blocked from accessing our API temporarily due to exceeding our rate limits frequently. Please read our docs at https://discord.com/developers/docs/topics/rate-limits to prevent this moving forward.

The above exception was the direct cause of the following exception:

Traceback (most recent call last):
  File "/opt/virtualenvs/python3/lib/python3.8/site-packages/discord/client.py", line 563, in connect
    self.ws = await asyncio.wait_for(coro, timeout=60.0)
  File "/usr/lib/python3.8/asyncio/tasks.py", line 494, in wait_for
    return fut.result()
  File "/opt/virtualenvs/python3/lib/python3.8/site-packages/discord/gateway.py", line 305, in from_client
    gateway = gateway or await client.http.get_gateway()
  File "/opt/virtualenvs/python3/lib/python3.8/site-packages/discord/http.py", line 969, in get_gateway
    raise GatewayNotFound() from exc
discord.errors.GatewayNotFound: The gateway to connect to discord was not found.
2022-02-06 13:23:28,078 ERROR: Attempting a reconnect in 256.94s
Traceback (most recent call last):
  File "/opt/virtualenvs/python3/lib/python3.8/site-packages/discord/http.py", line 967, in get_gateway
    data = await self.request(Route('GET', '/gateway'))
  File "/opt/virtualenvs/python3/lib/python3.8/site-packages/discord/http.py", line 216, in request
    raise HTTPException(r, data)
discord.errors.HTTPException: 429 Too Many Requests (error code: 0): You are being blocked from accessing our API temporarily due to exceeding our rate limits frequently. Please read our docs at https://discord.com/developers/docs/topics/rate-limits to prevent this moving forward.

The above exception was the direct cause of the following exception:

Traceback (most recent call last):
  File "/opt/virtualenvs/python3/lib/python3.8/site-packages/discord/client.py", line 563, in connect
    self.ws = await asyncio.wait_for(coro, timeout=60.0)
  File "/usr/lib/python3.8/asyncio/tasks.py", line 494, in wait_for
    return fut.result()
  File "/opt/virtualenvs/python3/lib/python3.8/site-packages/discord/gateway.py", line 305, in from_client
    gateway = gateway or await client.http.get_gateway()
  File "/opt/virtualenvs/python3/lib/python3.8/site-packages/discord/http.py", line 969, in get_gateway
    raise GatewayNotFound() from exc
discord.errors.GatewayNotFound: The gateway to connect to discord was not found.
2022-02-06 13:27:45,191 ERROR: Attempting a reconnect in 192.91s
Traceback (most recent call last):
  File "/opt/virtualenvs/python3/lib/python3.8/site-packages/discord/http.py", line 967, in get_gateway
    data = await self.request(Route('GET', '/gateway'))
  File "/opt/virtualenvs/python3/lib/python3.8/site-packages/discord/http.py", line 216, in request
    raise HTTPException(r, data)
discord.errors.HTTPException: 429 Too Many Requests (error code: 0): You are being blocked from accessing our API temporarily due to exceeding our rate limits frequently. Please read our docs at https://discord.com/developers/docs/topics/rate-limits to prevent this moving forward.

The above exception was the direct cause of the following exception:

Traceback (most recent call last):
  File "/opt/virtualenvs/python3/lib/python3.8/site-packages/discord/client.py", line 563, in connect
    self.ws = await asyncio.wait_for(coro, timeout=60.0)
  File "/usr/lib/python3.8/asyncio/tasks.py", line 494, in wait_for
    return fut.result()
  File "/opt/virtualenvs/python3/lib/python3.8/site-packages/discord/gateway.py", line 305, in from_client
    gateway = gateway or await client.http.get_gateway()
  File "/opt/virtualenvs/python3/lib/python3.8/site-packages/discord/http.py", line 969, in get_gateway
    raise GatewayNotFound() from exc
discord.errors.GatewayNotFound: The gateway to connect to discord was not found.
2022-02-06 13:30:58,270 ERROR: Attempting a reconnect in 757.01s
Traceback (most recent call last):
  File "/opt/virtualenvs/python3/lib/python3.8/site-packages/discord/http.py", line 967, in get_gateway
    data = await self.request(Route('GET', '/gateway'))
  File "/opt/virtualenvs/python3/lib/python3.8/site-packages/discord/http.py", line 216, in request
    raise HTTPException(r, data)
discord.errors.HTTPException: 429 Too Many Requests (error code: 0): You are being blocked from accessing our API temporarily due to exceeding our rate limits frequently. Please read our docs at https://discord.com/developers/docs/topics/rate-limits to prevent this moving forward.

The above exception was the direct cause of the following exception:

Traceback (most recent call last):
  File "/opt/virtualenvs/python3/lib/python3.8/site-packages/discord/client.py", line 563, in connect
    self.ws = await asyncio.wait_for(coro, timeout=60.0)
  File "/usr/lib/python3.8/asyncio/tasks.py", line 494, in wait_for
    return fut.result()
  File "/opt/virtualenvs/python3/lib/python3.8/site-packages/discord/gateway.py", line 305, in from_client
    gateway = gateway or await client.http.get_gateway()
  File "/opt/virtualenvs/python3/lib/python3.8/site-packages/discord/http.py", line 969, in get_gateway
    raise GatewayNotFound() from exc
discord.errors.GatewayNotFound: The gateway to connect to discord was not found.
2022-02-06 13:43:35,445 ERROR: Attempting a reconnect in 793.81s
Traceback (most recent call last):
  File "/opt/virtualenvs/python3/lib/python3.8/site-packages/discord/http.py", line 967, in get_gateway
    data = await self.request(Route('GET', '/gateway'))
  File "/opt/virtualenvs/python3/lib/python3.8/site-packages/discord/http.py", line 216, in request
    raise HTTPException(r, data)
discord.errors.HTTPException: 429 Too Many Requests (error code: 0): You are being blocked from accessing our API temporarily due to exceeding our rate limits frequently. Please read our docs at https://discord.com/developers/docs/topics/rate-limits to prevent this moving forward.

The above exception was the direct cause of the following exception:

Traceback (most recent call last):
  File "/opt/virtualenvs/python3/lib/python3.8/site-packages/discord/client.py", line 563, in connect
    self.ws = await asyncio.wait_for(coro, timeout=60.0)
  File "/usr/lib/python3.8/asyncio/tasks.py", line 494, in wait_for
    return fut.result()
  File "/opt/virtualenvs/python3/lib/python3.8/site-packages/discord/gateway.py", line 305, in from_client
    gateway = gateway or await client.http.get_gateway()
  File "/opt/virtualenvs/python3/lib/python3.8/site-packages/discord/http.py", line 969, in get_gateway
    raise GatewayNotFound() from exc
discord.errors.GatewayNotFound: The gateway to connect to discord was not found.
2022-02-06 13:56:49,414 ERROR: Attempting a reconnect in 528.88s
Traceback (most recent call last):
  File "/opt/virtualenvs/python3/lib/python3.8/site-packages/discord/http.py", line 967, in get_gateway
    data = await self.request(Route('GET', '/gateway'))
  File "/opt/virtualenvs/python3/lib/python3.8/site-packages/discord/http.py", line 216, in request
    raise HTTPException(r, data)
discord.errors.HTTPException: 429 Too Many Requests (error code: 0): You are being blocked from accessing our API temporarily due to exceeding our rate limits frequently. Please read our docs at https://discord.com/developers/docs/topics/rate-limits to prevent this moving forward.

The above exception was the direct cause of the following exception:

Traceback (most recent call last):
  File "/opt/virtualenvs/python3/lib/python3.8/site-packages/discord/client.py", line 563, in connect
    self.ws = await asyncio.wait_for(coro, timeout=60.0)
  File "/usr/lib/python3.8/asyncio/tasks.py", line 494, in wait_for
    return fut.result()
  File "/opt/virtualenvs/python3/lib/python3.8/site-packages/discord/gateway.py", line 305, in from_client
    gateway = gateway or await client.http.get_gateway()
  File "/opt/virtualenvs/python3/lib/python3.8/site-packages/discord/http.py", line 969, in get_gateway
    raise GatewayNotFound() from exc
discord.errors.GatewayNotFound: The gateway to connect to discord was not found.
2022-02-06 14:05:38,459 ERROR: Attempting a reconnect in 108.05s
Traceback (most recent call last):
  File "/opt/virtualenvs/python3/lib/python3.8/site-packages/discord/http.py", line 967, in get_gateway
    data = await self.request(Route('GET', '/gateway'))
  File "/opt/virtualenvs/python3/lib/python3.8/site-packages/discord/http.py", line 216, in request
    raise HTTPException(r, data)
discord.errors.HTTPException: 429 Too Many Requests (error code: 0): You are being blocked from accessing our API temporarily due to exceeding our rate limits frequently. Please read our docs at https://discord.com/developers/docs/topics/rate-limits to prevent this moving forward.

The above exception was the direct cause of the following exception:

Traceback (most recent call last):
  File "/opt/virtualenvs/python3/lib/python3.8/site-packages/discord/client.py", line 563, in connect
    self.ws = await asyncio.wait_for(coro, timeout=60.0)
  File "/usr/lib/python3.8/asyncio/tasks.py", line 494, in wait_for
    return fut.result()
  File "/opt/virtualenvs/python3/lib/python3.8/site-packages/discord/gateway.py", line 305, in from_client
    gateway = gateway or await client.http.get_gateway()
  File "/opt/virtualenvs/python3/lib/python3.8/site-packages/discord/http.py", line 969, in get_gateway
    raise GatewayNotFound() from exc
discord.errors.GatewayNotFound: The gateway to connect to discord was not found.
2022-02-06 14:07:26,675 ERROR: Attempting a reconnect in 659.72s
Traceback (most recent call last):
  File "/opt/virtualenvs/python3/lib/python3.8/site-packages/discord/http.py", line 967, in get_gateway
    data = await self.request(Route('GET', '/gateway'))
  File "/opt/virtualenvs/python3/lib/python3.8/site-packages/discord/http.py", line 216, in request
    raise HTTPException(r, data)
discord.errors.HTTPException: 429 Too Many Requests (error code: 0): You are being blocked from accessing our API temporarily due to exceeding our rate limits frequently. Please read our docs at https://discord.com/developers/docs/topics/rate-limits to prevent this moving forward.

The above exception was the direct cause of the following exception:

Traceback (most recent call last):
  File "/opt/virtualenvs/python3/lib/python3.8/site-packages/discord/client.py", line 563, in connect
    self.ws = await asyncio.wait_for(coro, timeout=60.0)
  File "/usr/lib/python3.8/asyncio/tasks.py", line 494, in wait_for
    return fut.result()
  File "/opt/virtualenvs/python3/lib/python3.8/site-packages/discord/gateway.py", line 305, in from_client
    gateway = gateway or await client.http.get_gateway()
  File "/opt/virtualenvs/python3/lib/python3.8/site-packages/discord/http.py", line 969, in get_gateway
    raise GatewayNotFound() from exc
discord.errors.GatewayNotFound: The gateway to connect to discord was not found.
2022-02-06 14:18:26,563 ERROR: Attempting a reconnect in 413.74s
Traceback (most recent call last):
  File "/opt/virtualenvs/python3/lib/python3.8/site-packages/discord/http.py", line 967, in get_gateway
    data = await self.request(Route('GET', '/gateway'))
  File "/opt/virtualenvs/python3/lib/python3.8/site-packages/discord/http.py", line 216, in request
    raise HTTPException(r, data)
discord.errors.HTTPException: 429 Too Many Requests (error code: 0): You are being blocked from accessing our API temporarily due to exceeding our rate limits frequently. Please read our docs at https://discord.com/developers/docs/topics/rate-limits to prevent this moving forward.

The above exception was the direct cause of the following exception:

Traceback (most recent call last):
  File "/opt/virtualenvs/python3/lib/python3.8/site-packages/discord/client.py", line 563, in connect
    self.ws = await asyncio.wait_for(coro, timeout=60.0)
  File "/usr/lib/python3.8/asyncio/tasks.py", line 494, in wait_for
    return fut.result()
  File "/opt/virtualenvs/python3/lib/python3.8/site-packages/discord/gateway.py", line 305, in from_client
    gateway = gateway or await client.http.get_gateway()
  File "/opt/virtualenvs/python3/lib/python3.8/site-packages/discord/http.py", line 969, in get_gateway
    raise GatewayNotFound() from exc
discord.errors.GatewayNotFound: The gateway to connect to discord was not found.
2022-02-06 14:22:13,789 INFO: logging in using static token
2022-02-06 14:22:13,884 INFO: Cleaning up tasks.
2022-02-06 14:22:13,885 INFO: Closing the event loop.
2022-02-06 14:26:00,150 INFO: logging in using static token
2022-02-06 14:26:00,235 INFO: Cleaning up tasks.
2022-02-06 14:26:00,236 INFO: Closing the event loop.
2022-02-06 14:36:54,171 INFO: logging in using static token
2022-02-06 14:36:54,430 INFO: Shard ID None has sent the IDENTIFY payload.
2022-02-06 14:36:54,585 INFO: Shard ID None has connected to Gateway: ["gateway-prd-main-0c1x",{"micros":115449,"calls":["discord-sessions-blue-prd-2-125",{"micros":114166,"calls":["start_session",{"micros":99362,"calls":["api-prd-main-k21x",{"micros":63692,"calls":["get_user",{"micros":4734},"add_authorized_ip",{"micros":6927},"get_guilds",{"micros":14572},"coros_wait",{"micros":1}]}]},"guilds_connect",{"micros":3,"calls":[]},"presence_connect",{"micros":1,"calls":[]}]}]}] (Session ID: cc8dc465eef329664e4e475a97819a18).
2022-02-06 14:36:56,693 INFO: 目前登入身份：神奇海螺#3847
2022-02-06 14:49:34,960 INFO: Chi in 9又4分之8.7月台[廁所]
2022-02-06 14:49:35,099 INFO: Connecting to voice...
2022-02-06 14:49:35,099 INFO: Starting voice handshake... (connection attempt 1)
2022-02-06 14:49:35,373 INFO: Voice handshake complete. Endpoint found singapore5156.discord.media
2022-02-06 14:49:35,876 INFO: 飄飄的飄飄大仙 in 9又4分之8.7月台[廁所]
2022-02-06 14:49:36,796 INFO: selected the voice protocol for use (xsalsa20_poly1305_lite)
2022-02-06 14:49:37,034 INFO: received secret key for voice connection
2022-02-06 14:49:38,915 INFO: Preparing to terminate ffmpeg process 155.
2022-02-06 14:49:38,917 INFO: ffmpeg process 155 successfully terminated with return code of 0.
2022-02-06 14:49:38,962 INFO: 飄飄的飄飄大仙 in 9又4分之8.7月台[打不出幹話就講出來啊]
2022-02-06 14:49:41,101 INFO: Preparing to terminate ffmpeg process 176.
2022-02-06 14:49:41,102 INFO: ffmpeg process 176 has not terminated. Waiting to terminate...
2022-02-06 14:49:41,103 INFO: ffmpeg process 176 should have terminated with a return code of -9.
2022-02-06 14:49:41,567 INFO: Preparing to terminate ffmpeg process 166.
2022-02-06 14:49:41,568 INFO: ffmpeg process 166 successfully terminated with return code of 0.
2022-02-06 14:49:41,952 INFO: Chi in 9又4分之8.7月台[打不出幹話就講出來啊]
2022-02-06 14:49:42,715 INFO: The voice handshake is being terminated for Channel ID 939895603851325470 (Guild ID 428109526550708234)
2022-02-06 14:49:42,715 INFO: Disconnecting from voice normally, close code 1000.
2022-02-06 14:49:42,980 INFO: Connecting to voice...
2022-02-06 14:49:42,980 INFO: Starting voice handshake... (connection attempt 1)
2022-02-06 14:49:43,252 INFO: Voice handshake complete. Endpoint found singapore5202.discord.media
2022-02-06 14:49:44,320 INFO: Preparing to terminate ffmpeg process 178.
2022-02-06 14:49:44,321 INFO: ffmpeg process 178 successfully terminated with return code of -9.
2022-02-06 14:49:44,755 INFO: selected the voice protocol for use (xsalsa20_poly1305_lite)
2022-02-06 14:49:45,009 INFO: received secret key for voice connection
2022-02-06 14:49:47,402 INFO: Preparing to terminate ffmpeg process 179.
2022-02-06 14:49:47,402 INFO: ffmpeg process 179 successfully terminated with return code of 0.
2022-02-06 14:49:49,360 INFO: Preparing to terminate ffmpeg process 189.
2022-02-06 14:49:49,361 INFO: ffmpeg process 189 successfully terminated with return code of 0.
2022-02-06 14:49:50,547 INFO: The voice handshake is being terminated for Channel ID 428109526550708238 (Guild ID 428109526550708234)
2022-02-06 14:49:50,548 INFO: Disconnecting from voice normally, close code 1000.
2022-02-06 14:58:02,152 INFO: Websocket closed with 1006, attempting a reconnect.
2022-02-06 14:58:02,153 INFO: Got a request to RESUME the websocket.
2022-02-06 14:58:02,314 INFO: Shard ID None has sent the RESUME payload.
2022-02-06 14:58:02,354 INFO: Shard ID None has successfully RESUMED session cc8dc465eef329664e4e475a97819a18 under trace ["gateway-prd-main-wjb4",{"micros":598,"calls":["discord-sessions-blue-prd-2-125",{"micros":31}]}].
2022-02-06 16:18:57,954 INFO: Got a request to RESUME the websocket.
2022-02-06 16:18:58,119 INFO: Shard ID None has sent the RESUME payload.
2022-02-06 16:18:58,167 INFO: Shard ID None has successfully RESUMED session cc8dc465eef329664e4e475a97819a18 under trace ["gateway-prd-main-cnvm",{"micros":5110,"calls":["discord-sessions-blue-prd-2-125",{"micros":21}]}].
2022-02-06 16:30:43,314 INFO: 楓夜 out 9又4分之8.7月台[打不出幹話就講出來啊]
2022-02-06 16:30:43,315 INFO: Connecting to voice...
2022-02-06 16:30:43,315 INFO: Starting voice handshake... (connection attempt 1)
2022-02-06 16:30:43,589 INFO: Voice handshake complete. Endpoint found singapore5202.discord.media
2022-02-06 16:30:45,059 INFO: selected the voice protocol for use (xsalsa20_poly1305_lite)
2022-02-06 16:30:45,308 INFO: received secret key for voice connection
2022-02-06 16:30:47,259 INFO: Preparing to terminate ffmpeg process 233.
2022-02-06 16:30:47,260 INFO: ffmpeg process 233 successfully terminated with return code of 0.
2022-02-06 16:30:47,372 INFO: The voice handshake is being terminated for Channel ID 428109526550708238 (Guild ID 428109526550708234)
2022-02-06 16:30:47,373 INFO: Disconnecting from voice normally, close code 1000.
2022-02-06 16:31:52,390 INFO: wawa的n out 9又4分之8.7月台[打不出幹話就講出來啊]
2022-02-06 16:31:52,391 WARNING: 'zh-tw' has been deprecated, falling back to 'zh-TW'. This fallback will be removed in a future version.
2022-02-06 16:31:53,399 INFO: Connecting to voice...
2022-02-06 16:31:53,399 INFO: Starting voice handshake... (connection attempt 1)
2022-02-06 16:31:53,674 INFO: Voice handshake complete. Endpoint found singapore5202.discord.media
2022-02-06 16:31:55,113 INFO: selected the voice protocol for use (xsalsa20_poly1305_lite)
2022-02-06 16:31:55,278 INFO: BunnyplayGG out 9又4分之8.7月台[打不出幹話就講出來啊]
2022-02-06 16:31:55,359 INFO: received secret key for voice connection
2022-02-06 16:31:56,319 INFO: MaiMai的Pool out 9又4分之8.7月台[打不出幹話就講出來啊]
2022-02-06 16:31:56,322 WARNING: 'zh-tw' has been deprecated, falling back to 'zh-TW'. This fallback will be removed in a future version.
2022-02-06 16:31:57,552 INFO: Preparing to terminate ffmpeg process 273.
2022-02-06 16:31:57,555 INFO: ffmpeg process 273 successfully terminated with return code of 0.
2022-02-06 16:31:57,664 INFO: The voice handshake is being terminated for Channel ID 428109526550708238 (Guild ID 428109526550708234)
2022-02-06 16:31:57,666 INFO: Disconnecting from voice normally, close code 1000.
2022-02-06 16:31:58,161 INFO: Connecting to voice...
2022-02-06 16:31:58,161 INFO: Starting voice handshake... (connection attempt 1)
2022-02-06 16:31:58,430 INFO: Voice handshake complete. Endpoint found singapore5202.discord.media
2022-02-06 16:31:59,887 INFO: selected the voice protocol for use (xsalsa20_poly1305_lite)
2022-02-06 16:32:00,135 INFO: received secret key for voice connection
2022-02-06 16:32:00,881 INFO: Preparing to terminate ffmpeg process 323.
2022-02-06 16:32:00,881 INFO: ffmpeg process 323 has not terminated. Waiting to terminate...
2022-02-06 16:32:00,882 INFO: ffmpeg process 323 should have terminated with a return code of -9.
2022-02-06 16:32:02,450 INFO: Preparing to terminate ffmpeg process 313.
2022-02-06 16:32:02,450 INFO: ffmpeg process 313 successfully terminated with return code of 0.
2022-02-06 16:32:02,559 INFO: The voice handshake is being terminated for Channel ID 428109526550708238 (Guild ID 428109526550708234)
2022-02-06 16:32:02,560 INFO: Disconnecting from voice normally, close code 1000.
2022-02-06 16:32:18,591 INFO: 飄飄的飄飄大仙 out 9又4分之8.7月台[打不出幹話就講出來啊]
2022-02-06 16:32:18,591 INFO: Connecting to voice...
2022-02-06 16:32:18,591 INFO: Starting voice handshake... (connection attempt 1)
2022-02-06 16:32:19,012 INFO: Voice handshake complete. Endpoint found singapore5202.discord.media
2022-02-06 16:32:20,038 INFO: 飄飄的飄飄大仙 in 9又4分之8.7月台[打不出幹話就講出來啊]
2022-02-06 16:32:20,441 INFO: selected the voice protocol for use (xsalsa20_poly1305_lite)
2022-02-06 16:32:20,684 INFO: received secret key for voice connection
2022-02-06 16:32:23,537 INFO: Preparing to terminate ffmpeg process 325.
2022-02-06 16:32:23,539 INFO: ffmpeg process 325 successfully terminated with return code of 0.
2022-02-06 16:32:23,727 INFO: The voice handshake is being terminated for Channel ID 428109526550708238 (Guild ID 428109526550708234)
2022-02-06 16:32:23,728 INFO: Disconnecting from voice normally, close code 1000.
2022-02-06 16:32:24,071 INFO: Connecting to voice...
2022-02-06 16:32:24,071 INFO: Starting voice handshake... (connection attempt 1)
2022-02-06 16:32:24,340 INFO: Voice handshake complete. Endpoint found singapore5202.discord.media
2022-02-06 16:32:25,780 INFO: selected the voice protocol for use (xsalsa20_poly1305_lite)
2022-02-06 16:32:26,024 INFO: received secret key for voice connection
2022-02-06 16:32:29,052 INFO: Preparing to terminate ffmpeg process 336.
2022-02-06 16:32:29,052 INFO: ffmpeg process 336 successfully terminated with return code of 0.
2022-02-06 16:32:31,233 INFO: Preparing to terminate ffmpeg process 346.
2022-02-06 16:32:31,235 INFO: ffmpeg process 346 successfully terminated with return code of 0.
2022-02-06 16:32:32,260 INFO: The voice handshake is being terminated for Channel ID 428109526550708238 (Guild ID 428109526550708234)
2022-02-06 16:32:32,261 INFO: Disconnecting from voice normally, close code 1000.
2022-02-06 16:41:08,106 INFO: Got a request to RESUME the websocket.
2022-02-06 16:41:08,304 INFO: Shard ID None has sent the RESUME payload.
2022-02-06 16:41:08,343 INFO: Shard ID None has successfully RESUMED session cc8dc465eef329664e4e475a97819a18 under trace ["gateway-prd-main-hf9c",{"micros":949,"calls":["discord-sessions-blue-prd-2-125",{"micros":21}]}].
2022-02-06 16:52:28,093 INFO: Chi out 9又4分之8.7月台[打不出幹話就講出來啊]
2022-02-06 16:52:28,094 INFO: Connecting to voice...
2022-02-06 16:52:28,094 INFO: Starting voice handshake... (connection attempt 1)
2022-02-06 16:52:29,173 INFO: Voice handshake complete. Endpoint found singapore5202.discord.media
2022-02-06 16:52:30,636 INFO: selected the voice protocol for use (xsalsa20_poly1305_lite)
2022-02-06 16:52:30,879 INFO: received secret key for voice connection
2022-02-06 16:52:32,655 INFO: Preparing to terminate ffmpeg process 376.
2022-02-06 16:52:32,657 INFO: ffmpeg process 376 successfully terminated with return code of 0.
2022-02-06 16:52:32,803 INFO: The voice handshake is being terminated for Channel ID 428109526550708238 (Guild ID 428109526550708234)
2022-02-06 16:52:32,804 INFO: Disconnecting from voice normally, close code 1000.
2022-02-06 16:52:54,678 INFO: Fiven-chung out 9又4分之8.7月台[打不出幹話就講出來啊]
2022-02-06 16:52:54,678 INFO: Connecting to voice...
2022-02-06 16:52:54,678 INFO: Starting voice handshake... (connection attempt 1)
2022-02-06 16:52:55,013 INFO: Voice handshake complete. Endpoint found singapore5202.discord.media
2022-02-06 16:52:56,461 INFO: selected the voice protocol for use (xsalsa20_poly1305_lite)
2022-02-06 16:52:56,704 INFO: received secret key for voice connection
2022-02-06 16:52:58,838 INFO: Preparing to terminate ffmpeg process 387.
2022-02-06 16:52:58,838 INFO: ffmpeg process 387 successfully terminated with return code of 0.
2022-02-06 16:52:59,033 INFO: The voice handshake is being terminated for Channel ID 428109526550708238 (Guild ID 428109526550708234)
2022-02-06 16:52:59,038 INFO: Disconnecting from voice normally, close code 1000.
2022-02-06 16:53:26,530 INFO: KyrieR out 9又4分之8.7月台[打不出幹話就講出來啊]
2022-02-06 16:53:26,530 INFO: Connecting to voice...
2022-02-06 16:53:26,531 INFO: Starting voice handshake... (connection attempt 1)
2022-02-06 16:53:26,950 INFO: Voice handshake complete. Endpoint found singapore5202.discord.media
2022-02-06 16:53:28,452 INFO: selected the voice protocol for use (xsalsa20_poly1305_lite)
2022-02-06 16:53:28,712 INFO: received secret key for voice connection
2022-02-06 16:53:30,738 INFO: Preparing to terminate ffmpeg process 398.
2022-02-06 16:53:30,739 INFO: ffmpeg process 398 successfully terminated with return code of 0.
2022-02-06 16:53:30,860 INFO: The voice handshake is being terminated for Channel ID 428109526550708238 (Guild ID 428109526550708234)
2022-02-06 16:53:30,861 INFO: Disconnecting from voice normally, close code 1000.
2022-02-06 16:54:52,116 INFO: 飄飄的飄飄大仙 out 9又4分之8.7月台[打不出幹話就講出來啊]
2022-02-06 16:54:52,117 INFO: Connecting to voice...
2022-02-06 16:54:52,117 INFO: Starting voice handshake... (connection attempt 1)
2022-02-06 16:54:52,288 INFO: Voice handshake complete. Endpoint found us-central1469.discord.media
2022-02-06 16:54:52,422 INFO: selected the voice protocol for use (xsalsa20_poly1305_lite)
2022-02-06 16:54:52,440 INFO: received secret key for voice connection
2022-02-06 16:54:55,301 INFO: Preparing to terminate ffmpeg process 409.
2022-02-06 16:54:55,302 INFO: ffmpeg process 409 successfully terminated with return code of 0.
2022-02-06 16:54:55,485 INFO: The voice handshake is being terminated for Channel ID 428109526550708238 (Guild ID 428109526550708234)
2022-02-06 16:54:55,486 INFO: Disconnecting from voice normally, close code 1000.
2022-02-06 19:01:52,336 INFO: Got a request to RESUME the websocket.
2022-02-06 19:01:52,497 INFO: Shard ID None has sent the RESUME payload.
2022-02-06 19:01:52,536 INFO: Shard ID None has successfully RESUMED session cc8dc465eef329664e4e475a97819a18 under trace ["gateway-prd-main-0k83",{"micros":1800,"calls":["discord-sessions-blue-prd-2-125",{"micros":20}]}].
2022-02-06 20:47:19,687 INFO: Got a request to RESUME the websocket.
2022-02-06 20:47:19,862 INFO: Shard ID None has sent the RESUME payload.
2022-02-06 20:47:19,904 INFO: Shard ID None has successfully RESUMED session cc8dc465eef329664e4e475a97819a18 under trace ["gateway-prd-main-drcs",{"micros":1721,"calls":["discord-sessions-blue-prd-2-125",{"micros":18}]}].
