2022-12-16 18:45:28,814 INFO: logging in using static token
2022-12-16 18:45:29,352 INFO: Shard ID None has connected to Gateway (Session ID: 4dd1dd7e2bcc38fdcc0a45df7fd66194).
2022-12-16 18:45:31,372 INFO: 目前登入身份：神奇海螺#3847
2022-12-16 18:46:50,185 ERROR: Ignoring exception in command '誒阿致'
Traceback (most recent call last):
  File "/opt/virtualenvs/python3/lib/python3.8/site-packages/discord/app_commands/commands.py", line 851, in _do_call
    return await self._callback(interaction, **params)  # type: ignore
  File "main.py", line 530, in cmd_talk
    res = await openai.Completion.create(
  File "/opt/virtualenvs/python3/lib/python3.8/site-packages/openai/api_resources/completion.py", line 25, in create
    return super().create(*args, **kwargs)
  File "/opt/virtualenvs/python3/lib/python3.8/site-packages/openai/api_resources/abstract/engine_api_resource.py", line 107, in create
    requestor = api_requestor.APIRequestor(
  File "/opt/virtualenvs/python3/lib/python3.8/site-packages/openai/api_requestor.py", line 85, in __init__
    self.api_key = key or util.default_api_key()
  File "/opt/virtualenvs/python3/lib/python3.8/site-packages/openai/util.py", line 186, in default_api_key
    raise openai.error.AuthenticationError(
openai.error.AuthenticationError: No API key provided. You can set your API key in code using 'openai.api_key = <API-KEY>', or you can set the environment variable OPENAI_API_KEY=<API-KEY>). If your API key is stored in a file, you can point the openai module at it with 'openai.api_key_path = <PATH>'. You can generate API keys in the OpenAI web interface. See https://onboard.openai.com for details, or email support@openai.com if you have any questions.

The above exception was the direct cause of the following exception:

Traceback (most recent call last):
  File "/opt/virtualenvs/python3/lib/python3.8/site-packages/discord/app_commands/tree.py", line 1240, in _call
    await command._invoke_with_namespace(interaction, namespace)
  File "/opt/virtualenvs/python3/lib/python3.8/site-packages/discord/app_commands/commands.py", line 876, in _invoke_with_namespace
    return await self._do_call(interaction, transformed_values)
  File "/opt/virtualenvs/python3/lib/python3.8/site-packages/discord/app_commands/commands.py", line 869, in _do_call
    raise CommandInvokeError(self, e) from e
discord.app_commands.errors.CommandInvokeError: Command '誒阿致' raised an exception: AuthenticationError: No API key provided. You can set your API key in code using 'openai.api_key = <API-KEY>', or you can set the environment variable OPENAI_API_KEY=<API-KEY>). If your API key is stored in a file, you can point the openai module at it with 'openai.api_key_path = <PATH>'. You can generate API keys in the OpenAI web interface. See https://onboard.openai.com for details, or email support@openai.com if you have any questions.
2022-12-16 18:47:56,216 INFO: logging in using static token
2022-12-16 18:47:56,771 INFO: Shard ID None has connected to Gateway (Session ID: ae1a909afd3ccebf9f3ff1e65d2d8d98).
2022-12-16 18:47:58,780 INFO: 目前登入身份：神奇海螺#3847
2022-12-16 18:48:09,994 INFO: message='Request to OpenAI API' method=post path=https://api.openai.com/v1/completions
2022-12-16 18:48:11,849 INFO: message='OpenAI API response' path=https://api.openai.com/v1/completions processing_ms=1660 request_id=ef099fed96b97649f0a662f0cf7b8d5a response_code=200
2022-12-16 18:48:12,084 ERROR: Ignoring exception in command '誒阿致'
Traceback (most recent call last):
  File "/opt/virtualenvs/python3/lib/python3.8/site-packages/discord/app_commands/commands.py", line 851, in _do_call
    return await self._callback(interaction, **params)  # type: ignore
  File "main.py", line 530, in cmd_talk
    res = await openai.Completion.create(
TypeError: object OpenAIObject can't be used in 'await' expression

The above exception was the direct cause of the following exception:

Traceback (most recent call last):
  File "/opt/virtualenvs/python3/lib/python3.8/site-packages/discord/app_commands/tree.py", line 1240, in _call
    await command._invoke_with_namespace(interaction, namespace)
  File "/opt/virtualenvs/python3/lib/python3.8/site-packages/discord/app_commands/commands.py", line 876, in _invoke_with_namespace
    return await self._do_call(interaction, transformed_values)
  File "/opt/virtualenvs/python3/lib/python3.8/site-packages/discord/app_commands/commands.py", line 865, in _do_call
    raise CommandInvokeError(self, e) from e
discord.app_commands.errors.CommandInvokeError: Command '誒阿致' raised an exception: TypeError: object OpenAIObject can't be used in 'await' expression
2022-12-16 18:51:42,167 INFO: logging in using static token
2022-12-16 18:51:42,806 INFO: Shard ID None has connected to Gateway (Session ID: f37f4d77b14ced2297433a1ceb78060b).
2022-12-16 18:51:44,832 INFO: 目前登入身份：神奇海螺#3847
2022-12-16 18:53:01,223 INFO: logging in using static token
2022-12-16 18:53:01,663 INFO: Shard ID None has connected to Gateway (Session ID: d59faaa00aa0e2579e8408a1b7a37821).
2022-12-16 18:53:03,675 INFO: 目前登入身份：神奇海螺#3847
2022-12-16 18:53:14,580 INFO: message='Request to OpenAI API' method=post path=https://api.openai.com/v1/completions
2022-12-16 18:53:16,005 INFO: message='OpenAI API response' path=https://api.openai.com/v1/completions processing_ms=1226 request_id=e7092c2cbf8ea887d582dfb9b6cdc2a0 response_code=200
2022-12-16 18:53:55,612 INFO: message='Request to OpenAI API' method=post path=https://api.openai.com/v1/completions
2022-12-16 18:53:58,116 INFO: message='OpenAI API response' path=https://api.openai.com/v1/completions processing_ms=2422 request_id=17933b7990b10960967f4d6802273c97 response_code=200
2022-12-16 18:53:58,163 INFO: 1 in test[一般]
2022-12-16 18:53:58,178 INFO: Connecting to voice...
2022-12-16 18:53:58,179 INFO: Starting voice handshake... (connection attempt 1)
2022-12-16 18:53:58,427 INFO: Voice handshake complete. Endpoint found hongkong2302.discord.media
2022-12-16 18:54:01,372 INFO: ffmpeg process 6851 successfully terminated with return code of 0.
2022-12-16 18:54:02,934 INFO: 1 out test[一般]
2022-12-16 18:54:04,163 INFO: ffmpeg process 6866 successfully terminated with return code of 0.
2022-12-16 18:54:06,617 INFO: ffmpeg process 6891 successfully terminated with return code of 0.
2022-12-16 18:54:07,645 INFO: The voice handshake is being terminated for Channel ID 876364970638585882 (Guild ID 876364969904578591)
2022-12-16 18:54:07,645 INFO: Disconnecting from voice normally, close code 1000.
2022-12-16 19:03:39,132 INFO: logging in using static token
2022-12-16 19:03:39,593 INFO: Shard ID None has connected to Gateway (Session ID: 0aebb0a70ee8e4ac37bf791ac73862ac).
2022-12-16 19:03:41,604 INFO: 目前登入身份：神奇海螺#3847
2022-12-16 19:03:49,334 INFO: message='Request to OpenAI API' method=post path=https://api.openai.com/v1/completions
2022-12-16 19:03:52,953 INFO: message='OpenAI API response' path=https://api.openai.com/v1/completions processing_ms=3419 request_id=62a74b151d5777f94159603c1a8182b8 response_code=200
2022-12-16 19:03:52,957 ERROR: Ignoring exception in command '誒阿致'
Traceback (most recent call last):
  File "/opt/virtualenvs/python3/lib/python3.8/site-packages/discord/app_commands/commands.py", line 851, in _do_call
    return await self._callback(interaction, **params)  # type: ignore
  File "main.py", line 531, in cmd_talk
    res = await loop.run_in_executor(None,openai.Completion.create(
RuntimeError: Task <Task pending name='CommandTree-invoker' coro=<CommandTree._from_interaction.<locals>.wrapper() running at /opt/virtualenvs/python3/lib/python3.8/site-packages/discord/app_commands/tree.py:1089>> got Future <Future pending cb=[_chain_future.<locals>._call_check_cancel() at /usr/lib/python3.8/asyncio/futures.py:360]> attached to a different loop

The above exception was the direct cause of the following exception:

Traceback (most recent call last):
  File "/opt/virtualenvs/python3/lib/python3.8/site-packages/discord/app_commands/tree.py", line 1240, in _call
    await command._invoke_with_namespace(interaction, namespace)
  File "/opt/virtualenvs/python3/lib/python3.8/site-packages/discord/app_commands/commands.py", line 876, in _invoke_with_namespace
    return await self._do_call(interaction, transformed_values)
  File "/opt/virtualenvs/python3/lib/python3.8/site-packages/discord/app_commands/commands.py", line 869, in _do_call
    raise CommandInvokeError(self, e) from e
discord.app_commands.errors.CommandInvokeError: Command '誒阿致' raised an exception: RuntimeError: Task <Task pending name='CommandTree-invoker' coro=<CommandTree._from_interaction.<locals>.wrapper() running at /opt/virtualenvs/python3/lib/python3.8/site-packages/discord/app_commands/tree.py:1089>> got Future <Future pending cb=[_chain_future.<locals>._call_check_cancel() at /usr/lib/python3.8/asyncio/futures.py:360]> attached to a different loop
2022-12-16 19:08:38,704 INFO: logging in using static token
2022-12-16 19:08:39,179 INFO: Shard ID None has connected to Gateway (Session ID: ea1fd6c5490f1068b1c287eeb15f18d6).
2022-12-16 19:08:41,187 INFO: 目前登入身份：神奇海螺#3847
2022-12-16 19:08:49,124 INFO: message='Request to OpenAI API' method=post path=https://api.openai.com/v1/completions
2022-12-16 19:08:55,785 INFO: message='OpenAI API response' path=https://api.openai.com/v1/completions processing_ms=6440 request_id=0ef045a35b7f531f74788e0ced861e19 response_code=200
2022-12-16 19:08:55,788 ERROR: Ignoring exception in command '誒阿致'
Traceback (most recent call last):
  File "/opt/virtualenvs/python3/lib/python3.8/site-packages/discord/app_commands/commands.py", line 851, in _do_call
    return await self._callback(interaction, **params)  # type: ignore
  File "main.py", line 537, in cmd_talk
    answer = res.choices[0]['text']
AttributeError: '_asyncio.Future' object has no attribute 'choices'

The above exception was the direct cause of the following exception:

Traceback (most recent call last):
  File "/opt/virtualenvs/python3/lib/python3.8/site-packages/discord/app_commands/tree.py", line 1240, in _call
    await command._invoke_with_namespace(interaction, namespace)
  File "/opt/virtualenvs/python3/lib/python3.8/site-packages/discord/app_commands/commands.py", line 876, in _invoke_with_namespace
    return await self._do_call(interaction, transformed_values)
  File "/opt/virtualenvs/python3/lib/python3.8/site-packages/discord/app_commands/commands.py", line 869, in _do_call
    raise CommandInvokeError(self, e) from e
discord.app_commands.errors.CommandInvokeError: Command '誒阿致' raised an exception: AttributeError: '_asyncio.Future' object has no attribute 'choices'
2022-12-16 19:09:18,017 INFO: message='Request to OpenAI API' method=post path=https://api.openai.com/v1/completions
2022-12-16 19:09:25,998 INFO: message='OpenAI API response' path=https://api.openai.com/v1/completions processing_ms=7913 request_id=07bfadcf6dd414dff84ba6e01312518e response_code=200
2022-12-16 19:09:25,999 ERROR: Ignoring exception in command '誒阿致'
Traceback (most recent call last):
  File "/opt/virtualenvs/python3/lib/python3.8/site-packages/discord/app_commands/commands.py", line 851, in _do_call
    return await self._callback(interaction, **params)  # type: ignore
  File "main.py", line 537, in cmd_talk
    answer = res.choices[0]['text']
AttributeError: '_asyncio.Future' object has no attribute 'choices'

The above exception was the direct cause of the following exception:

Traceback (most recent call last):
  File "/opt/virtualenvs/python3/lib/python3.8/site-packages/discord/app_commands/tree.py", line 1240, in _call
    await command._invoke_with_namespace(interaction, namespace)
  File "/opt/virtualenvs/python3/lib/python3.8/site-packages/discord/app_commands/commands.py", line 876, in _invoke_with_namespace
    return await self._do_call(interaction, transformed_values)
  File "/opt/virtualenvs/python3/lib/python3.8/site-packages/discord/app_commands/commands.py", line 869, in _do_call
    raise CommandInvokeError(self, e) from e
discord.app_commands.errors.CommandInvokeError: Command '誒阿致' raised an exception: AttributeError: '_asyncio.Future' object has no attribute 'choices'
2022-12-16 19:09:26,041 INFO: 1 in test[一般]
2022-12-16 19:09:26,074 INFO: Connecting to voice...
2022-12-16 19:09:26,079 INFO: Starting voice handshake... (connection attempt 1)
2022-12-16 19:09:26,331 INFO: Voice handshake complete. Endpoint found hongkong8385.discord.media
2022-12-16 19:09:29,289 INFO: ffmpeg process 8460 successfully terminated with return code of 0.
2022-12-16 19:09:31,453 INFO: 1 out test[一般]
2022-12-16 19:09:31,454 INFO: ffmpeg process 8476 successfully terminated with return code of 0.
2022-12-16 19:09:33,848 INFO: ffmpeg process 8489 successfully terminated with return code of 0.
2022-12-16 19:09:34,880 INFO: The voice handshake is being terminated for Channel ID 876364970638585882 (Guild ID 876364969904578591)
2022-12-16 19:09:34,881 INFO: Disconnecting from voice normally, close code 1000.
2022-12-16 19:10:06,452 INFO: logging in using static token
2022-12-16 19:10:06,953 INFO: Shard ID None has connected to Gateway (Session ID: 5fff0f1a3c360dcaf047fbf628adf40c).
2022-12-16 19:10:08,964 INFO: 目前登入身份：神奇海螺#3847
2022-12-16 19:10:17,597 INFO: message='Request to OpenAI API' method=post path=https://api.openai.com/v1/completions
2022-12-16 19:10:20,771 INFO: message='OpenAI API response' path=https://api.openai.com/v1/completions processing_ms=2953 request_id=f833eca5cf5939249b4eba4c52430d70 response_code=200
2022-12-16 19:10:20,774 ERROR: Ignoring exception in command '誒阿致'
Traceback (most recent call last):
  File "/opt/virtualenvs/python3/lib/python3.8/site-packages/discord/app_commands/commands.py", line 851, in _do_call
    return await self._callback(interaction, **params)  # type: ignore
  File "main.py", line 531, in cmd_talk
    res = await loop.run_in_executor(None,openai.Completion.create(
RuntimeError: Task <Task pending name='CommandTree-invoker' coro=<CommandTree._from_interaction.<locals>.wrapper() running at /opt/virtualenvs/python3/lib/python3.8/site-packages/discord/app_commands/tree.py:1089>> got Future <Future pending cb=[_chain_future.<locals>._call_check_cancel() at /usr/lib/python3.8/asyncio/futures.py:360]> attached to a different loop

The above exception was the direct cause of the following exception:

Traceback (most recent call last):
  File "/opt/virtualenvs/python3/lib/python3.8/site-packages/discord/app_commands/tree.py", line 1240, in _call
    await command._invoke_with_namespace(interaction, namespace)
  File "/opt/virtualenvs/python3/lib/python3.8/site-packages/discord/app_commands/commands.py", line 876, in _invoke_with_namespace
    return await self._do_call(interaction, transformed_values)
  File "/opt/virtualenvs/python3/lib/python3.8/site-packages/discord/app_commands/commands.py", line 869, in _do_call
    raise CommandInvokeError(self, e) from e
discord.app_commands.errors.CommandInvokeError: Command '誒阿致' raised an exception: RuntimeError: Task <Task pending name='CommandTree-invoker' coro=<CommandTree._from_interaction.<locals>.wrapper() running at /opt/virtualenvs/python3/lib/python3.8/site-packages/discord/app_commands/tree.py:1089>> got Future <Future pending cb=[_chain_future.<locals>._call_check_cancel() at /usr/lib/python3.8/asyncio/futures.py:360]> attached to a different loop
2022-12-16 19:10:21,198 INFO: Connecting to voice...
2022-12-16 19:10:21,205 INFO: Starting voice handshake... (connection attempt 1)
2022-12-16 19:10:21,402 INFO: Voice handshake complete. Endpoint found hongkong1311.discord.media
2022-12-16 19:10:21,605 ERROR: Exception occurred during Voice Protocol voice server update handler
Traceback (most recent call last):
  File "/opt/virtualenvs/python3/lib/python3.8/site-packages/discord/state.py", line 157, in logging_coroutine
    await coroutine
  File "/opt/virtualenvs/python3/lib/python3.8/site-packages/discord/voice_client.py", line 337, in on_voice_server_update
    await self.ws.close(4000)
AttributeError: '_MissingSentinel' object has no attribute 'close'
2022-12-16 19:10:23,153 INFO: ffmpeg process 8646 has not terminated. Waiting to terminate...
2022-12-16 19:10:23,157 INFO: ffmpeg process 8646 should have terminated with a return code of 1.
2022-12-16 19:10:24,833 INFO: The voice handshake is being terminated for Channel ID 1053388632385396766 (Guild ID 876364969904578591)
2022-12-16 19:10:24,834 INFO: Disconnecting from voice normally, close code 1000.
2022-12-16 19:10:34,171 INFO: 1 in test[一般]
2022-12-16 19:10:34,201 INFO: Connecting to voice...
2022-12-16 19:10:34,205 INFO: Starting voice handshake... (connection attempt 1)
2022-12-16 19:10:34,463 INFO: Voice handshake complete. Endpoint found hongkong9989.discord.media
2022-12-16 19:10:37,900 INFO: ffmpeg process 8685 successfully terminated with return code of 0.
2022-12-16 19:10:40,081 INFO: ffmpeg process 8699 successfully terminated with return code of 0.
2022-12-16 19:10:41,147 INFO: The voice handshake is being terminated for Channel ID 876364970638585882 (Guild ID 876364969904578591)
2022-12-16 19:10:41,148 INFO: Disconnecting from voice normally, close code 1000.
2022-12-16 19:10:43,964 INFO: message='Request to OpenAI API' method=post path=https://api.openai.com/v1/completions
2022-12-16 19:10:49,016 INFO: message='OpenAI API response' path=https://api.openai.com/v1/completions processing_ms=4932 request_id=9b1173bba909f35928d58ad4cd66caa8 response_code=200
2022-12-16 19:10:49,017 ERROR: Ignoring exception in command '誒阿致'
Traceback (most recent call last):
  File "/opt/virtualenvs/python3/lib/python3.8/site-packages/discord/app_commands/commands.py", line 851, in _do_call
    return await self._callback(interaction, **params)  # type: ignore
  File "main.py", line 531, in cmd_talk
    res = await loop.run_in_executor(None,openai.Completion.create(
RuntimeError: Task <Task pending name='CommandTree-invoker' coro=<CommandTree._from_interaction.<locals>.wrapper() running at /opt/virtualenvs/python3/lib/python3.8/site-packages/discord/app_commands/tree.py:1089>> got Future <Future pending cb=[_chain_future.<locals>._call_check_cancel() at /usr/lib/python3.8/asyncio/futures.py:360]> attached to a different loop

The above exception was the direct cause of the following exception:

Traceback (most recent call last):
  File "/opt/virtualenvs/python3/lib/python3.8/site-packages/discord/app_commands/tree.py", line 1240, in _call
    await command._invoke_with_namespace(interaction, namespace)
  File "/opt/virtualenvs/python3/lib/python3.8/site-packages/discord/app_commands/commands.py", line 876, in _invoke_with_namespace
    return await self._do_call(interaction, transformed_values)
  File "/opt/virtualenvs/python3/lib/python3.8/site-packages/discord/app_commands/commands.py", line 869, in _do_call
    raise CommandInvokeError(self, e) from e
discord.app_commands.errors.CommandInvokeError: Command '誒阿致' raised an exception: RuntimeError: Task <Task pending name='CommandTree-invoker' coro=<CommandTree._from_interaction.<locals>.wrapper() running at /opt/virtualenvs/python3/lib/python3.8/site-packages/discord/app_commands/tree.py:1089>> got Future <Future pending cb=[_chain_future.<locals>._call_check_cancel() at /usr/lib/python3.8/asyncio/futures.py:360]> attached to a different loop
2022-12-16 19:10:49,028 INFO: 1 out test[一般]
2022-12-16 19:10:49,028 INFO: Connecting to voice...
2022-12-16 19:10:49,028 INFO: Starting voice handshake... (connection attempt 1)
2022-12-16 19:10:49,109 INFO: Voice handshake complete. Endpoint found us-central5033.discord.media
2022-12-16 19:10:50,636 INFO: ffmpeg process 8726 successfully terminated with return code of 0.
2022-12-16 19:10:51,663 INFO: The voice handshake is being terminated for Channel ID 876364970638585882 (Guild ID 876364969904578591)
2022-12-16 19:10:51,664 INFO: Disconnecting from voice normally, close code 1000.
2022-12-16 19:12:22,012 INFO: Shard ID None has successfully RESUMED session 5fff0f1a3c360dcaf047fbf628adf40c.
2022-12-16 19:17:18,529 INFO: logging in using static token
2022-12-16 19:17:19,053 INFO: Shard ID None has connected to Gateway (Session ID: d044ca45098a07ab61c235c2273f6ffc).
2022-12-16 19:17:21,074 INFO: 目前登入身份：神奇海螺#3847
2022-12-16 19:17:33,820 INFO: message='Request to OpenAI API' method=post path=https://api.openai.com/v1/completions
2022-12-16 19:17:36,094 INFO: message='OpenAI API response' path=https://api.openai.com/v1/completions processing_ms=2036 request_id=4dd48069b65049d8d8af741bc17aaf63 response_code=200
2022-12-16 19:17:36,423 ERROR: Ignoring exception in command '誒阿致'
Traceback (most recent call last):
  File "/opt/virtualenvs/python3/lib/python3.8/site-packages/discord/app_commands/commands.py", line 851, in _do_call
    return await self._callback(interaction, **params)  # type: ignore
  File "main.py", line 531, in cmd_talk
    res = await asyncio.gather(openai.Completion.create(
  File "/usr/lib/python3.8/asyncio/tasks.py", line 823, in gather
    if arg not in arg_to_fut:
TypeError: unhashable type: 'OpenAIObject'

The above exception was the direct cause of the following exception:

Traceback (most recent call last):
  File "/opt/virtualenvs/python3/lib/python3.8/site-packages/discord/app_commands/tree.py", line 1240, in _call
    await command._invoke_with_namespace(interaction, namespace)
  File "/opt/virtualenvs/python3/lib/python3.8/site-packages/discord/app_commands/commands.py", line 876, in _invoke_with_namespace
    return await self._do_call(interaction, transformed_values)
  File "/opt/virtualenvs/python3/lib/python3.8/site-packages/discord/app_commands/commands.py", line 865, in _do_call
    raise CommandInvokeError(self, e) from e
discord.app_commands.errors.CommandInvokeError: Command '誒阿致' raised an exception: TypeError: unhashable type: 'OpenAIObject'
2022-12-16 19:19:28,928 INFO: logging in using static token
2022-12-16 19:19:29,410 INFO: Shard ID None has connected to Gateway (Session ID: c057c03a22565c74d472c46aed262d6a).
2022-12-16 19:19:31,415 INFO: 目前登入身份：神奇海螺#3847
2022-12-16 19:19:36,710 INFO: message='Request to OpenAI API' method=post path=https://api.openai.com/v1/completions
2022-12-16 19:19:38,286 INFO: message='OpenAI API response' path=https://api.openai.com/v1/completions processing_ms=1319 request_id=85e8657d36f09b8b552933ca9cf9792c response_code=200
2022-12-16 19:19:38,859 ERROR: Ignoring exception in command '誒阿致'
Traceback (most recent call last):
  File "/opt/virtualenvs/python3/lib/python3.8/site-packages/discord/app_commands/commands.py", line 851, in _do_call
    return await self._callback(interaction, **params)  # type: ignore
  File "main.py", line 531, in cmd_talk
    res = await asyncio.coroutine(openai.Completion.create(
TypeError: object function can't be used in 'await' expression

The above exception was the direct cause of the following exception:

Traceback (most recent call last):
  File "/opt/virtualenvs/python3/lib/python3.8/site-packages/discord/app_commands/tree.py", line 1240, in _call
    await command._invoke_with_namespace(interaction, namespace)
  File "/opt/virtualenvs/python3/lib/python3.8/site-packages/discord/app_commands/commands.py", line 876, in _invoke_with_namespace
    return await self._do_call(interaction, transformed_values)
  File "/opt/virtualenvs/python3/lib/python3.8/site-packages/discord/app_commands/commands.py", line 865, in _do_call
    raise CommandInvokeError(self, e) from e
discord.app_commands.errors.CommandInvokeError: Command '誒阿致' raised an exception: TypeError: object function can't be used in 'await' expression
2022-12-16 19:27:44,136 INFO: logging in using static token
2022-12-16 19:27:44,611 INFO: Shard ID None has connected to Gateway (Session ID: 9945abd29b75f5b703c6b76606a08794).
2022-12-16 19:27:46,627 INFO: 目前登入身份：神奇海螺#3847
2022-12-16 19:28:51,572 INFO: logging in using static token
2022-12-16 19:28:52,144 INFO: Shard ID None has connected to Gateway (Session ID: ff1823aafa50e3a8c055022e1856ab43).
2022-12-16 19:28:54,167 INFO: 目前登入身份：神奇海螺#3847
2022-12-16 19:29:03,191 INFO: message='Request to OpenAI API' method=post path=https://api.openai.com/v1/completions
2022-12-16 19:29:06,369 INFO: message='OpenAI API response' path=https://api.openai.com/v1/completions processing_ms=3011 request_id=13c05188f71422ae353a537dec40b04a response_code=200
2022-12-16 19:29:06,612 ERROR: Ignoring exception in command '誒阿致'
Traceback (most recent call last):
  File "/opt/virtualenvs/python3/lib/python3.8/site-packages/discord/app_commands/commands.py", line 851, in _do_call
    return await self._callback(interaction, **params)  # type: ignore
  File "main.py", line 531, in cmd_talk
    res = await sync_to_async(openai.Completion.create(
  File "/opt/virtualenvs/python3/lib/python3.8/site-packages/asgiref/sync.py", line 528, in sync_to_async
    return SyncToAsync(
  File "/opt/virtualenvs/python3/lib/python3.8/site-packages/asgiref/sync.py", line 364, in __init__
    raise TypeError("sync_to_async can only be applied to sync functions.")
TypeError: sync_to_async can only be applied to sync functions.

The above exception was the direct cause of the following exception:

Traceback (most recent call last):
  File "/opt/virtualenvs/python3/lib/python3.8/site-packages/discord/app_commands/tree.py", line 1240, in _call
    await command._invoke_with_namespace(interaction, namespace)
  File "/opt/virtualenvs/python3/lib/python3.8/site-packages/discord/app_commands/commands.py", line 876, in _invoke_with_namespace
    return await self._do_call(interaction, transformed_values)
  File "/opt/virtualenvs/python3/lib/python3.8/site-packages/discord/app_commands/commands.py", line 865, in _do_call
    raise CommandInvokeError(self, e) from e
discord.app_commands.errors.CommandInvokeError: Command '誒阿致' raised an exception: TypeError: sync_to_async can only be applied to sync functions.
2022-12-16 19:29:06,731 INFO: 1 in test[一般]
2022-12-16 19:29:06,740 INFO: Connecting to voice...
2022-12-16 19:29:06,747 INFO: Starting voice handshake... (connection attempt 1)
2022-12-16 19:29:07,005 INFO: Voice handshake complete. Endpoint found hongkong8879.discord.media
2022-12-16 19:29:09,958 INFO: ffmpeg process 10712 successfully terminated with return code of 0.
2022-12-16 19:29:12,757 INFO: ffmpeg process 10741 successfully terminated with return code of 0.
2022-12-16 19:29:13,827 INFO: The voice handshake is being terminated for Channel ID 876364970638585882 (Guild ID 876364969904578591)
2022-12-16 19:29:13,829 INFO: Disconnecting from voice normally, close code 1000.
2022-12-16 19:31:27,206 INFO: logging in using static token
2022-12-16 19:31:27,732 INFO: Shard ID None has connected to Gateway (Session ID: 0ed19a8250024e87563850c8d428a734).
2022-12-16 19:31:29,747 INFO: 目前登入身份：神奇海螺#3847
2022-12-16 19:31:43,351 INFO: message='Request to OpenAI API' method=post path=https://api.openai.com/v1/completions
2022-12-16 19:31:43,377 INFO: 1 out test[一般]
2022-12-16 19:31:43,381 INFO: Connecting to voice...
2022-12-16 19:31:43,382 INFO: Starting voice handshake... (connection attempt 1)
2022-12-16 19:31:43,497 INFO: Voice handshake complete. Endpoint found us-central2661.discord.media
2022-12-16 19:31:45,025 INFO: message='OpenAI API response' path=https://api.openai.com/v1/completions processing_ms=1415 request_id=62d22ccb7f9f4b7a3fbc957ab5edcd68 response_code=200
2022-12-16 19:31:45,059 INFO: ffmpeg process 11062 successfully terminated with return code of 0.
2022-12-16 19:31:46,084 INFO: The voice handshake is being terminated for Channel ID 876364970638585882 (Guild ID 876364969904578591)
2022-12-16 19:31:46,089 INFO: Disconnecting from voice normally, close code 1000.
2022-12-16 19:33:02,534 INFO: message='Request to OpenAI API' method=post path=https://api.openai.com/v1/completions
2022-12-16 19:33:05,512 INFO: 1 in test[一般]
2022-12-16 19:33:05,524 INFO: Connecting to voice...
2022-12-16 19:33:05,524 INFO: Starting voice handshake... (connection attempt 1)
2022-12-16 19:33:05,749 INFO: Voice handshake complete. Endpoint found hongkong7115.discord.media
2022-12-16 19:33:05,930 ERROR: Exception occurred during Voice Protocol voice server update handler
Traceback (most recent call last):
  File "/opt/virtualenvs/python3/lib/python3.8/site-packages/discord/state.py", line 157, in logging_coroutine
    await coroutine
  File "/opt/virtualenvs/python3/lib/python3.8/site-packages/discord/voice_client.py", line 337, in on_voice_server_update
    await self.ws.close(4000)
AttributeError: '_MissingSentinel' object has no attribute 'close'
2022-12-16 19:33:08,711 INFO: ffmpeg process 11235 successfully terminated with return code of 0.
2022-12-16 19:33:11,053 INFO: ffmpeg process 11250 successfully terminated with return code of 0.
2022-12-16 19:33:12,082 INFO: The voice handshake is being terminated for Channel ID 876364970638585882 (Guild ID 876364969904578591)
2022-12-16 19:33:12,083 INFO: Disconnecting from voice normally, close code 1000.
2022-12-16 19:33:25,589 INFO: 1 out test[一般]
2022-12-16 19:33:25,590 INFO: Connecting to voice...
2022-12-16 19:33:25,590 INFO: Starting voice handshake... (connection attempt 1)
2022-12-16 19:33:25,666 INFO: Voice handshake complete. Endpoint found us-central4565.discord.media
2022-12-16 19:33:26,004 INFO: message='OpenAI API response' path=https://api.openai.com/v1/completions processing_ms=23270 request_id=a030b98987dd153149385957ee4f0c74 response_code=200
2022-12-16 19:33:26,005 INFO: message='Request to OpenAI API' method=post path=https://api.openai.com/v1/completions
2022-12-16 19:33:26,138 ERROR: Ignoring exception in command '誒阿致'
Traceback (most recent call last):
  File "/opt/virtualenvs/python3/lib/python3.8/site-packages/discord/app_commands/commands.py", line 851, in _do_call
    return await self._callback(interaction, **params)  # type: ignore
  File "main.py", line 539, in cmd_talk
    await interaction.response.send_message(answer)
  File "/opt/virtualenvs/python3/lib/python3.8/site-packages/discord/interactions.py", line 718, in send_message
    await adapter.create_interaction_response(
  File "/opt/virtualenvs/python3/lib/python3.8/site-packages/discord/webhook/async_.py", line 219, in request
    raise NotFound(response, data)
discord.errors.NotFound: 404 Not Found (error code: 10062): Unknown interaction

The above exception was the direct cause of the following exception:

Traceback (most recent call last):
  File "/opt/virtualenvs/python3/lib/python3.8/site-packages/discord/app_commands/tree.py", line 1240, in _call
    await command._invoke_with_namespace(interaction, namespace)
  File "/opt/virtualenvs/python3/lib/python3.8/site-packages/discord/app_commands/commands.py", line 876, in _invoke_with_namespace
    return await self._do_call(interaction, transformed_values)
  File "/opt/virtualenvs/python3/lib/python3.8/site-packages/discord/app_commands/commands.py", line 869, in _do_call
    raise CommandInvokeError(self, e) from e
discord.app_commands.errors.CommandInvokeError: Command '誒阿致' raised an exception: NotFound: 404 Not Found (error code: 10062): Unknown interaction
2022-12-16 19:33:27,212 INFO: ffmpeg process 11296 successfully terminated with return code of 0.
2022-12-16 19:33:28,239 INFO: The voice handshake is being terminated for Channel ID 876364970638585882 (Guild ID 876364969904578591)
2022-12-16 19:33:28,240 INFO: Disconnecting from voice normally, close code 1000.
2022-12-16 19:33:48,237 INFO: message='OpenAI API response' path=https://api.openai.com/v1/completions processing_ms=22133 request_id=117e7afb79e245660014ead1445e429f response_code=200
2022-12-16 19:33:48,455 ERROR: Ignoring exception in command '誒阿致'
Traceback (most recent call last):
  File "/opt/virtualenvs/python3/lib/python3.8/site-packages/discord/app_commands/commands.py", line 851, in _do_call
    return await self._callback(interaction, **params)  # type: ignore
  File "main.py", line 539, in cmd_talk
    await interaction.response.send_message(answer)
  File "/opt/virtualenvs/python3/lib/python3.8/site-packages/discord/interactions.py", line 718, in send_message
    await adapter.create_interaction_response(
  File "/opt/virtualenvs/python3/lib/python3.8/site-packages/discord/webhook/async_.py", line 219, in request
    raise NotFound(response, data)
discord.errors.NotFound: 404 Not Found (error code: 10062): Unknown interaction

The above exception was the direct cause of the following exception:

Traceback (most recent call last):
  File "/opt/virtualenvs/python3/lib/python3.8/site-packages/discord/app_commands/tree.py", line 1240, in _call
    await command._invoke_with_namespace(interaction, namespace)
  File "/opt/virtualenvs/python3/lib/python3.8/site-packages/discord/app_commands/commands.py", line 876, in _invoke_with_namespace
    return await self._do_call(interaction, transformed_values)
  File "/opt/virtualenvs/python3/lib/python3.8/site-packages/discord/app_commands/commands.py", line 869, in _do_call
    raise CommandInvokeError(self, e) from e
discord.app_commands.errors.CommandInvokeError: Command '誒阿致' raised an exception: NotFound: 404 Not Found (error code: 10062): Unknown interaction
2022-12-16 19:33:59,014 INFO: message='Request to OpenAI API' method=post path=https://api.openai.com/v1/completions
2022-12-16 19:34:00,450 INFO: message='OpenAI API response' path=https://api.openai.com/v1/completions processing_ms=1368 request_id=3521bc10c5ff775a197bca5475f478a6 response_code=200
2022-12-16 19:38:50,234 INFO: logging in using static token
2022-12-16 19:38:51,176 INFO: Shard ID None has connected to Gateway (Session ID: 533d84883f66f02bb81e781e295c1f30).
2022-12-16 19:39:02,070 INFO: logging in using static token
2022-12-16 19:39:02,746 INFO: Shard ID None has connected to Gateway (Session ID: f3ac18ccde18ad4ec9bc06cf793b85e9).
2022-12-16 19:39:04,751 INFO: 目前登入身份：神奇海螺#3847
2022-12-16 19:39:11,311 ERROR: Ignoring exception in on_message
Traceback (most recent call last):
  File "/opt/virtualenvs/python3/lib/python3.8/site-packages/discord/client.py", line 409, in _run_event
    await coro(*args, **kwargs)
  File "main.py", line 385, in on_message
    res = await sync_to_async(openai.Completion.create)(
  File "/opt/virtualenvs/python3/lib/python3.8/site-packages/asgiref/sync.py", line 435, in __call__
    ret = await asyncio.wait_for(future, timeout=None)
  File "/usr/lib/python3.8/asyncio/tasks.py", line 455, in wait_for
    return await fut
  File "/usr/lib/python3.8/concurrent/futures/thread.py", line 57, in run
    result = self.fn(*self.args, **self.kwargs)
  File "/opt/virtualenvs/python3/lib/python3.8/site-packages/asgiref/sync.py", line 476, in thread_handler
    return func(*args, **kwargs)
  File "/opt/virtualenvs/python3/lib/python3.8/site-packages/openai/api_resources/completion.py", line 25, in create
    return super().create(*args, **kwargs)
  File "/opt/virtualenvs/python3/lib/python3.8/site-packages/openai/api_resources/abstract/engine_api_resource.py", line 115, in create
    response, _, api_key = requestor.request(
  File "/opt/virtualenvs/python3/lib/python3.8/site-packages/openai/api_requestor.py", line 171, in request
    result = self.request_raw(
  File "/opt/virtualenvs/python3/lib/python3.8/site-packages/openai/api_requestor.py", line 339, in request_raw
    data = json.dumps(params).encode()
  File "/usr/lib/python3.8/json/__init__.py", line 231, in dumps
    return _default_encoder.encode(obj)
  File "/usr/lib/python3.8/json/encoder.py", line 199, in encode
    chunks = self.iterencode(o, _one_shot=True)
  File "/usr/lib/python3.8/json/encoder.py", line 257, in iterencode
    return _iterencode(o, 0)
  File "/usr/lib/python3.8/json/encoder.py", line 179, in default
    raise TypeError(f'Object of type {o.__class__.__name__} '
TypeError: Object of type Message is not JSON serializable
2022-12-16 19:39:46,555 ERROR: Ignoring exception in on_message
Traceback (most recent call last):
  File "/opt/virtualenvs/python3/lib/python3.8/site-packages/discord/client.py", line 409, in _run_event
    await coro(*args, **kwargs)
  File "main.py", line 385, in on_message
    res = await sync_to_async(openai.Completion.create)(
  File "/opt/virtualenvs/python3/lib/python3.8/site-packages/asgiref/sync.py", line 435, in __call__
    ret = await asyncio.wait_for(future, timeout=None)
  File "/usr/lib/python3.8/asyncio/tasks.py", line 455, in wait_for
    return await fut
  File "/usr/lib/python3.8/concurrent/futures/thread.py", line 57, in run
    result = self.fn(*self.args, **self.kwargs)
  File "/opt/virtualenvs/python3/lib/python3.8/site-packages/asgiref/sync.py", line 476, in thread_handler
    return func(*args, **kwargs)
  File "/opt/virtualenvs/python3/lib/python3.8/site-packages/openai/api_resources/completion.py", line 25, in create
    return super().create(*args, **kwargs)
  File "/opt/virtualenvs/python3/lib/python3.8/site-packages/openai/api_resources/abstract/engine_api_resource.py", line 115, in create
    response, _, api_key = requestor.request(
  File "/opt/virtualenvs/python3/lib/python3.8/site-packages/openai/api_requestor.py", line 171, in request
    result = self.request_raw(
  File "/opt/virtualenvs/python3/lib/python3.8/site-packages/openai/api_requestor.py", line 339, in request_raw
    data = json.dumps(params).encode()
  File "/usr/lib/python3.8/json/__init__.py", line 231, in dumps
    return _default_encoder.encode(obj)
  File "/usr/lib/python3.8/json/encoder.py", line 199, in encode
    chunks = self.iterencode(o, _one_shot=True)
  File "/usr/lib/python3.8/json/encoder.py", line 257, in iterencode
    return _iterencode(o, 0)
  File "/usr/lib/python3.8/json/encoder.py", line 179, in default
    raise TypeError(f'Object of type {o.__class__.__name__} '
TypeError: Object of type Message is not JSON serializable
2022-12-16 19:40:43,347 INFO: logging in using static token
2022-12-16 19:40:43,860 INFO: Shard ID None has connected to Gateway (Session ID: 6a862ffde7925e3b2fe044f6f1031f1b).
2022-12-16 19:40:45,868 INFO: 目前登入身份：神奇海螺#3847
2022-12-16 19:40:51,270 INFO: message='Request to OpenAI API' method=post path=https://api.openai.com/v1/completions
2022-12-16 19:40:52,765 INFO: message='OpenAI API response' path=https://api.openai.com/v1/completions processing_ms=1313 request_id=839ffe621d5c057a151c2275174ce948 response_code=200
2022-12-16 19:41:02,242 INFO: message='Request to OpenAI API' method=post path=https://api.openai.com/v1/completions
2022-12-16 19:41:16,367 INFO: message='OpenAI API response' path=https://api.openai.com/v1/completions processing_ms=14031 request_id=59f7ead33e6b0354045fa721f68ffb4c response_code=200
2022-12-16 19:41:16,965 INFO: 1 in test[一般]
2022-12-16 19:41:17,002 INFO: Connecting to voice...
2022-12-16 19:41:17,002 INFO: Starting voice handshake... (connection attempt 1)
2022-12-16 19:41:17,177 INFO: Voice handshake complete. Endpoint found hongkong9424.discord.media
2022-12-16 19:41:17,330 ERROR: Exception occurred during Voice Protocol voice server update handler
Traceback (most recent call last):
  File "/opt/virtualenvs/python3/lib/python3.8/site-packages/discord/state.py", line 157, in logging_coroutine
    await coroutine
  File "/opt/virtualenvs/python3/lib/python3.8/site-packages/discord/voice_client.py", line 337, in on_voice_server_update
    await self.ws.close(4000)
AttributeError: '_MissingSentinel' object has no attribute 'close'
2022-12-16 19:41:20,665 INFO: ffmpeg process 12440 successfully terminated with return code of 0.
2022-12-16 19:41:22,194 INFO: 1 out test[一般]
2022-12-16 19:41:23,538 INFO: ffmpeg process 12459 successfully terminated with return code of 0.
2022-12-16 19:41:26,019 INFO: ffmpeg process 12473 successfully terminated with return code of 0.
2022-12-16 19:41:27,046 INFO: The voice handshake is being terminated for Channel ID 876364970638585882 (Guild ID 876364969904578591)
2022-12-16 19:41:27,046 INFO: Disconnecting from voice normally, close code 1000.
2022-12-16 19:42:05,338 INFO: message='Request to OpenAI API' method=post path=https://api.openai.com/v1/completions
2022-12-16 19:42:18,316 INFO: message='OpenAI API response' path=https://api.openai.com/v1/completions processing_ms=12913 request_id=e499437157fa0735ae7ed1ae054eceba response_code=200
2022-12-16 19:42:36,871 INFO: Shard ID None has successfully RESUMED session 6a862ffde7925e3b2fe044f6f1031f1b.
2022-12-16 19:42:48,903 INFO: message='Request to OpenAI API' method=post path=https://api.openai.com/v1/completions
2022-12-16 19:42:50,681 INFO: message='OpenAI API response' path=https://api.openai.com/v1/completions processing_ms=1703 request_id=b32ab9d1860511995943c5d874fc7d9e response_code=200
2022-12-16 19:44:12,889 INFO: message='Request to OpenAI API' method=post path=https://api.openai.com/v1/completions
2022-12-16 19:44:13,731 INFO: 1 in test[一般]
2022-12-16 19:44:13,750 INFO: Connecting to voice...
2022-12-16 19:44:13,750 INFO: Starting voice handshake... (connection attempt 1)
2022-12-16 19:44:13,997 INFO: Voice handshake complete. Endpoint found hongkong10004.discord.media
2022-12-16 19:44:14,146 ERROR: Exception occurred during Voice Protocol voice server update handler
Traceback (most recent call last):
  File "/opt/virtualenvs/python3/lib/python3.8/site-packages/discord/state.py", line 157, in logging_coroutine
    await coroutine
  File "/opt/virtualenvs/python3/lib/python3.8/site-packages/discord/voice_client.py", line 337, in on_voice_server_update
    await self.ws.close(4000)
AttributeError: '_MissingSentinel' object has no attribute 'close'
2022-12-16 19:44:17,312 INFO: ffmpeg process 12831 successfully terminated with return code of 0.
2022-12-16 19:44:19,999 INFO: ffmpeg process 12845 successfully terminated with return code of 0.
2022-12-16 19:44:21,071 INFO: The voice handshake is being terminated for Channel ID 876364970638585882 (Guild ID 876364969904578591)
2022-12-16 19:44:21,072 INFO: Disconnecting from voice normally, close code 1000.
2022-12-16 19:44:21,185 INFO: message='OpenAI API response' path=https://api.openai.com/v1/completions processing_ms=8101 request_id=8296466880e85650cd9cefc00bb46a98 response_code=200
2022-12-16 19:44:57,867 INFO: 1 out test[一般]
2022-12-16 19:44:57,868 INFO: Connecting to voice...
2022-12-16 19:44:57,868 INFO: Starting voice handshake... (connection attempt 1)
2022-12-16 19:44:57,968 INFO: Voice handshake complete. Endpoint found us-central6494.discord.media
2022-12-16 19:44:59,496 INFO: ffmpeg process 12935 successfully terminated with return code of 0.
2022-12-16 19:45:00,521 INFO: The voice handshake is being terminated for Channel ID 876364970638585882 (Guild ID 876364969904578591)
2022-12-16 19:45:00,523 INFO: Disconnecting from voice normally, close code 1000.
2022-12-16 19:45:23,633 INFO: message='Request to OpenAI API' method=post path=https://api.openai.com/v1/completions
2022-12-16 19:45:28,690 INFO: 1 in test[一般]
2022-12-16 19:45:28,717 INFO: Connecting to voice...
2022-12-16 19:45:28,718 INFO: Starting voice handshake... (connection attempt 1)
2022-12-16 19:45:28,915 INFO: Voice handshake complete. Endpoint found hongkong6360.discord.media
2022-12-16 19:45:29,114 ERROR: Exception occurred during Voice Protocol voice server update handler
Traceback (most recent call last):
  File "/opt/virtualenvs/python3/lib/python3.8/site-packages/discord/state.py", line 157, in logging_coroutine
    await coroutine
  File "/opt/virtualenvs/python3/lib/python3.8/site-packages/discord/voice_client.py", line 337, in on_voice_server_update
    await self.ws.close(4000)
AttributeError: '_MissingSentinel' object has no attribute 'close'
2022-12-16 19:45:31,832 INFO: ffmpeg process 13001 successfully terminated with return code of 0.
2022-12-16 19:45:32,315 INFO: 1 out test[一般]
2022-12-16 19:45:34,035 INFO: ffmpeg process 13016 successfully terminated with return code of 0.
2022-12-16 19:45:36,495 INFO: ffmpeg process 13030 successfully terminated with return code of 0.
2022-12-16 19:45:37,225 INFO: message='OpenAI API response' path=https://api.openai.com/v1/completions processing_ms=13489 request_id=652f0876349f6fb5c041841d42fec01e response_code=200
2022-12-16 19:45:37,526 INFO: The voice handshake is being terminated for Channel ID 876364970638585882 (Guild ID 876364969904578591)
2022-12-16 19:45:37,527 INFO: Disconnecting from voice normally, close code 1000.
2022-12-16 19:45:55,535 INFO: message='Request to OpenAI API' method=post path=https://api.openai.com/v1/completions
2022-12-16 19:46:15,269 INFO: message='OpenAI API response' path=https://api.openai.com/v1/completions processing_ms=19621 request_id=7ede87c3925438366788b90ec5bd2978 response_code=200
2022-12-16 19:49:57,703 INFO: message='Request to OpenAI API' method=post path=https://api.openai.com/v1/completions
2022-12-16 19:50:13,615 INFO: message='OpenAI API response' path=https://api.openai.com/v1/completions processing_ms=15710 request_id=61df135d054eb1e1042675b5fb1bea18 response_code=200
2022-12-16 19:51:05,172 INFO: message='Request to OpenAI API' method=post path=https://api.openai.com/v1/completions
2022-12-16 19:51:17,953 INFO: message='OpenAI API response' path=https://api.openai.com/v1/completions processing_ms=12680 request_id=2ec20664234528f5698ddc5ee7bf167d response_code=200
2022-12-16 19:51:54,759 INFO: message='Request to OpenAI API' method=post path=https://api.openai.com/v1/completions
2022-12-16 19:52:19,559 INFO: 1 in test[一般]
2022-12-16 19:52:19,582 INFO: Connecting to voice...
2022-12-16 19:52:19,583 INFO: Starting voice handshake... (connection attempt 1)
2022-12-16 19:52:19,747 INFO: Voice handshake complete. Endpoint found hongkong7879.discord.media
2022-12-16 19:52:19,946 ERROR: Exception occurred during Voice Protocol voice server update handler
Traceback (most recent call last):
  File "/opt/virtualenvs/python3/lib/python3.8/site-packages/discord/state.py", line 157, in logging_coroutine
    await coroutine
  File "/opt/virtualenvs/python3/lib/python3.8/site-packages/discord/voice_client.py", line 337, in on_voice_server_update
    await self.ws.close(4000)
AttributeError: '_MissingSentinel' object has no attribute 'close'
2022-12-16 19:52:20,168 INFO: message='OpenAI API response' path=https://api.openai.com/v1/completions processing_ms=25341 request_id=721c4dba2e2849a72fb151f882ccce37 response_code=200
2022-12-16 19:52:22,710 INFO: ffmpeg process 13229 successfully terminated with return code of 0.
2022-12-16 19:52:23,043 INFO: 1 out test[一般]
2022-12-16 19:52:25,427 INFO: ffmpeg process 13239 successfully terminated with return code of 0.
2022-12-16 19:52:27,885 INFO: ffmpeg process 13249 successfully terminated with return code of 0.
2022-12-16 19:52:28,913 INFO: The voice handshake is being terminated for Channel ID 876364970638585882 (Guild ID 876364969904578591)
2022-12-16 19:52:28,913 INFO: Disconnecting from voice normally, close code 1000.
2022-12-16 21:03:28,947 INFO: Shard ID None has successfully RESUMED session 6a862ffde7925e3b2fe044f6f1031f1b.
2022-12-16 21:58:23,500 INFO: logging in using static token
2022-12-16 21:58:24,017 INFO: Shard ID None has connected to Gateway (Session ID: 201ab37d1200fe896860ac3a992738d4).
2022-12-16 21:58:26,021 INFO: 目前登入身份：神奇海螺#3847
2022-12-16 22:15:57,401 INFO: Shard ID None has successfully RESUMED session 201ab37d1200fe896860ac3a992738d4.
2022-12-16 23:36:40,298 INFO: Shard ID None has successfully RESUMED session 201ab37d1200fe896860ac3a992738d4.
2022-12-16 23:53:14,758 INFO: logging in using static token
2022-12-16 23:53:15,791 INFO: Shard ID None has connected to Gateway (Session ID: d7d4f50416a5ede782b00b2adaa5c7c1).
2022-12-16 23:53:17,801 INFO: 目前登入身份：神奇海螺#3847
2022-12-17 02:15:35,232 INFO: Shard ID None has successfully RESUMED session d7d4f50416a5ede782b00b2adaa5c7c1.
2022-12-17 02:34:39,465 INFO: Shard ID None has successfully RESUMED session d7d4f50416a5ede782b00b2adaa5c7c1.
2022-12-17 04:47:20,619 INFO: Shard ID None has successfully RESUMED session d7d4f50416a5ede782b00b2adaa5c7c1.
2022-12-17 05:29:41,766 INFO: logging in using static token
2022-12-17 05:29:42,261 INFO: Shard ID None has connected to Gateway (Session ID: c3f755b55679570c8978208a8c8c3164).
2022-12-17 05:29:44,299 INFO: 目前登入身份：神奇海螺#3847
2022-12-17 07:08:04,978 INFO: Shard ID None has successfully RESUMED session c3f755b55679570c8978208a8c8c3164.
2022-12-17 08:07:03,427 INFO: message='Request to OpenAI API' method=post path=https://api.openai.com/v1/completions
2022-12-17 08:07:07,781 INFO: message='OpenAI API response' path=https://api.openai.com/v1/completions processing_ms=4125 request_id=ccf49074924a617d22b00b276f8e73c8 response_code=200
2022-12-17 08:15:01,797 INFO: logging in using static token
2022-12-17 08:15:02,238 INFO: Shard ID None has connected to Gateway (Session ID: 7426290a3b58a4e5983ec91344450ca0).
2022-12-17 08:15:04,272 INFO: 目前登入身份：神奇海螺#3847
2022-12-17 10:27:30,358 INFO: Shard ID None has successfully RESUMED session 7426290a3b58a4e5983ec91344450ca0.
2022-12-17 10:33:26,926 INFO: logging in using static token
2022-12-17 10:33:27,488 INFO: Shard ID None has connected to Gateway (Session ID: 3885a0a27e42919f34aba6e2baa603b2).
2022-12-17 10:33:29,495 INFO: 目前登入身份：神奇海螺#3847
2022-12-17 10:51:59,309 INFO: Shard ID None has successfully RESUMED session 3885a0a27e42919f34aba6e2baa603b2.
2022-12-17 12:16:01,318 INFO: Shard ID None has successfully RESUMED session 3885a0a27e42919f34aba6e2baa603b2.
2022-12-17 13:21:20,627 INFO: Shard ID None has successfully RESUMED session 3885a0a27e42919f34aba6e2baa603b2.
2022-12-17 14:26:05,692 INFO: Shard ID None has successfully RESUMED session 3885a0a27e42919f34aba6e2baa603b2.
2022-12-17 14:26:37,945 INFO: message='Request to OpenAI API' method=post path=https://api.openai.com/v1/completions
2022-12-17 14:26:42,117 INFO: message='OpenAI API response' path=https://api.openai.com/v1/completions processing_ms=3934 request_id=0fd75485947993b0015a5adf2fad12ca response_code=200
2022-12-17 15:23:02,842 INFO: message='Request to OpenAI API' method=post path=https://api.openai.com/v1/completions
2022-12-17 15:23:12,343 INFO: message='OpenAI API response' path=https://api.openai.com/v1/completions processing_ms=9273 request_id=f59148f88ffe19bdcb5881233069ebf5 response_code=200
2022-12-17 15:56:19,956 INFO: Shard ID None has successfully RESUMED session 3885a0a27e42919f34aba6e2baa603b2.
2022-12-17 16:11:55,907 INFO: message='Request to OpenAI API' method=post path=https://api.openai.com/v1/completions
2022-12-17 16:11:56,998 INFO: message='OpenAI API response' path=https://api.openai.com/v1/completions processing_ms=854 request_id=d9657d9f8a2211d81f62a19fe031ad65 response_code=200
2022-12-17 16:12:21,764 INFO: message='Request to OpenAI API' method=post path=https://api.openai.com/v1/completions
2022-12-17 16:12:33,812 INFO: message='OpenAI API response' path=https://api.openai.com/v1/completions processing_ms=11955 request_id=e03e8483c5bced93a95206d72a40dead response_code=200
2022-12-17 16:13:13,168 INFO: message='Request to OpenAI API' method=post path=https://api.openai.com/v1/completions
2022-12-17 16:13:22,364 INFO: message='OpenAI API response' path=https://api.openai.com/v1/completions processing_ms=9078 request_id=0ab220b42014c39c893292a86b3d6093 response_code=200
2022-12-17 16:14:45,599 INFO: message='Request to OpenAI API' method=post path=https://api.openai.com/v1/completions
2022-12-17 16:14:47,445 INFO: message='OpenAI API response' path=https://api.openai.com/v1/completions processing_ms=1693 request_id=41291213d2db02d3f9ed7c16eacdb796 response_code=200
2022-12-17 16:15:50,213 INFO: message='Request to OpenAI API' method=post path=https://api.openai.com/v1/completions
2022-12-17 16:15:51,049 INFO: message='OpenAI API response' path=https://api.openai.com/v1/completions processing_ms=770 request_id=e8f26a126606e9214c85110719c2ea82 response_code=200
2022-12-17 16:17:36,212 INFO: message='Request to OpenAI API' method=post path=https://api.openai.com/v1/completions
2022-12-17 16:17:38,317 INFO: message='OpenAI API response' path=https://api.openai.com/v1/completions processing_ms=1893 request_id=535c65d0f918bfb14435b0355043a9e6 response_code=200
2022-12-17 16:19:34,186 INFO: message='Request to OpenAI API' method=post path=https://api.openai.com/v1/completions
2022-12-17 16:19:34,873 INFO: message='OpenAI API response' path=https://api.openai.com/v1/completions processing_ms=505 request_id=470190f04286045180906192eaa1a009 response_code=200
2022-12-17 16:20:25,894 INFO: message='Request to OpenAI API' method=post path=https://api.openai.com/v1/completions
2022-12-17 16:20:26,653 INFO: message='OpenAI API response' path=https://api.openai.com/v1/completions processing_ms=694 request_id=b6649f67e3b133a8c41e6d577d243be6 response_code=200
2022-12-17 16:23:47,728 INFO: message='Request to OpenAI API' method=post path=https://api.openai.com/v1/completions
2022-12-17 16:23:49,541 INFO: message='OpenAI API response' path=https://api.openai.com/v1/completions processing_ms=1621 request_id=f8743c2634823798a0f4a85b35e91ada response_code=200
2022-12-17 18:37:54,089 INFO: Shard ID None has successfully RESUMED session 3885a0a27e42919f34aba6e2baa603b2.
2022-12-17 20:42:16,233 INFO: Shard ID None has successfully RESUMED session 3885a0a27e42919f34aba6e2baa603b2.
