2022-10-19 22:58:40,896 INFO: logging in using static token
2022-10-19 22:58:41,372 INFO: Shard ID None has connected to Gateway (Session ID: cf225ad65ea38068bf82315b683e124e).
2022-10-19 22:58:43,399 INFO: 目前登入身份：神奇海螺#3847
2022-10-20 02:17:13,650 INFO: Shard ID None has successfully RESUMED session cf225ad65ea38068bf82315b683e124e.
2022-10-20 05:19:12,926 INFO: Shard ID None has successfully RESUMED session cf225ad65ea38068bf82315b683e124e.
2022-10-20 05:37:04,037 INFO: Shard ID None has successfully RESUMED session cf225ad65ea38068bf82315b683e124e.
2022-10-20 07:10:26,645 INFO: Shard ID None has successfully RESUMED session cf225ad65ea38068bf82315b683e124e.
2022-10-20 08:30:30,929 INFO: logging in using static token
2022-10-20 08:30:31,400 INFO: Shard ID None has connected to Gateway (Session ID: 33628bf68612e7a5407864c742674290).
2022-10-20 08:30:33,406 INFO: 目前登入身份：神奇海螺#3847
2022-10-20 08:30:41,664 INFO: logging in using static token
2022-10-20 08:30:42,123 INFO: Shard ID None has connected to Gateway (Session ID: 773fca58bd004655c43c27c827969b55).
2022-10-20 08:30:44,130 INFO: 目前登入身份：神奇海螺#3847
2022-10-20 08:31:16,914 ERROR: Ignoring exception in command '測試'
Traceback (most recent call last):
  File "/opt/virtualenvs/python3/lib/python3.8/site-packages/discord/app_commands/commands.py", line 851, in _do_call
    return await self._callback(interaction, **params)  # type: ignore
  File "main.py", line 449, in test
    await interaction.response.send_message("Second "+ interaction.user.name)
  File "/opt/virtualenvs/python3/lib/python3.8/site-packages/discord/interactions.py", line 692, in send_message
    raise InteractionResponded(self._parent)
discord.errors.InteractionResponded: This interaction has already been responded to before

The above exception was the direct cause of the following exception:

Traceback (most recent call last):
  File "/opt/virtualenvs/python3/lib/python3.8/site-packages/discord/app_commands/tree.py", line 1240, in _call
    await command._invoke_with_namespace(interaction, namespace)
  File "/opt/virtualenvs/python3/lib/python3.8/site-packages/discord/app_commands/commands.py", line 876, in _invoke_with_namespace
    return await self._do_call(interaction, transformed_values)
  File "/opt/virtualenvs/python3/lib/python3.8/site-packages/discord/app_commands/commands.py", line 869, in _do_call
    raise CommandInvokeError(self, e) from e
discord.app_commands.errors.CommandInvokeError: Command '測試' raised an exception: InteractionResponded: This interaction has already been responded to before
2022-10-20 08:33:05,058 INFO: logging in using static token
2022-10-20 08:33:05,454 INFO: Shard ID None has connected to Gateway (Session ID: 7a163263e685d9bb23770649d2dbdbed).
2022-10-20 08:33:07,462 INFO: 目前登入身份：神奇海螺#3847
2022-10-20 08:33:16,426 ERROR: Ignoring exception in command '測試'
Traceback (most recent call last):
  File "/opt/virtualenvs/python3/lib/python3.8/site-packages/discord/app_commands/commands.py", line 851, in _do_call
    return await self._callback(interaction, **params)  # type: ignore
  File "main.py", line 449, in test
    await interaction.message.send("Second "+ interaction.user.name)
AttributeError: 'NoneType' object has no attribute 'send'

The above exception was the direct cause of the following exception:

Traceback (most recent call last):
  File "/opt/virtualenvs/python3/lib/python3.8/site-packages/discord/app_commands/tree.py", line 1240, in _call
    await command._invoke_with_namespace(interaction, namespace)
  File "/opt/virtualenvs/python3/lib/python3.8/site-packages/discord/app_commands/commands.py", line 876, in _invoke_with_namespace
    return await self._do_call(interaction, transformed_values)
  File "/opt/virtualenvs/python3/lib/python3.8/site-packages/discord/app_commands/commands.py", line 869, in _do_call
    raise CommandInvokeError(self, e) from e
discord.app_commands.errors.CommandInvokeError: Command '測試' raised an exception: AttributeError: 'NoneType' object has no attribute 'send'
2022-10-20 08:34:23,166 ERROR: Ignoring exception in command '測試'
Traceback (most recent call last):
  File "/opt/virtualenvs/python3/lib/python3.8/site-packages/discord/app_commands/commands.py", line 851, in _do_call
    return await self._callback(interaction, **params)  # type: ignore
  File "main.py", line 449, in test
    await interaction.channel.send("Second "+ interaction.user.name)
AttributeError: 'NoneType' object has no attribute 'send'

The above exception was the direct cause of the following exception:

Traceback (most recent call last):
  File "/opt/virtualenvs/python3/lib/python3.8/site-packages/discord/app_commands/tree.py", line 1240, in _call
    await command._invoke_with_namespace(interaction, namespace)
  File "/opt/virtualenvs/python3/lib/python3.8/site-packages/discord/app_commands/commands.py", line 876, in _invoke_with_namespace
    return await self._do_call(interaction, transformed_values)
  File "/opt/virtualenvs/python3/lib/python3.8/site-packages/discord/app_commands/commands.py", line 869, in _do_call
    raise CommandInvokeError(self, e) from e
discord.app_commands.errors.CommandInvokeError: Command '測試' raised an exception: AttributeError: 'NoneType' object has no attribute 'send'
2022-10-20 08:34:40,485 INFO: logging in using static token
2022-10-20 08:34:40,836 INFO: Shard ID None has connected to Gateway (Session ID: a7d36eccbeb639ca5e842c7fc3bd2bea).
2022-10-20 08:34:42,869 INFO: 目前登入身份：神奇海螺#3847
2022-10-20 08:35:35,258 INFO: 1 in test[一般]
2022-10-20 08:35:35,377 INFO: Connecting to voice...
2022-10-20 08:35:35,377 INFO: Starting voice handshake... (connection attempt 1)
2022-10-20 08:35:35,596 INFO: Voice handshake complete. Endpoint found japan8836.discord.media
2022-10-20 08:35:38,319 INFO: ffmpeg process 5034 successfully terminated with return code of 0.
2022-10-20 08:35:39,192 INFO: 1 out test[一般]
2022-10-20 08:35:40,350 INFO: ffmpeg process 5048 successfully terminated with return code of 0.
2022-10-20 08:35:42,760 INFO: ffmpeg process 5061 successfully terminated with return code of 0.
2022-10-20 08:35:43,787 INFO: The voice handshake is being terminated for Channel ID 876364970638585882 (Guild ID 876364969904578591)
2022-10-20 08:35:43,788 INFO: Disconnecting from voice normally, close code 1000.
2022-10-20 11:24:40,126 INFO: Shard ID None has successfully RESUMED session a7d36eccbeb639ca5e842c7fc3bd2bea.
2022-10-20 15:33:15,986 INFO: logging in using static token
2022-10-20 15:33:16,509 INFO: Shard ID None has connected to Gateway (Session ID: 018342688aa3cca5d82341348899fc65).
2022-10-20 15:33:18,529 INFO: 目前登入身份：神奇海螺#3847
2022-10-20 15:33:37,898 ERROR: Ignoring exception in command '阿致分隊'
Traceback (most recent call last):
  File "/opt/virtualenvs/python3/lib/python3.8/site-packages/discord/app_commands/commands.py", line 851, in _do_call
    return await self._callback(interaction, **params)  # type: ignore
  File "main.py", line 482, in cmd_split
    user =interaction.author
AttributeError: 'Interaction' object has no attribute 'author'

The above exception was the direct cause of the following exception:

Traceback (most recent call last):
  File "/opt/virtualenvs/python3/lib/python3.8/site-packages/discord/app_commands/tree.py", line 1240, in _call
    await command._invoke_with_namespace(interaction, namespace)
  File "/opt/virtualenvs/python3/lib/python3.8/site-packages/discord/app_commands/commands.py", line 876, in _invoke_with_namespace
    return await self._do_call(interaction, transformed_values)
  File "/opt/virtualenvs/python3/lib/python3.8/site-packages/discord/app_commands/commands.py", line 869, in _do_call
    raise CommandInvokeError(self, e) from e
discord.app_commands.errors.CommandInvokeError: Command '阿致分隊' raised an exception: AttributeError: 'Interaction' object has no attribute 'author'
2022-10-20 15:34:03,945 INFO: logging in using static token
2022-10-20 15:34:04,312 INFO: Shard ID None has connected to Gateway (Session ID: d9fa89edf14e7edfd491b876801f1169).
2022-10-20 15:34:06,329 INFO: 目前登入身份：神奇海螺#3847
2022-10-20 15:34:54,121 INFO: BunnyplayGG in 9又4分之8.7月台[123是什麼敷衍的名字]
2022-10-20 15:34:54,284 INFO: Connecting to voice...
2022-10-20 15:34:54,284 INFO: Starting voice handshake... (connection attempt 1)
2022-10-20 15:34:54,540 INFO: Voice handshake complete. Endpoint found hongkong9582.discord.media
2022-10-20 15:34:57,862 INFO: ffmpeg process 782 successfully terminated with return code of 0.
2022-10-20 15:35:00,895 INFO: ffmpeg process 796 successfully terminated with return code of 0.
2022-10-20 15:35:01,923 INFO: The voice handshake is being terminated for Channel ID 728631391809437746 (Guild ID 428109526550708234)
2022-10-20 15:35:01,924 INFO: Disconnecting from voice normally, close code 1000.
