2022-10-01 22:38:18,381 INFO: logging in using static token
2022-10-01 22:38:18,618 INFO: Shard ID None has sent the IDENTIFY payload.
2022-10-01 22:38:18,768 INFO: Shard ID None has connected to Gateway: ["gateway-prd-us-east1-c-lfnx",{"micros":115273,"calls":["id_created",{"micros":1267,"calls":[]},"session_lookup_time",{"micros":456,"calls":[]},"session_lookup_finished",{"micros":14,"calls":[]},"discord-sessions-blue-prd-2-58",{"micros":110014,"calls":["start_session",{"micros":57941,"calls":["discord-api-7948bc9d7b-plg8k",{"micros":52170,"calls":["get_user",{"micros":16698},"get_guilds",{"micros":5531},"send_scheduled_deletion_message",{"micros":9},"guild_join_requests",{"micros":1},"authorized_ip_coro",{"micros":10}]}]},"starting_guild_connect",{"micros":46,"calls":[]},"presence_started",{"micros":9443,"calls":[]},"guilds_started",{"micros":141,"calls":[]},"guilds_connect",{"micros":2,"calls":[]},"presence_connect",{"micros":42413,"calls":[]},"connect_finished",{"micros":42419,"calls":[]},"build_ready",{"micros":20,"calls":[]},"optimize_ready",{"micros":1,"calls":[]},"split_ready",{"micros":1,"calls":[]},"clean_ready",{"micros":0,"calls":[]}]}]}] (Session ID: 9737e4011a9660ecfb9be701e0d80642).
2022-10-01 22:38:20,827 INFO: 目前登入身份：神奇海螺#3847
2022-10-02 02:04:50,642 INFO: Got a request to RESUME the websocket.
2022-10-02 02:04:50,786 INFO: Shard ID None has sent the RESUME payload.
2022-10-02 02:04:50,813 INFO: Shard ID None has successfully RESUMED session 9737e4011a9660ecfb9be701e0d80642 under trace ["gateway-prd-us-east1-c-c3l8",{"micros":2039,"calls":["id_created",{"micros":0,"calls":[]},"session_lookup_time",{"micros":1805,"calls":[]},"session_lookup_finished",{"micros":14,"calls":[]},"discord-sessions-blue-prd-2-58",{"micros":17}]}].
2022-10-02 02:32:06,384 INFO: Got a request to RESUME the websocket.
2022-10-02 02:32:06,553 INFO: Shard ID None has sent the RESUME payload.
2022-10-02 02:32:06,585 INFO: Shard ID None has successfully RESUMED session 9737e4011a9660ecfb9be701e0d80642 under trace ["gateway-prd-us-east1-c-mg8l",{"micros":570,"calls":["id_created",{"micros":0,"calls":[]},"session_lookup_time",{"micros":294,"calls":[]},"session_lookup_finished",{"micros":15,"calls":[]},"discord-sessions-blue-prd-2-58",{"micros":20}]}].
2022-10-02 02:48:42,674 INFO: Got a request to RESUME the websocket.
2022-10-02 02:48:42,827 INFO: Shard ID None has sent the RESUME payload.
2022-10-02 02:48:42,851 INFO: Shard ID None has successfully RESUMED session 9737e4011a9660ecfb9be701e0d80642 under trace ["gateway-prd-us-east1-c-7m6t",{"micros":1058,"calls":["id_created",{"micros":0,"calls":[]},"session_lookup_time",{"micros":669,"calls":[]},"session_lookup_finished",{"micros":16,"calls":[]},"discord-sessions-blue-prd-2-58",{"micros":31}]}].
2022-10-02 03:16:59,452 INFO: logging in using static token
2022-10-02 03:16:59,779 INFO: Shard ID None has sent the IDENTIFY payload.
2022-10-02 03:16:59,910 INFO: Shard ID None has connected to Gateway: ["gateway-prd-us-east1-b-l8pl",{"micros":50805,"calls":["id_created",{"micros":1149,"calls":[]},"session_lookup_time",{"micros":312,"calls":[]},"session_lookup_finished",{"micros":11,"calls":[]},"discord-sessions-blue-prd-2-103",{"micros":47749,"calls":["start_session",{"micros":44224,"calls":["discord-api-7948bc9d7b-qhrjs",{"micros":40561,"calls":["get_user",{"micros":7612},"get_guilds",{"micros":9011},"send_scheduled_deletion_message",{"micros":11},"guild_join_requests",{"micros":3413},"authorized_ip_coro",{"micros":31}]}]},"starting_guild_connect",{"micros":61,"calls":[]},"presence_started",{"micros":346,"calls":[]},"guilds_started",{"micros":182,"calls":[]},"guilds_connect",{"micros":1,"calls":[]},"presence_connect",{"micros":2887,"calls":[]},"connect_finished",{"micros":2902,"calls":[]},"build_ready",{"micros":31,"calls":[]},"optimize_ready",{"micros":1,"calls":[]},"split_ready",{"micros":0,"calls":[]},"clean_ready",{"micros":1,"calls":[]}]}]}] (Session ID: 2d0d7835c98a7f82ce88dc7a3f89ecc0).
2022-10-02 03:17:01,971 INFO: 目前登入身份：神奇海螺#3847
2022-10-02 03:37:49,065 INFO: Got a request to RESUME the websocket.
2022-10-02 03:37:49,253 INFO: Shard ID None has sent the RESUME payload.
2022-10-02 03:37:49,338 INFO: Shard ID None has successfully RESUMED session 2d0d7835c98a7f82ce88dc7a3f89ecc0 under trace ["gateway-prd-us-east1-c-6t96",{"micros":756,"calls":["id_created",{"micros":0,"calls":[]},"session_lookup_time",{"micros":376,"calls":[]},"session_lookup_finished",{"micros":9,"calls":[]},"discord-sessions-blue-prd-2-103",{"micros":19}]}].
2022-10-02 03:40:33,325 INFO: 貓嗷嗚飄飄大仙 in 9又4分之8.7月台[123是什麼敷衍的名字]
2022-10-02 03:40:33,372 INFO: Connecting to voice...
2022-10-02 03:40:33,373 INFO: Starting voice handshake... (connection attempt 1)
2022-10-02 03:40:33,689 INFO: Voice handshake complete. Endpoint found hongkong6360.discord.media
2022-10-02 03:40:34,525 INFO: selected the voice protocol for use (xsalsa20_poly1305_lite)
2022-10-02 03:40:34,695 INFO: received secret key for voice connection
2022-10-02 03:40:37,452 INFO: Preparing to terminate ffmpeg process 177.
2022-10-02 03:40:37,452 INFO: ffmpeg process 177 successfully terminated with return code of 0.
2022-10-02 03:40:40,151 INFO: Preparing to terminate ffmpeg process 188.
2022-10-02 03:40:40,152 INFO: ffmpeg process 188 successfully terminated with return code of 0.
2022-10-02 03:40:41,172 INFO: The voice handshake is being terminated for Channel ID 728631391809437746 (Guild ID 428109526550708234)
2022-10-02 03:40:41,173 INFO: Disconnecting from voice normally, close code 1000.
2022-10-02 04:47:16,497 INFO: 貓嗷嗚飄飄大仙 out 9又4分之8.7月台[123是什麼敷衍的名字]
2022-10-02 04:47:16,498 INFO: Connecting to voice...
2022-10-02 04:47:16,498 INFO: Starting voice handshake... (connection attempt 1)
2022-10-02 04:47:16,661 INFO: Voice handshake complete. Endpoint found oregon10000.discord.media
2022-10-02 04:47:16,767 INFO: selected the voice protocol for use (xsalsa20_poly1305_lite)
2022-10-02 04:47:16,784 INFO: received secret key for voice connection
2022-10-02 04:47:19,334 INFO: Preparing to terminate ffmpeg process 309.
2022-10-02 04:47:19,335 INFO: ffmpeg process 309 successfully terminated with return code of 0.
2022-10-02 04:47:20,408 INFO: The voice handshake is being terminated for Channel ID 728631391809437746 (Guild ID 428109526550708234)
2022-10-02 04:47:20,409 INFO: Disconnecting from voice normally, close code 1000.
2022-10-02 06:19:58,064 INFO: 貓嗷嗚飄飄大仙 in 9又4分之8.7月台[123是什麼敷衍的名字]
2022-10-02 06:19:58,178 INFO: Connecting to voice...
2022-10-02 06:19:58,178 INFO: Starting voice handshake... (connection attempt 1)
2022-10-02 06:19:58,466 INFO: Voice handshake complete. Endpoint found hongkong10004.discord.media
2022-10-02 06:19:59,317 INFO: selected the voice protocol for use (xsalsa20_poly1305_lite)
2022-10-02 06:19:59,488 INFO: received secret key for voice connection
2022-10-02 06:20:02,718 INFO: Preparing to terminate ffmpeg process 442.
2022-10-02 06:20:02,719 INFO: ffmpeg process 442 successfully terminated with return code of 0.
2022-10-02 06:20:05,798 INFO: Preparing to terminate ffmpeg process 452.
2022-10-02 06:20:05,798 INFO: ffmpeg process 452 successfully terminated with return code of 0.
2022-10-02 06:20:06,824 INFO: The voice handshake is being terminated for Channel ID 728631391809437746 (Guild ID 428109526550708234)
2022-10-02 06:20:06,825 INFO: Disconnecting from voice normally, close code 1000.
2022-10-02 07:19:43,782 INFO: Got a request to RESUME the websocket.
2022-10-02 07:19:43,976 INFO: Shard ID None has sent the RESUME payload.
2022-10-02 07:19:44,074 INFO: Shard ID None has successfully RESUMED session 2d0d7835c98a7f82ce88dc7a3f89ecc0 under trace ["gateway-prd-us-east1-b-93c5",{"micros":525,"calls":["id_created",{"micros":0,"calls":[]},"session_lookup_time",{"micros":249,"calls":[]},"session_lookup_finished",{"micros":17,"calls":[]},"discord-sessions-blue-prd-2-103",{"micros":17}]}].
2022-10-02 07:32:18,478 INFO: KyrieR in 9又4分之8.7月台[123是什麼敷衍的名字]
2022-10-02 07:32:18,619 INFO: Connecting to voice...
2022-10-02 07:32:18,619 INFO: Starting voice handshake... (connection attempt 1)
2022-10-02 07:32:18,912 INFO: Voice handshake complete. Endpoint found hongkong10004.discord.media
2022-10-02 07:32:19,746 INFO: selected the voice protocol for use (xsalsa20_poly1305_lite)
2022-10-02 07:32:19,912 INFO: received secret key for voice connection
2022-10-02 07:32:22,522 INFO: Preparing to terminate ffmpeg process 568.
2022-10-02 07:32:22,522 INFO: ffmpeg process 568 successfully terminated with return code of 0.
2022-10-02 07:32:25,141 INFO: Preparing to terminate ffmpeg process 578.
2022-10-02 07:32:25,142 INFO: ffmpeg process 578 successfully terminated with return code of 0.
2022-10-02 07:32:26,147 INFO: The voice handshake is being terminated for Channel ID 728631391809437746 (Guild ID 428109526550708234)
2022-10-02 07:32:26,148 INFO: Disconnecting from voice normally, close code 1000.
2022-10-02 07:39:06,719 INFO: 貓嗷嗚飄飄大仙 out 9又4分之8.7月台[123是什麼敷衍的名字]
2022-10-02 07:39:06,719 INFO: Connecting to voice...
2022-10-02 07:39:06,720 INFO: Starting voice handshake... (connection attempt 1)
2022-10-02 07:39:07,061 INFO: Voice handshake complete. Endpoint found hongkong10004.discord.media
2022-10-02 07:39:07,917 INFO: selected the voice protocol for use (xsalsa20_poly1305_lite)
2022-10-02 07:39:08,086 INFO: received secret key for voice connection
2022-10-02 07:39:08,895 INFO: KyrieR out 9又4分之8.7月台[123是什麼敷衍的名字]
2022-10-02 07:39:10,635 INFO: Preparing to terminate ffmpeg process 607.
2022-10-02 07:39:10,635 INFO: ffmpeg process 607 successfully terminated with return code of 0.
2022-10-02 07:39:13,512 INFO: Preparing to terminate ffmpeg process 617.
2022-10-02 07:39:13,513 INFO: ffmpeg process 617 successfully terminated with return code of 0.
2022-10-02 07:39:14,525 INFO: The voice handshake is being terminated for Channel ID 728631391809437746 (Guild ID 428109526550708234)
2022-10-02 07:39:14,525 INFO: Disconnecting from voice normally, close code 1000.
2022-10-02 10:10:57,962 INFO: Got a request to RESUME the websocket.
2022-10-02 10:10:58,146 INFO: Shard ID None has sent the RESUME payload.
2022-10-02 10:10:58,229 INFO: Shard ID None has successfully RESUMED session 2d0d7835c98a7f82ce88dc7a3f89ecc0 under trace ["gateway-prd-us-east1-c-11zr",{"micros":685,"calls":["id_created",{"micros":0,"calls":[]},"session_lookup_time",{"micros":328,"calls":[]},"session_lookup_finished",{"micros":14,"calls":[]},"discord-sessions-blue-prd-2-103",{"micros":15}]}].
2022-10-02 10:30:06,520 INFO: Chi in 9又4分之8.7月台[123是什麼敷衍的名字]
2022-10-02 10:30:06,661 INFO: Connecting to voice...
2022-10-02 10:30:06,661 INFO: Starting voice handshake... (connection attempt 1)
2022-10-02 10:30:06,958 INFO: Voice handshake complete. Endpoint found hongkong7364.discord.media
2022-10-02 10:30:07,796 INFO: selected the voice protocol for use (xsalsa20_poly1305_lite)
2022-10-02 10:30:07,962 INFO: received secret key for voice connection
2022-10-02 10:30:10,151 INFO: Preparing to terminate ffmpeg process 875.
2022-10-02 10:30:10,152 INFO: ffmpeg process 875 successfully terminated with return code of 0.
2022-10-02 10:30:13,166 INFO: Preparing to terminate ffmpeg process 885.
2022-10-02 10:30:13,167 INFO: ffmpeg process 885 successfully terminated with return code of 0.
2022-10-02 10:30:14,199 INFO: The voice handshake is being terminated for Channel ID 728631391809437746 (Guild ID 428109526550708234)
2022-10-02 10:30:14,200 INFO: Disconnecting from voice normally, close code 1000.
2022-10-02 11:00:07,605 INFO: BunnyplayGG in 9又4分之8.7月台[123是什麼敷衍的名字]
2022-10-02 11:00:07,707 INFO: Connecting to voice...
2022-10-02 11:00:07,707 INFO: Starting voice handshake... (connection attempt 1)
2022-10-02 11:00:07,999 INFO: Voice handshake complete. Endpoint found hongkong7364.discord.media
2022-10-02 11:00:08,841 INFO: selected the voice protocol for use (xsalsa20_poly1305_lite)
2022-10-02 11:00:09,009 INFO: received secret key for voice connection
2022-10-02 11:00:11,401 INFO: Preparing to terminate ffmpeg process 950.
2022-10-02 11:00:11,402 INFO: ffmpeg process 950 successfully terminated with return code of 0.
2022-10-02 11:00:13,727 INFO: Preparing to terminate ffmpeg process 960.
2022-10-02 11:00:13,728 INFO: ffmpeg process 960 successfully terminated with return code of 0.
2022-10-02 11:00:14,754 INFO: The voice handshake is being terminated for Channel ID 728631391809437746 (Guild ID 428109526550708234)
2022-10-02 11:00:14,755 INFO: Disconnecting from voice normally, close code 1000.
2022-10-02 11:00:37,448 INFO: BunnyplayGG out 9又4分之8.7月台[123是什麼敷衍的名字]
2022-10-02 11:00:37,449 INFO: Connecting to voice...
2022-10-02 11:00:37,449 INFO: Starting voice handshake... (connection attempt 1)
2022-10-02 11:00:37,815 INFO: Voice handshake complete. Endpoint found hongkong7364.discord.media
2022-10-02 11:00:38,649 INFO: selected the voice protocol for use (xsalsa20_poly1305_lite)
2022-10-02 11:00:38,827 INFO: received secret key for voice connection
2022-10-02 11:00:41,197 INFO: Preparing to terminate ffmpeg process 971.
2022-10-02 11:00:41,198 INFO: ffmpeg process 971 successfully terminated with return code of 0.
2022-10-02 11:00:42,247 INFO: The voice handshake is being terminated for Channel ID 728631391809437746 (Guild ID 428109526550708234)
2022-10-02 11:00:42,248 INFO: Disconnecting from voice normally, close code 1000.
2022-10-02 11:07:32,137 INFO: Chi out 9又4分之8.7月台[123是什麼敷衍的名字]
2022-10-02 11:07:32,137 INFO: Connecting to voice...
2022-10-02 11:07:32,137 INFO: Starting voice handshake... (connection attempt 1)
2022-10-02 11:07:32,292 INFO: Voice handshake complete. Endpoint found oregon10001.discord.media
2022-10-02 11:07:32,399 INFO: selected the voice protocol for use (xsalsa20_poly1305_lite)
2022-10-02 11:07:32,416 INFO: received secret key for voice connection
2022-10-02 11:07:33,986 INFO: Preparing to terminate ffmpeg process 982.
2022-10-02 11:07:33,987 INFO: ffmpeg process 982 successfully terminated with return code of 0.
2022-10-02 11:07:35,033 INFO: The voice handshake is being terminated for Channel ID 728631391809437746 (Guild ID 428109526550708234)
2022-10-02 11:07:35,034 INFO: Disconnecting from voice normally, close code 1000.
2022-10-02 13:12:19,946 INFO: 貓嗷嗚飄飄大仙 in 9又4分之8.7月台[123是什麼敷衍的名字]
2022-10-02 13:12:19,994 INFO: Connecting to voice...
2022-10-02 13:12:19,995 INFO: Starting voice handshake... (connection attempt 1)
2022-10-02 13:12:20,283 INFO: Voice handshake complete. Endpoint found hongkong8036.discord.media
2022-10-02 13:12:21,142 INFO: selected the voice protocol for use (xsalsa20_poly1305_lite)
2022-10-02 13:12:21,316 INFO: received secret key for voice connection
2022-10-02 13:12:24,544 INFO: Preparing to terminate ffmpeg process 1191.
2022-10-02 13:12:24,545 INFO: ffmpeg process 1191 successfully terminated with return code of 0.
2022-10-02 13:12:26,743 INFO: Preparing to terminate ffmpeg process 1201.
2022-10-02 13:12:26,744 INFO: ffmpeg process 1201 successfully terminated with return code of 0.
2022-10-02 13:12:27,748 INFO: The voice handshake is being terminated for Channel ID 728631391809437746 (Guild ID 428109526550708234)
2022-10-02 13:12:27,749 INFO: Disconnecting from voice normally, close code 1000.
2022-10-02 13:17:21,205 INFO: 神奇海螺 in 9又4分之8.7月台[123是什麼敷衍的名字]
2022-10-02 13:17:21,253 INFO: Connecting to voice...
2022-10-02 13:17:21,253 INFO: Starting voice handshake... (connection attempt 1)
2022-10-02 13:17:21,544 INFO: Voice handshake complete. Endpoint found hongkong8036.discord.media
2022-10-02 13:17:22,438 INFO: selected the voice protocol for use (xsalsa20_poly1305_lite)
2022-10-02 13:17:22,615 INFO: received secret key for voice connection
2022-10-02 13:17:25,487 INFO: Preparing to terminate ffmpeg process 1212.
2022-10-02 13:17:25,488 INFO: ffmpeg process 1212 successfully terminated with return code of 0.
2022-10-02 13:17:28,382 INFO: Preparing to terminate ffmpeg process 1222.
2022-10-02 13:17:28,382 INFO: ffmpeg process 1222 successfully terminated with return code of 0.
2022-10-02 13:17:29,472 INFO: The voice handshake is being terminated for Channel ID 728631391809437746 (Guild ID 428109526550708234)
2022-10-02 13:17:29,472 INFO: Disconnecting from voice normally, close code 1000.
2022-10-02 13:17:31,920 INFO: MaiMai的Pool in 9又4分之8.7月台[123是什麼敷衍的名字]
2022-10-02 13:17:32,017 INFO: Connecting to voice...
2022-10-02 13:17:32,018 INFO: Starting voice handshake... (connection attempt 1)
2022-10-02 13:17:32,329 INFO: Voice handshake complete. Endpoint found hongkong8036.discord.media
2022-10-02 13:17:33,201 INFO: selected the voice protocol for use (xsalsa20_poly1305_lite)
2022-10-02 13:17:33,366 INFO: received secret key for voice connection
2022-10-02 13:17:35,659 INFO: Preparing to terminate ffmpeg process 1233.
2022-10-02 13:17:35,660 INFO: ffmpeg process 1233 successfully terminated with return code of 0.
2022-10-02 13:17:38,439 INFO: Preparing to terminate ffmpeg process 1243.
2022-10-02 13:17:38,440 INFO: ffmpeg process 1243 successfully terminated with return code of 0.
2022-10-02 13:17:39,511 INFO: The voice handshake is being terminated for Channel ID 728631391809437746 (Guild ID 428109526550708234)
2022-10-02 13:17:39,512 INFO: Disconnecting from voice normally, close code 1000.
2022-10-02 13:25:31,069 INFO: wawa的n in 9又4分之8.7月台[123是什麼敷衍的名字]
2022-10-02 13:25:31,118 INFO: Connecting to voice...
2022-10-02 13:25:31,118 INFO: Starting voice handshake... (connection attempt 1)
2022-10-02 13:25:31,442 INFO: Voice handshake complete. Endpoint found hongkong8036.discord.media
2022-10-02 13:25:32,337 INFO: selected the voice protocol for use (xsalsa20_poly1305_lite)
2022-10-02 13:25:32,503 INFO: received secret key for voice connection
2022-10-02 13:25:34,654 INFO: Preparing to terminate ffmpeg process 1272.
2022-10-02 13:25:34,654 INFO: ffmpeg process 1272 successfully terminated with return code of 0.
2022-10-02 13:25:37,333 INFO: Preparing to terminate ffmpeg process 1282.
2022-10-02 13:25:37,334 INFO: ffmpeg process 1282 successfully terminated with return code of 0.
2022-10-02 13:25:38,343 INFO: The voice handshake is being terminated for Channel ID 728631391809437746 (Guild ID 428109526550708234)
2022-10-02 13:25:38,343 INFO: Disconnecting from voice normally, close code 1000.
2022-10-02 13:27:19,669 INFO: Got a request to RESUME the websocket.
2022-10-02 13:27:19,723 ERROR: Attempting a reconnect in 1.97s
Traceback (most recent call last):
  File "/opt/virtualenvs/python3/lib/python3.8/site-packages/discord/http.py", line 967, in get_gateway
    data = await self.request(Route('GET', '/gateway'))
  File "/opt/virtualenvs/python3/lib/python3.8/site-packages/discord/http.py", line 216, in request
    raise HTTPException(r, data)
discord.errors.HTTPException: 429 Too Many Requests (error code: 0): You are being blocked from accessing our API temporarily due to exceeding our rate limits frequently. Please read our docs at https://discord.com/developers/docs/topics/rate-limits to prevent this moving forward.

The above exception was the direct cause of the following exception:

Traceback (most recent call last):
  File "/opt/virtualenvs/python3/lib/python3.8/site-packages/discord/client.py", line 563, in connect
    self.ws = await asyncio.wait_for(coro, timeout=60.0)
  File "/usr/lib/python3.8/asyncio/tasks.py", line 494, in wait_for
    return fut.result()
  File "/opt/virtualenvs/python3/lib/python3.8/site-packages/discord/gateway.py", line 305, in from_client
    gateway = gateway or await client.http.get_gateway()
  File "/opt/virtualenvs/python3/lib/python3.8/site-packages/discord/http.py", line 969, in get_gateway
    raise GatewayNotFound() from exc
discord.errors.GatewayNotFound: The gateway to connect to discord was not found.
2022-10-02 13:27:21,737 ERROR: Attempting a reconnect in 0.80s
Traceback (most recent call last):
  File "/opt/virtualenvs/python3/lib/python3.8/site-packages/discord/http.py", line 967, in get_gateway
    data = await self.request(Route('GET', '/gateway'))
  File "/opt/virtualenvs/python3/lib/python3.8/site-packages/discord/http.py", line 216, in request
    raise HTTPException(r, data)
discord.errors.HTTPException: 429 Too Many Requests (error code: 0): You are being blocked from accessing our API temporarily due to exceeding our rate limits frequently. Please read our docs at https://discord.com/developers/docs/topics/rate-limits to prevent this moving forward.

The above exception was the direct cause of the following exception:

Traceback (most recent call last):
  File "/opt/virtualenvs/python3/lib/python3.8/site-packages/discord/client.py", line 563, in connect
    self.ws = await asyncio.wait_for(coro, timeout=60.0)
  File "/usr/lib/python3.8/asyncio/tasks.py", line 494, in wait_for
    return fut.result()
  File "/opt/virtualenvs/python3/lib/python3.8/site-packages/discord/gateway.py", line 305, in from_client
    gateway = gateway or await client.http.get_gateway()
  File "/opt/virtualenvs/python3/lib/python3.8/site-packages/discord/http.py", line 969, in get_gateway
    raise GatewayNotFound() from exc
discord.errors.GatewayNotFound: The gateway to connect to discord was not found.
2022-10-02 13:27:22,581 ERROR: Attempting a reconnect in 2.29s
Traceback (most recent call last):
  File "/opt/virtualenvs/python3/lib/python3.8/site-packages/discord/http.py", line 967, in get_gateway
    data = await self.request(Route('GET', '/gateway'))
  File "/opt/virtualenvs/python3/lib/python3.8/site-packages/discord/http.py", line 216, in request
    raise HTTPException(r, data)
discord.errors.HTTPException: 429 Too Many Requests (error code: 0): You are being blocked from accessing our API temporarily due to exceeding our rate limits frequently. Please read our docs at https://discord.com/developers/docs/topics/rate-limits to prevent this moving forward.

The above exception was the direct cause of the following exception:

Traceback (most recent call last):
  File "/opt/virtualenvs/python3/lib/python3.8/site-packages/discord/client.py", line 563, in connect
    self.ws = await asyncio.wait_for(coro, timeout=60.0)
  File "/usr/lib/python3.8/asyncio/tasks.py", line 494, in wait_for
    return fut.result()
  File "/opt/virtualenvs/python3/lib/python3.8/site-packages/discord/gateway.py", line 305, in from_client
    gateway = gateway or await client.http.get_gateway()
  File "/opt/virtualenvs/python3/lib/python3.8/site-packages/discord/http.py", line 969, in get_gateway
    raise GatewayNotFound() from exc
discord.errors.GatewayNotFound: The gateway to connect to discord was not found.
2022-10-02 13:27:24,908 ERROR: Attempting a reconnect in 15.97s
Traceback (most recent call last):
  File "/opt/virtualenvs/python3/lib/python3.8/site-packages/discord/http.py", line 967, in get_gateway
    data = await self.request(Route('GET', '/gateway'))
  File "/opt/virtualenvs/python3/lib/python3.8/site-packages/discord/http.py", line 216, in request
    raise HTTPException(r, data)
discord.errors.HTTPException: 429 Too Many Requests (error code: 0): You are being blocked from accessing our API temporarily due to exceeding our rate limits frequently. Please read our docs at https://discord.com/developers/docs/topics/rate-limits to prevent this moving forward.

The above exception was the direct cause of the following exception:

Traceback (most recent call last):
  File "/opt/virtualenvs/python3/lib/python3.8/site-packages/discord/client.py", line 563, in connect
    self.ws = await asyncio.wait_for(coro, timeout=60.0)
  File "/usr/lib/python3.8/asyncio/tasks.py", line 494, in wait_for
    return fut.result()
  File "/opt/virtualenvs/python3/lib/python3.8/site-packages/discord/gateway.py", line 305, in from_client
    gateway = gateway or await client.http.get_gateway()
  File "/opt/virtualenvs/python3/lib/python3.8/site-packages/discord/http.py", line 969, in get_gateway
    raise GatewayNotFound() from exc
discord.errors.GatewayNotFound: The gateway to connect to discord was not found.
2022-10-02 13:27:40,940 ERROR: Attempting a reconnect in 15.90s
Traceback (most recent call last):
  File "/opt/virtualenvs/python3/lib/python3.8/site-packages/discord/http.py", line 967, in get_gateway
    data = await self.request(Route('GET', '/gateway'))
  File "/opt/virtualenvs/python3/lib/python3.8/site-packages/discord/http.py", line 216, in request
    raise HTTPException(r, data)
discord.errors.HTTPException: 429 Too Many Requests (error code: 0): You are being blocked from accessing our API temporarily due to exceeding our rate limits frequently. Please read our docs at https://discord.com/developers/docs/topics/rate-limits to prevent this moving forward.

The above exception was the direct cause of the following exception:

Traceback (most recent call last):
  File "/opt/virtualenvs/python3/lib/python3.8/site-packages/discord/client.py", line 563, in connect
    self.ws = await asyncio.wait_for(coro, timeout=60.0)
  File "/usr/lib/python3.8/asyncio/tasks.py", line 494, in wait_for
    return fut.result()
  File "/opt/virtualenvs/python3/lib/python3.8/site-packages/discord/gateway.py", line 305, in from_client
    gateway = gateway or await client.http.get_gateway()
  File "/opt/virtualenvs/python3/lib/python3.8/site-packages/discord/http.py", line 969, in get_gateway
    raise GatewayNotFound() from exc
discord.errors.GatewayNotFound: The gateway to connect to discord was not found.
2022-10-02 13:27:56,901 ERROR: Attempting a reconnect in 13.83s
Traceback (most recent call last):
  File "/opt/virtualenvs/python3/lib/python3.8/site-packages/discord/http.py", line 967, in get_gateway
    data = await self.request(Route('GET', '/gateway'))
  File "/opt/virtualenvs/python3/lib/python3.8/site-packages/discord/http.py", line 216, in request
    raise HTTPException(r, data)
discord.errors.HTTPException: 429 Too Many Requests (error code: 0): You are being blocked from accessing our API temporarily due to exceeding our rate limits frequently. Please read our docs at https://discord.com/developers/docs/topics/rate-limits to prevent this moving forward.

The above exception was the direct cause of the following exception:

Traceback (most recent call last):
  File "/opt/virtualenvs/python3/lib/python3.8/site-packages/discord/client.py", line 563, in connect
    self.ws = await asyncio.wait_for(coro, timeout=60.0)
  File "/usr/lib/python3.8/asyncio/tasks.py", line 494, in wait_for
    return fut.result()
  File "/opt/virtualenvs/python3/lib/python3.8/site-packages/discord/gateway.py", line 305, in from_client
    gateway = gateway or await client.http.get_gateway()
  File "/opt/virtualenvs/python3/lib/python3.8/site-packages/discord/http.py", line 969, in get_gateway
    raise GatewayNotFound() from exc
discord.errors.GatewayNotFound: The gateway to connect to discord was not found.
2022-10-02 13:28:10,796 ERROR: Attempting a reconnect in 121.25s
Traceback (most recent call last):
  File "/opt/virtualenvs/python3/lib/python3.8/site-packages/discord/http.py", line 967, in get_gateway
    data = await self.request(Route('GET', '/gateway'))
  File "/opt/virtualenvs/python3/lib/python3.8/site-packages/discord/http.py", line 216, in request
    raise HTTPException(r, data)
discord.errors.HTTPException: 429 Too Many Requests (error code: 0): You are being blocked from accessing our API temporarily due to exceeding our rate limits frequently. Please read our docs at https://discord.com/developers/docs/topics/rate-limits to prevent this moving forward.

The above exception was the direct cause of the following exception:

Traceback (most recent call last):
  File "/opt/virtualenvs/python3/lib/python3.8/site-packages/discord/client.py", line 563, in connect
    self.ws = await asyncio.wait_for(coro, timeout=60.0)
  File "/usr/lib/python3.8/asyncio/tasks.py", line 494, in wait_for
    return fut.result()
  File "/opt/virtualenvs/python3/lib/python3.8/site-packages/discord/gateway.py", line 305, in from_client
    gateway = gateway or await client.http.get_gateway()
  File "/opt/virtualenvs/python3/lib/python3.8/site-packages/discord/http.py", line 969, in get_gateway
    raise GatewayNotFound() from exc
discord.errors.GatewayNotFound: The gateway to connect to discord was not found.
2022-10-02 13:30:12,197 ERROR: Attempting a reconnect in 204.38s
Traceback (most recent call last):
  File "/opt/virtualenvs/python3/lib/python3.8/site-packages/discord/http.py", line 967, in get_gateway
    data = await self.request(Route('GET', '/gateway'))
  File "/opt/virtualenvs/python3/lib/python3.8/site-packages/discord/http.py", line 216, in request
    raise HTTPException(r, data)
discord.errors.HTTPException: 429 Too Many Requests (error code: 0): You are being blocked from accessing our API temporarily due to exceeding our rate limits frequently. Please read our docs at https://discord.com/developers/docs/topics/rate-limits to prevent this moving forward.

The above exception was the direct cause of the following exception:

Traceback (most recent call last):
  File "/opt/virtualenvs/python3/lib/python3.8/site-packages/discord/client.py", line 563, in connect
    self.ws = await asyncio.wait_for(coro, timeout=60.0)
  File "/usr/lib/python3.8/asyncio/tasks.py", line 494, in wait_for
    return fut.result()
  File "/opt/virtualenvs/python3/lib/python3.8/site-packages/discord/gateway.py", line 305, in from_client
    gateway = gateway or await client.http.get_gateway()
  File "/opt/virtualenvs/python3/lib/python3.8/site-packages/discord/http.py", line 969, in get_gateway
    raise GatewayNotFound() from exc
discord.errors.GatewayNotFound: The gateway to connect to discord was not found.
2022-10-02 13:33:36,737 ERROR: Attempting a reconnect in 143.54s
Traceback (most recent call last):
  File "/opt/virtualenvs/python3/lib/python3.8/site-packages/discord/http.py", line 967, in get_gateway
    data = await self.request(Route('GET', '/gateway'))
  File "/opt/virtualenvs/python3/lib/python3.8/site-packages/discord/http.py", line 216, in request
    raise HTTPException(r, data)
discord.errors.HTTPException: 429 Too Many Requests (error code: 0): You are being blocked from accessing our API temporarily due to exceeding our rate limits frequently. Please read our docs at https://discord.com/developers/docs/topics/rate-limits to prevent this moving forward.

The above exception was the direct cause of the following exception:

Traceback (most recent call last):
  File "/opt/virtualenvs/python3/lib/python3.8/site-packages/discord/client.py", line 563, in connect
    self.ws = await asyncio.wait_for(coro, timeout=60.0)
  File "/usr/lib/python3.8/asyncio/tasks.py", line 494, in wait_for
    return fut.result()
  File "/opt/virtualenvs/python3/lib/python3.8/site-packages/discord/gateway.py", line 305, in from_client
    gateway = gateway or await client.http.get_gateway()
  File "/opt/virtualenvs/python3/lib/python3.8/site-packages/discord/http.py", line 969, in get_gateway
    raise GatewayNotFound() from exc
discord.errors.GatewayNotFound: The gateway to connect to discord was not found.
2022-10-02 13:36:00,429 ERROR: Attempting a reconnect in 470.16s
Traceback (most recent call last):
  File "/opt/virtualenvs/python3/lib/python3.8/site-packages/discord/http.py", line 967, in get_gateway
    data = await self.request(Route('GET', '/gateway'))
  File "/opt/virtualenvs/python3/lib/python3.8/site-packages/discord/http.py", line 216, in request
    raise HTTPException(r, data)
discord.errors.HTTPException: 429 Too Many Requests (error code: 0): You are being blocked from accessing our API temporarily due to exceeding our rate limits frequently. Please read our docs at https://discord.com/developers/docs/topics/rate-limits to prevent this moving forward.

The above exception was the direct cause of the following exception:

Traceback (most recent call last):
  File "/opt/virtualenvs/python3/lib/python3.8/site-packages/discord/client.py", line 563, in connect
    self.ws = await asyncio.wait_for(coro, timeout=60.0)
  File "/usr/lib/python3.8/asyncio/tasks.py", line 494, in wait_for
    return fut.result()
  File "/opt/virtualenvs/python3/lib/python3.8/site-packages/discord/gateway.py", line 305, in from_client
    gateway = gateway or await client.http.get_gateway()
  File "/opt/virtualenvs/python3/lib/python3.8/site-packages/discord/http.py", line 969, in get_gateway
    raise GatewayNotFound() from exc
discord.errors.GatewayNotFound: The gateway to connect to discord was not found.
2022-10-02 13:43:50,748 ERROR: Attempting a reconnect in 43.75s
Traceback (most recent call last):
  File "/opt/virtualenvs/python3/lib/python3.8/site-packages/discord/http.py", line 967, in get_gateway
    data = await self.request(Route('GET', '/gateway'))
  File "/opt/virtualenvs/python3/lib/python3.8/site-packages/discord/http.py", line 216, in request
    raise HTTPException(r, data)
discord.errors.HTTPException: 429 Too Many Requests (error code: 0): You are being blocked from accessing our API temporarily due to exceeding our rate limits frequently. Please read our docs at https://discord.com/developers/docs/topics/rate-limits to prevent this moving forward.

The above exception was the direct cause of the following exception:

Traceback (most recent call last):
  File "/opt/virtualenvs/python3/lib/python3.8/site-packages/discord/client.py", line 563, in connect
    self.ws = await asyncio.wait_for(coro, timeout=60.0)
  File "/usr/lib/python3.8/asyncio/tasks.py", line 494, in wait_for
    return fut.result()
  File "/opt/virtualenvs/python3/lib/python3.8/site-packages/discord/gateway.py", line 305, in from_client
    gateway = gateway or await client.http.get_gateway()
  File "/opt/virtualenvs/python3/lib/python3.8/site-packages/discord/http.py", line 969, in get_gateway
    raise GatewayNotFound() from exc
discord.errors.GatewayNotFound: The gateway to connect to discord was not found.
2022-10-02 13:44:34,600 ERROR: Attempting a reconnect in 418.74s
Traceback (most recent call last):
  File "/opt/virtualenvs/python3/lib/python3.8/site-packages/discord/http.py", line 967, in get_gateway
    data = await self.request(Route('GET', '/gateway'))
  File "/opt/virtualenvs/python3/lib/python3.8/site-packages/discord/http.py", line 216, in request
    raise HTTPException(r, data)
discord.errors.HTTPException: 429 Too Many Requests (error code: 0): You are being blocked from accessing our API temporarily due to exceeding our rate limits frequently. Please read our docs at https://discord.com/developers/docs/topics/rate-limits to prevent this moving forward.

The above exception was the direct cause of the following exception:

Traceback (most recent call last):
  File "/opt/virtualenvs/python3/lib/python3.8/site-packages/discord/client.py", line 563, in connect
    self.ws = await asyncio.wait_for(coro, timeout=60.0)
  File "/usr/lib/python3.8/asyncio/tasks.py", line 494, in wait_for
    return fut.result()
  File "/opt/virtualenvs/python3/lib/python3.8/site-packages/discord/gateway.py", line 305, in from_client
    gateway = gateway or await client.http.get_gateway()
  File "/opt/virtualenvs/python3/lib/python3.8/site-packages/discord/http.py", line 969, in get_gateway
    raise GatewayNotFound() from exc
discord.errors.GatewayNotFound: The gateway to connect to discord was not found.
2022-10-02 13:51:33,485 ERROR: Attempting a reconnect in 322.27s
Traceback (most recent call last):
  File "/opt/virtualenvs/python3/lib/python3.8/site-packages/discord/http.py", line 967, in get_gateway
    data = await self.request(Route('GET', '/gateway'))
  File "/opt/virtualenvs/python3/lib/python3.8/site-packages/discord/http.py", line 216, in request
    raise HTTPException(r, data)
discord.errors.HTTPException: 429 Too Many Requests (error code: 0): You are being blocked from accessing our API temporarily due to exceeding our rate limits frequently. Please read our docs at https://discord.com/developers/docs/topics/rate-limits to prevent this moving forward.

The above exception was the direct cause of the following exception:

Traceback (most recent call last):
  File "/opt/virtualenvs/python3/lib/python3.8/site-packages/discord/client.py", line 563, in connect
    self.ws = await asyncio.wait_for(coro, timeout=60.0)
  File "/usr/lib/python3.8/asyncio/tasks.py", line 494, in wait_for
    return fut.result()
  File "/opt/virtualenvs/python3/lib/python3.8/site-packages/discord/gateway.py", line 305, in from_client
    gateway = gateway or await client.http.get_gateway()
  File "/opt/virtualenvs/python3/lib/python3.8/site-packages/discord/http.py", line 969, in get_gateway
    raise GatewayNotFound() from exc
discord.errors.GatewayNotFound: The gateway to connect to discord was not found.
2022-10-02 13:56:55,903 ERROR: Attempting a reconnect in 664.17s
Traceback (most recent call last):
  File "/opt/virtualenvs/python3/lib/python3.8/site-packages/discord/http.py", line 967, in get_gateway
    data = await self.request(Route('GET', '/gateway'))
  File "/opt/virtualenvs/python3/lib/python3.8/site-packages/discord/http.py", line 216, in request
    raise HTTPException(r, data)
discord.errors.HTTPException: 429 Too Many Requests (error code: 0): You are being blocked from accessing our API temporarily due to exceeding our rate limits frequently. Please read our docs at https://discord.com/developers/docs/topics/rate-limits to prevent this moving forward.

The above exception was the direct cause of the following exception:

Traceback (most recent call last):
  File "/opt/virtualenvs/python3/lib/python3.8/site-packages/discord/client.py", line 563, in connect
    self.ws = await asyncio.wait_for(coro, timeout=60.0)
  File "/usr/lib/python3.8/asyncio/tasks.py", line 494, in wait_for
    return fut.result()
  File "/opt/virtualenvs/python3/lib/python3.8/site-packages/discord/gateway.py", line 305, in from_client
    gateway = gateway or await client.http.get_gateway()
  File "/opt/virtualenvs/python3/lib/python3.8/site-packages/discord/http.py", line 969, in get_gateway
    raise GatewayNotFound() from exc
discord.errors.GatewayNotFound: The gateway to connect to discord was not found.
2022-10-02 14:08:00,228 ERROR: Attempting a reconnect in 323.30s
Traceback (most recent call last):
  File "/opt/virtualenvs/python3/lib/python3.8/site-packages/discord/http.py", line 967, in get_gateway
    data = await self.request(Route('GET', '/gateway'))
  File "/opt/virtualenvs/python3/lib/python3.8/site-packages/discord/http.py", line 216, in request
    raise HTTPException(r, data)
discord.errors.HTTPException: 429 Too Many Requests (error code: 0): You are being blocked from accessing our API temporarily due to exceeding our rate limits frequently. Please read our docs at https://discord.com/developers/docs/topics/rate-limits to prevent this moving forward.

The above exception was the direct cause of the following exception:

Traceback (most recent call last):
  File "/opt/virtualenvs/python3/lib/python3.8/site-packages/discord/client.py", line 563, in connect
    self.ws = await asyncio.wait_for(coro, timeout=60.0)
  File "/usr/lib/python3.8/asyncio/tasks.py", line 494, in wait_for
    return fut.result()
  File "/opt/virtualenvs/python3/lib/python3.8/site-packages/discord/gateway.py", line 305, in from_client
    gateway = gateway or await client.http.get_gateway()
  File "/opt/virtualenvs/python3/lib/python3.8/site-packages/discord/http.py", line 969, in get_gateway
    raise GatewayNotFound() from exc
discord.errors.GatewayNotFound: The gateway to connect to discord was not found.
2022-10-02 14:13:23,682 ERROR: Attempting a reconnect in 243.00s
Traceback (most recent call last):
  File "/opt/virtualenvs/python3/lib/python3.8/site-packages/discord/http.py", line 967, in get_gateway
    data = await self.request(Route('GET', '/gateway'))
  File "/opt/virtualenvs/python3/lib/python3.8/site-packages/discord/http.py", line 216, in request
    raise HTTPException(r, data)
discord.errors.HTTPException: 429 Too Many Requests (error code: 0): You are being blocked from accessing our API temporarily due to exceeding our rate limits frequently. Please read our docs at https://discord.com/developers/docs/topics/rate-limits to prevent this moving forward.

The above exception was the direct cause of the following exception:

Traceback (most recent call last):
  File "/opt/virtualenvs/python3/lib/python3.8/site-packages/discord/client.py", line 563, in connect
    self.ws = await asyncio.wait_for(coro, timeout=60.0)
  File "/usr/lib/python3.8/asyncio/tasks.py", line 494, in wait_for
    return fut.result()
  File "/opt/virtualenvs/python3/lib/python3.8/site-packages/discord/gateway.py", line 305, in from_client
    gateway = gateway or await client.http.get_gateway()
  File "/opt/virtualenvs/python3/lib/python3.8/site-packages/discord/http.py", line 969, in get_gateway
    raise GatewayNotFound() from exc
discord.errors.GatewayNotFound: The gateway to connect to discord was not found.
2022-10-02 14:17:26,836 ERROR: Attempting a reconnect in 598.96s
Traceback (most recent call last):
  File "/opt/virtualenvs/python3/lib/python3.8/site-packages/discord/http.py", line 967, in get_gateway
    data = await self.request(Route('GET', '/gateway'))
  File "/opt/virtualenvs/python3/lib/python3.8/site-packages/discord/http.py", line 216, in request
    raise HTTPException(r, data)
discord.errors.HTTPException: 429 Too Many Requests (error code: 0): You are being blocked from accessing our API temporarily due to exceeding our rate limits frequently. Please read our docs at https://discord.com/developers/docs/topics/rate-limits to prevent this moving forward.

The above exception was the direct cause of the following exception:

Traceback (most recent call last):
  File "/opt/virtualenvs/python3/lib/python3.8/site-packages/discord/client.py", line 563, in connect
    self.ws = await asyncio.wait_for(coro, timeout=60.0)
  File "/usr/lib/python3.8/asyncio/tasks.py", line 494, in wait_for
    return fut.result()
  File "/opt/virtualenvs/python3/lib/python3.8/site-packages/discord/gateway.py", line 305, in from_client
    gateway = gateway or await client.http.get_gateway()
  File "/opt/virtualenvs/python3/lib/python3.8/site-packages/discord/http.py", line 969, in get_gateway
    raise GatewayNotFound() from exc
discord.errors.GatewayNotFound: The gateway to connect to discord was not found.
2022-10-02 14:27:26,096 INFO: Shard ID None has sent the RESUME payload.
2022-10-02 14:27:26,181 INFO: Shard ID None session has been invalidated.
2022-10-02 14:27:26,265 INFO: Got a request to IDENTIFY the websocket.
2022-10-02 14:27:31,405 INFO: Shard ID None has sent the IDENTIFY payload.
2022-10-02 14:27:31,565 INFO: Shard ID None has connected to Gateway: ["gateway-prd-us-east1-c-lfnx",{"micros":79894,"calls":["id_created",{"micros":1152,"calls":[]},"session_lookup_time",{"micros":391,"calls":[]},"session_lookup_finished",{"micros":13,"calls":[]},"discord-sessions-blue-prd-2-46",{"micros":77241,"calls":["start_session",{"micros":41368,"calls":["discord-api-7948bc9d7b-zt2lz",{"micros":36423,"calls":["get_user",{"micros":11495},"get_guilds",{"micros":4385},"send_scheduled_deletion_message",{"micros":12},"guild_join_requests",{"micros":2},"authorized_ip_coro",{"micros":13}]}]},"starting_guild_connect",{"micros":56,"calls":[]},"presence_started",{"micros":15295,"calls":[]},"guilds_started",{"micros":163,"calls":[]},"guilds_connect",{"micros":1,"calls":[]},"presence_connect",{"micros":20334,"calls":[]},"connect_finished",{"micros":20339,"calls":[]},"build_ready",{"micros":17,"calls":[]},"optimize_ready",{"micros":0,"calls":[]},"split_ready",{"micros":1,"calls":[]},"clean_ready",{"micros":0,"calls":[]}]}]}] (Session ID: 7d25dbb52e04e37749eaa08c37db67e8).
2022-10-02 14:27:33,619 INFO: 目前登入身份：神奇海螺#3847
2022-10-02 14:42:00,645 INFO: wawa的n out 9又4分之8.7月台[123是什麼敷衍的名字]
2022-10-02 14:42:00,645 INFO: Connecting to voice...
2022-10-02 14:42:00,646 INFO: Starting voice handshake... (connection attempt 1)
2022-10-02 14:42:01,011 INFO: Voice handshake complete. Endpoint found hongkong8036.discord.media
2022-10-02 14:42:01,870 INFO: selected the voice protocol for use (xsalsa20_poly1305_lite)
2022-10-02 14:42:02,038 INFO: received secret key for voice connection
2022-10-02 14:42:03,203 INFO: wawa的n in 9又4分之8.7月台[123是什麼敷衍的名字]
2022-10-02 14:42:04,027 INFO: Preparing to terminate ffmpeg process 1420.
2022-10-02 14:42:04,028 INFO: ffmpeg process 1420 successfully terminated with return code of 0.
2022-10-02 14:42:07,256 INFO: Preparing to terminate ffmpeg process 1430.
2022-10-02 14:42:07,257 INFO: ffmpeg process 1430 successfully terminated with return code of 0.
2022-10-02 14:42:09,876 INFO: Preparing to terminate ffmpeg process 1440.
2022-10-02 14:42:09,876 INFO: ffmpeg process 1440 successfully terminated with return code of 0.
2022-10-02 14:42:10,942 INFO: The voice handshake is being terminated for Channel ID 728631391809437746 (Guild ID 428109526550708234)
2022-10-02 14:42:10,943 INFO: Disconnecting from voice normally, close code 1000.
2022-10-02 15:19:07,950 INFO: BunnyplayGG out 9又4分之8.7月台[123是什麼敷衍的名字]
2022-10-02 15:19:07,950 INFO: Connecting to voice...
2022-10-02 15:19:07,950 INFO: Starting voice handshake... (connection attempt 1)
2022-10-02 15:19:08,250 INFO: Voice handshake complete. Endpoint found hongkong8036.discord.media
2022-10-02 15:19:09,136 INFO: selected the voice protocol for use (xsalsa20_poly1305_lite)
2022-10-02 15:19:09,314 INFO: received secret key for voice connection
2022-10-02 15:19:11,685 INFO: Preparing to terminate ffmpeg process 1489.
2022-10-02 15:19:11,687 INFO: ffmpeg process 1489 successfully terminated with return code of 0.
2022-10-02 15:19:12,736 INFO: The voice handshake is being terminated for Channel ID 728631391809437746 (Guild ID 428109526550708234)
2022-10-02 15:19:12,736 INFO: Disconnecting from voice normally, close code 1000.
2022-10-02 17:25:53,932 INFO: MaiMai的Pool out 9又4分之8.7月台[123是什麼敷衍的名字]
2022-10-02 17:25:53,933 INFO: Connecting to voice...
2022-10-02 17:25:53,933 INFO: Starting voice handshake... (connection attempt 1)
2022-10-02 17:25:54,223 INFO: Voice handshake complete. Endpoint found hongkong8036.discord.media
2022-10-02 17:25:55,088 INFO: selected the voice protocol for use (xsalsa20_poly1305_lite)
2022-10-02 17:25:55,258 INFO: received secret key for voice connection
2022-10-02 17:25:57,370 INFO: Preparing to terminate ffmpeg process 1690.
2022-10-02 17:25:57,372 INFO: ffmpeg process 1690 successfully terminated with return code of 0.
2022-10-02 17:25:58,379 INFO: The voice handshake is being terminated for Channel ID 728631391809437746 (Guild ID 428109526550708234)
2022-10-02 17:25:58,380 INFO: Disconnecting from voice normally, close code 1000.
2022-10-02 17:27:19,343 INFO: wawa的n out 9又4分之8.7月台[123是什麼敷衍的名字]
2022-10-02 17:27:19,344 INFO: Connecting to voice...
2022-10-02 17:27:19,344 INFO: Starting voice handshake... (connection attempt 1)
2022-10-02 17:27:19,620 INFO: Voice handshake complete. Endpoint found hongkong8036.discord.media
2022-10-02 17:27:19,814 ERROR: Exception occurred during Voice Protocol voice server update handler
Traceback (most recent call last):
  File "/opt/virtualenvs/python3/lib/python3.8/site-packages/discord/state.py", line 102, in logging_coroutine
    await coroutine
  File "/opt/virtualenvs/python3/lib/python3.8/site-packages/discord/voice_client.py", line 295, in on_voice_server_update
    await self.ws.close(4000)
AttributeError: 'NoneType' object has no attribute 'close'
2022-10-02 17:27:20,464 INFO: selected the voice protocol for use (xsalsa20_poly1305_lite)
2022-10-02 17:27:20,631 INFO: received secret key for voice connection
2022-10-02 17:27:21,534 INFO: 神奇海螺 in 9又4分之8.7月台[123是什麼敷衍的名字]
2022-10-02 17:27:23,909 INFO: Preparing to terminate ffmpeg process 1701.
2022-10-02 17:27:23,910 INFO: ffmpeg process 1701 successfully terminated with return code of 0.
2022-10-02 17:27:26,950 INFO: Preparing to terminate ffmpeg process 1711.
2022-10-02 17:27:26,950 INFO: ffmpeg process 1711 successfully terminated with return code of 0.
2022-10-02 17:27:30,844 INFO: Preparing to terminate ffmpeg process 1721.
2022-10-02 17:27:30,845 INFO: ffmpeg process 1721 successfully terminated with return code of 0.
2022-10-02 17:27:33,511 INFO: Preparing to terminate ffmpeg process 1731.
2022-10-02 17:27:33,512 INFO: ffmpeg process 1731 successfully terminated with return code of 0.
2022-10-02 17:27:34,521 INFO: The voice handshake is being terminated for Channel ID 728631391809437746 (Guild ID 428109526550708234)
2022-10-02 17:27:34,522 INFO: Disconnecting from voice normally, close code 1000.
2022-10-02 17:27:35,231 INFO: 貓嗷嗚飄飄大仙 out 9又4分之8.7月台[123是什麼敷衍的名字]
2022-10-02 17:27:35,231 INFO: Connecting to voice...
2022-10-02 17:27:35,231 INFO: Starting voice handshake... (connection attempt 1)
2022-10-02 17:27:35,603 INFO: Voice handshake complete. Endpoint found hongkong8036.discord.media
2022-10-02 17:27:36,458 INFO: selected the voice protocol for use (xsalsa20_poly1305_lite)
2022-10-02 17:27:36,632 INFO: received secret key for voice connection
2022-10-02 17:27:39,180 INFO: Preparing to terminate ffmpeg process 1742.
2022-10-02 17:27:39,181 INFO: ffmpeg process 1742 successfully terminated with return code of 0.
2022-10-02 17:27:43,516 INFO: Preparing to terminate ffmpeg process 1752.
2022-10-02 17:27:43,517 INFO: ffmpeg process 1752 successfully terminated with return code of 0.
2022-10-02 17:27:44,569 INFO: The voice handshake is being terminated for Channel ID 728631391809437746 (Guild ID 428109526550708234)
2022-10-02 17:27:44,570 INFO: Disconnecting from voice normally, close code 1000.
2022-10-02 17:29:34,472 INFO: Got a request to RESUME the websocket.
2022-10-02 17:29:34,523 ERROR: Attempting a reconnect in 0.23s
Traceback (most recent call last):
  File "/opt/virtualenvs/python3/lib/python3.8/site-packages/discord/http.py", line 967, in get_gateway
    data = await self.request(Route('GET', '/gateway'))
  File "/opt/virtualenvs/python3/lib/python3.8/site-packages/discord/http.py", line 216, in request
    raise HTTPException(r, data)
discord.errors.HTTPException: 429 Too Many Requests (error code: 0): You are being blocked from accessing our API temporarily due to exceeding our rate limits frequently. Please read our docs at https://discord.com/developers/docs/topics/rate-limits to prevent this moving forward.

The above exception was the direct cause of the following exception:

Traceback (most recent call last):
  File "/opt/virtualenvs/python3/lib/python3.8/site-packages/discord/client.py", line 563, in connect
    self.ws = await asyncio.wait_for(coro, timeout=60.0)
  File "/usr/lib/python3.8/asyncio/tasks.py", line 494, in wait_for
    return fut.result()
  File "/opt/virtualenvs/python3/lib/python3.8/site-packages/discord/gateway.py", line 305, in from_client
    gateway = gateway or await client.http.get_gateway()
  File "/opt/virtualenvs/python3/lib/python3.8/site-packages/discord/http.py", line 969, in get_gateway
    raise GatewayNotFound() from exc
discord.errors.GatewayNotFound: The gateway to connect to discord was not found.
2022-10-02 17:29:34,791 ERROR: Attempting a reconnect in 2.75s
Traceback (most recent call last):
  File "/opt/virtualenvs/python3/lib/python3.8/site-packages/discord/http.py", line 967, in get_gateway
    data = await self.request(Route('GET', '/gateway'))
  File "/opt/virtualenvs/python3/lib/python3.8/site-packages/discord/http.py", line 216, in request
    raise HTTPException(r, data)
discord.errors.HTTPException: 429 Too Many Requests (error code: 0): You are being blocked from accessing our API temporarily due to exceeding our rate limits frequently. Please read our docs at https://discord.com/developers/docs/topics/rate-limits to prevent this moving forward.

The above exception was the direct cause of the following exception:

Traceback (most recent call last):
  File "/opt/virtualenvs/python3/lib/python3.8/site-packages/discord/client.py", line 563, in connect
    self.ws = await asyncio.wait_for(coro, timeout=60.0)
  File "/usr/lib/python3.8/asyncio/tasks.py", line 494, in wait_for
    return fut.result()
  File "/opt/virtualenvs/python3/lib/python3.8/site-packages/discord/gateway.py", line 305, in from_client
    gateway = gateway or await client.http.get_gateway()
  File "/opt/virtualenvs/python3/lib/python3.8/site-packages/discord/http.py", line 969, in get_gateway
    raise GatewayNotFound() from exc
discord.errors.GatewayNotFound: The gateway to connect to discord was not found.
2022-10-02 17:29:37,583 ERROR: Attempting a reconnect in 0.55s
Traceback (most recent call last):
  File "/opt/virtualenvs/python3/lib/python3.8/site-packages/discord/http.py", line 967, in get_gateway
    data = await self.request(Route('GET', '/gateway'))
  File "/opt/virtualenvs/python3/lib/python3.8/site-packages/discord/http.py", line 216, in request
    raise HTTPException(r, data)
discord.errors.HTTPException: 429 Too Many Requests (error code: 0): You are being blocked from accessing our API temporarily due to exceeding our rate limits frequently. Please read our docs at https://discord.com/developers/docs/topics/rate-limits to prevent this moving forward.

The above exception was the direct cause of the following exception:

Traceback (most recent call last):
  File "/opt/virtualenvs/python3/lib/python3.8/site-packages/discord/client.py", line 563, in connect
    self.ws = await asyncio.wait_for(coro, timeout=60.0)
  File "/usr/lib/python3.8/asyncio/tasks.py", line 494, in wait_for
    return fut.result()
  File "/opt/virtualenvs/python3/lib/python3.8/site-packages/discord/gateway.py", line 305, in from_client
    gateway = gateway or await client.http.get_gateway()
  File "/opt/virtualenvs/python3/lib/python3.8/site-packages/discord/http.py", line 969, in get_gateway
    raise GatewayNotFound() from exc
discord.errors.GatewayNotFound: The gateway to connect to discord was not found.
2022-10-02 17:29:38,175 ERROR: Attempting a reconnect in 5.12s
Traceback (most recent call last):
  File "/opt/virtualenvs/python3/lib/python3.8/site-packages/discord/http.py", line 967, in get_gateway
    data = await self.request(Route('GET', '/gateway'))
  File "/opt/virtualenvs/python3/lib/python3.8/site-packages/discord/http.py", line 216, in request
    raise HTTPException(r, data)
discord.errors.HTTPException: 429 Too Many Requests (error code: 0): You are being blocked from accessing our API temporarily due to exceeding our rate limits frequently. Please read our docs at https://discord.com/developers/docs/topics/rate-limits to prevent this moving forward.

The above exception was the direct cause of the following exception:

Traceback (most recent call last):
  File "/opt/virtualenvs/python3/lib/python3.8/site-packages/discord/client.py", line 563, in connect
    self.ws = await asyncio.wait_for(coro, timeout=60.0)
  File "/usr/lib/python3.8/asyncio/tasks.py", line 494, in wait_for
    return fut.result()
  File "/opt/virtualenvs/python3/lib/python3.8/site-packages/discord/gateway.py", line 305, in from_client
    gateway = gateway or await client.http.get_gateway()
  File "/opt/virtualenvs/python3/lib/python3.8/site-packages/discord/http.py", line 969, in get_gateway
    raise GatewayNotFound() from exc
discord.errors.GatewayNotFound: The gateway to connect to discord was not found.
2022-10-02 17:29:43,336 ERROR: Attempting a reconnect in 24.66s
Traceback (most recent call last):
  File "/opt/virtualenvs/python3/lib/python3.8/site-packages/discord/http.py", line 967, in get_gateway
    data = await self.request(Route('GET', '/gateway'))
  File "/opt/virtualenvs/python3/lib/python3.8/site-packages/discord/http.py", line 216, in request
    raise HTTPException(r, data)
discord.errors.HTTPException: 429 Too Many Requests (error code: 0): You are being blocked from accessing our API temporarily due to exceeding our rate limits frequently. Please read our docs at https://discord.com/developers/docs/topics/rate-limits to prevent this moving forward.

The above exception was the direct cause of the following exception:

Traceback (most recent call last):
  File "/opt/virtualenvs/python3/lib/python3.8/site-packages/discord/client.py", line 563, in connect
    self.ws = await asyncio.wait_for(coro, timeout=60.0)
  File "/usr/lib/python3.8/asyncio/tasks.py", line 494, in wait_for
    return fut.result()
  File "/opt/virtualenvs/python3/lib/python3.8/site-packages/discord/gateway.py", line 305, in from_client
    gateway = gateway or await client.http.get_gateway()
  File "/opt/virtualenvs/python3/lib/python3.8/site-packages/discord/http.py", line 969, in get_gateway
    raise GatewayNotFound() from exc
discord.errors.GatewayNotFound: The gateway to connect to discord was not found.
2022-10-02 17:30:08,076 ERROR: Attempting a reconnect in 42.24s
Traceback (most recent call last):
  File "/opt/virtualenvs/python3/lib/python3.8/site-packages/discord/http.py", line 967, in get_gateway
    data = await self.request(Route('GET', '/gateway'))
  File "/opt/virtualenvs/python3/lib/python3.8/site-packages/discord/http.py", line 216, in request
    raise HTTPException(r, data)
discord.errors.HTTPException: 429 Too Many Requests (error code: 0): You are being blocked from accessing our API temporarily due to exceeding our rate limits frequently. Please read our docs at https://discord.com/developers/docs/topics/rate-limits to prevent this moving forward.

The above exception was the direct cause of the following exception:

Traceback (most recent call last):
  File "/opt/virtualenvs/python3/lib/python3.8/site-packages/discord/client.py", line 563, in connect
    self.ws = await asyncio.wait_for(coro, timeout=60.0)
  File "/usr/lib/python3.8/asyncio/tasks.py", line 494, in wait_for
    return fut.result()
  File "/opt/virtualenvs/python3/lib/python3.8/site-packages/discord/gateway.py", line 305, in from_client
    gateway = gateway or await client.http.get_gateway()
  File "/opt/virtualenvs/python3/lib/python3.8/site-packages/discord/http.py", line 969, in get_gateway
    raise GatewayNotFound() from exc
discord.errors.GatewayNotFound: The gateway to connect to discord was not found.
2022-10-02 17:30:50,427 ERROR: Attempting a reconnect in 123.41s
Traceback (most recent call last):
  File "/opt/virtualenvs/python3/lib/python3.8/site-packages/discord/http.py", line 967, in get_gateway
    data = await self.request(Route('GET', '/gateway'))
  File "/opt/virtualenvs/python3/lib/python3.8/site-packages/discord/http.py", line 216, in request
    raise HTTPException(r, data)
discord.errors.HTTPException: 429 Too Many Requests (error code: 0): You are being blocked from accessing our API temporarily due to exceeding our rate limits frequently. Please read our docs at https://discord.com/developers/docs/topics/rate-limits to prevent this moving forward.

The above exception was the direct cause of the following exception:

Traceback (most recent call last):
  File "/opt/virtualenvs/python3/lib/python3.8/site-packages/discord/client.py", line 563, in connect
    self.ws = await asyncio.wait_for(coro, timeout=60.0)
  File "/usr/lib/python3.8/asyncio/tasks.py", line 494, in wait_for
    return fut.result()
  File "/opt/virtualenvs/python3/lib/python3.8/site-packages/discord/gateway.py", line 305, in from_client
    gateway = gateway or await client.http.get_gateway()
  File "/opt/virtualenvs/python3/lib/python3.8/site-packages/discord/http.py", line 969, in get_gateway
    raise GatewayNotFound() from exc
discord.errors.GatewayNotFound: The gateway to connect to discord was not found.
2022-10-02 17:32:53,988 ERROR: Attempting a reconnect in 61.55s
Traceback (most recent call last):
  File "/opt/virtualenvs/python3/lib/python3.8/site-packages/discord/http.py", line 967, in get_gateway
    data = await self.request(Route('GET', '/gateway'))
  File "/opt/virtualenvs/python3/lib/python3.8/site-packages/discord/http.py", line 216, in request
    raise HTTPException(r, data)
discord.errors.HTTPException: 429 Too Many Requests (error code: 0): You are being blocked from accessing our API temporarily due to exceeding our rate limits frequently. Please read our docs at https://discord.com/developers/docs/topics/rate-limits to prevent this moving forward.

The above exception was the direct cause of the following exception:

Traceback (most recent call last):
  File "/opt/virtualenvs/python3/lib/python3.8/site-packages/discord/client.py", line 563, in connect
    self.ws = await asyncio.wait_for(coro, timeout=60.0)
  File "/usr/lib/python3.8/asyncio/tasks.py", line 494, in wait_for
    return fut.result()
  File "/opt/virtualenvs/python3/lib/python3.8/site-packages/discord/gateway.py", line 305, in from_client
    gateway = gateway or await client.http.get_gateway()
  File "/opt/virtualenvs/python3/lib/python3.8/site-packages/discord/http.py", line 969, in get_gateway
    raise GatewayNotFound() from exc
discord.errors.GatewayNotFound: The gateway to connect to discord was not found.
2022-10-02 17:33:55,651 ERROR: Attempting a reconnect in 239.36s
Traceback (most recent call last):
  File "/opt/virtualenvs/python3/lib/python3.8/site-packages/discord/http.py", line 967, in get_gateway
    data = await self.request(Route('GET', '/gateway'))
  File "/opt/virtualenvs/python3/lib/python3.8/site-packages/discord/http.py", line 216, in request
    raise HTTPException(r, data)
discord.errors.HTTPException: 429 Too Many Requests (error code: 0): You are being blocked from accessing our API temporarily due to exceeding our rate limits frequently. Please read our docs at https://discord.com/developers/docs/topics/rate-limits to prevent this moving forward.

The above exception was the direct cause of the following exception:

Traceback (most recent call last):
  File "/opt/virtualenvs/python3/lib/python3.8/site-packages/discord/client.py", line 563, in connect
    self.ws = await asyncio.wait_for(coro, timeout=60.0)
  File "/usr/lib/python3.8/asyncio/tasks.py", line 494, in wait_for
    return fut.result()
  File "/opt/virtualenvs/python3/lib/python3.8/site-packages/discord/gateway.py", line 305, in from_client
    gateway = gateway or await client.http.get_gateway()
  File "/opt/virtualenvs/python3/lib/python3.8/site-packages/discord/http.py", line 969, in get_gateway
    raise GatewayNotFound() from exc
discord.errors.GatewayNotFound: The gateway to connect to discord was not found.
2022-10-02 17:37:55,191 ERROR: Attempting a reconnect in 308.59s
Traceback (most recent call last):
  File "/opt/virtualenvs/python3/lib/python3.8/site-packages/discord/http.py", line 967, in get_gateway
    data = await self.request(Route('GET', '/gateway'))
  File "/opt/virtualenvs/python3/lib/python3.8/site-packages/discord/http.py", line 216, in request
    raise HTTPException(r, data)
discord.errors.HTTPException: 429 Too Many Requests (error code: 0): You are being blocked from accessing our API temporarily due to exceeding our rate limits frequently. Please read our docs at https://discord.com/developers/docs/topics/rate-limits to prevent this moving forward.

The above exception was the direct cause of the following exception:

Traceback (most recent call last):
  File "/opt/virtualenvs/python3/lib/python3.8/site-packages/discord/client.py", line 563, in connect
    self.ws = await asyncio.wait_for(coro, timeout=60.0)
  File "/usr/lib/python3.8/asyncio/tasks.py", line 494, in wait_for
    return fut.result()
  File "/opt/virtualenvs/python3/lib/python3.8/site-packages/discord/gateway.py", line 305, in from_client
    gateway = gateway or await client.http.get_gateway()
  File "/opt/virtualenvs/python3/lib/python3.8/site-packages/discord/http.py", line 969, in get_gateway
    raise GatewayNotFound() from exc
discord.errors.GatewayNotFound: The gateway to connect to discord was not found.
2022-10-02 17:43:03,936 ERROR: Attempting a reconnect in 952.34s
Traceback (most recent call last):
  File "/opt/virtualenvs/python3/lib/python3.8/site-packages/discord/http.py", line 967, in get_gateway
    data = await self.request(Route('GET', '/gateway'))
  File "/opt/virtualenvs/python3/lib/python3.8/site-packages/discord/http.py", line 216, in request
    raise HTTPException(r, data)
discord.errors.HTTPException: 429 Too Many Requests (error code: 0): You are being blocked from accessing our API temporarily due to exceeding our rate limits frequently. Please read our docs at https://discord.com/developers/docs/topics/rate-limits to prevent this moving forward.

The above exception was the direct cause of the following exception:

Traceback (most recent call last):
  File "/opt/virtualenvs/python3/lib/python3.8/site-packages/discord/client.py", line 563, in connect
    self.ws = await asyncio.wait_for(coro, timeout=60.0)
  File "/usr/lib/python3.8/asyncio/tasks.py", line 494, in wait_for
    return fut.result()
  File "/opt/virtualenvs/python3/lib/python3.8/site-packages/discord/gateway.py", line 305, in from_client
    gateway = gateway or await client.http.get_gateway()
  File "/opt/virtualenvs/python3/lib/python3.8/site-packages/discord/http.py", line 969, in get_gateway
    raise GatewayNotFound() from exc
discord.errors.GatewayNotFound: The gateway to connect to discord was not found.
2022-10-02 17:58:56,432 ERROR: Attempting a reconnect in 949.31s
Traceback (most recent call last):
  File "/opt/virtualenvs/python3/lib/python3.8/site-packages/discord/http.py", line 967, in get_gateway
    data = await self.request(Route('GET', '/gateway'))
  File "/opt/virtualenvs/python3/lib/python3.8/site-packages/discord/http.py", line 216, in request
    raise HTTPException(r, data)
discord.errors.HTTPException: 429 Too Many Requests (error code: 0): You are being blocked from accessing our API temporarily due to exceeding our rate limits frequently. Please read our docs at https://discord.com/developers/docs/topics/rate-limits to prevent this moving forward.

The above exception was the direct cause of the following exception:

Traceback (most recent call last):
  File "/opt/virtualenvs/python3/lib/python3.8/site-packages/discord/client.py", line 563, in connect
    self.ws = await asyncio.wait_for(coro, timeout=60.0)
  File "/usr/lib/python3.8/asyncio/tasks.py", line 494, in wait_for
    return fut.result()
  File "/opt/virtualenvs/python3/lib/python3.8/site-packages/discord/gateway.py", line 305, in from_client
    gateway = gateway or await client.http.get_gateway()
  File "/opt/virtualenvs/python3/lib/python3.8/site-packages/discord/http.py", line 969, in get_gateway
    raise GatewayNotFound() from exc
discord.errors.GatewayNotFound: The gateway to connect to discord was not found.
2022-10-02 18:14:46,029 INFO: Shard ID None has sent the RESUME payload.
2022-10-02 18:14:46,112 INFO: Shard ID None session has been invalidated.
2022-10-02 18:14:46,196 INFO: Got a request to IDENTIFY the websocket.
2022-10-02 18:14:51,343 INFO: Shard ID None has sent the IDENTIFY payload.
2022-10-02 18:14:51,526 INFO: Shard ID None has connected to Gateway: ["gateway-prd-us-east1-c-11zr",{"micros":95565,"calls":["id_created",{"micros":1996,"calls":[]},"session_lookup_time",{"micros":622,"calls":[]},"session_lookup_finished",{"micros":14,"calls":[]},"discord-sessions-blue-prd-2-194",{"micros":91765,"calls":["start_session",{"micros":72850,"calls":["discord-api-7948bc9d7b-qj42w",{"micros":67761,"calls":["get_user",{"micros":16024},"get_guilds",{"micros":6285},"send_scheduled_deletion_message",{"micros":31},"guild_join_requests",{"micros":1220},"authorized_ip_coro",{"micros":39}]}]},"starting_guild_connect",{"micros":52,"calls":[]},"presence_started",{"micros":1637,"calls":[]},"guilds_started",{"micros":191,"calls":[]},"guilds_connect",{"micros":2,"calls":[]},"presence_connect",{"micros":16981,"calls":[]},"connect_finished",{"micros":16987,"calls":[]},"build_ready",{"micros":45,"calls":[]},"optimize_ready",{"micros":0,"calls":[]},"split_ready",{"micros":1,"calls":[]},"clean_ready",{"micros":0,"calls":[]}]}]}] (Session ID: e3fae4f38394d60a3c9627f1af6d7f0f).
2022-10-02 18:14:53,602 INFO: 目前登入身份：神奇海螺#3847
2022-10-02 19:33:02,490 INFO: Got a request to RESUME the websocket.
2022-10-02 19:33:02,710 INFO: Shard ID None has sent the RESUME payload.
2022-10-02 19:33:02,793 INFO: Shard ID None has successfully RESUMED session e3fae4f38394d60a3c9627f1af6d7f0f under trace ["gateway-prd-us-east1-c-jsqk",{"micros":816,"calls":["id_created",{"micros":0,"calls":[]},"session_lookup_time",{"micros":344,"calls":[]},"session_lookup_finished",{"micros":13,"calls":[]},"discord-sessions-blue-prd-2-194",{"micros":20}]}].
2022-10-02 20:31:38,098 INFO: Got a request to RESUME the websocket.
2022-10-02 20:31:38,143 ERROR: Attempting a reconnect in 0.51s
Traceback (most recent call last):
  File "/opt/virtualenvs/python3/lib/python3.8/site-packages/discord/http.py", line 967, in get_gateway
    data = await self.request(Route('GET', '/gateway'))
  File "/opt/virtualenvs/python3/lib/python3.8/site-packages/discord/http.py", line 216, in request
    raise HTTPException(r, data)
discord.errors.HTTPException: 429 Too Many Requests (error code: 0): You are being blocked from accessing our API temporarily due to exceeding our rate limits frequently. Please read our docs at https://discord.com/developers/docs/topics/rate-limits to prevent this moving forward.

The above exception was the direct cause of the following exception:

Traceback (most recent call last):
  File "/opt/virtualenvs/python3/lib/python3.8/site-packages/discord/client.py", line 563, in connect
    self.ws = await asyncio.wait_for(coro, timeout=60.0)
  File "/usr/lib/python3.8/asyncio/tasks.py", line 494, in wait_for
    return fut.result()
  File "/opt/virtualenvs/python3/lib/python3.8/site-packages/discord/gateway.py", line 305, in from_client
    gateway = gateway or await client.http.get_gateway()
  File "/opt/virtualenvs/python3/lib/python3.8/site-packages/discord/http.py", line 969, in get_gateway
    raise GatewayNotFound() from exc
discord.errors.GatewayNotFound: The gateway to connect to discord was not found.
2022-10-02 20:31:38,693 ERROR: Attempting a reconnect in 1.88s
Traceback (most recent call last):
  File "/opt/virtualenvs/python3/lib/python3.8/site-packages/discord/http.py", line 967, in get_gateway
    data = await self.request(Route('GET', '/gateway'))
  File "/opt/virtualenvs/python3/lib/python3.8/site-packages/discord/http.py", line 216, in request
    raise HTTPException(r, data)
discord.errors.HTTPException: 429 Too Many Requests (error code: 0): You are being blocked from accessing our API temporarily due to exceeding our rate limits frequently. Please read our docs at https://discord.com/developers/docs/topics/rate-limits to prevent this moving forward.

The above exception was the direct cause of the following exception:

Traceback (most recent call last):
  File "/opt/virtualenvs/python3/lib/python3.8/site-packages/discord/client.py", line 563, in connect
    self.ws = await asyncio.wait_for(coro, timeout=60.0)
  File "/usr/lib/python3.8/asyncio/tasks.py", line 494, in wait_for
    return fut.result()
  File "/opt/virtualenvs/python3/lib/python3.8/site-packages/discord/gateway.py", line 305, in from_client
    gateway = gateway or await client.http.get_gateway()
  File "/opt/virtualenvs/python3/lib/python3.8/site-packages/discord/http.py", line 969, in get_gateway
    raise GatewayNotFound() from exc
discord.errors.GatewayNotFound: The gateway to connect to discord was not found.
2022-10-02 20:31:40,615 ERROR: Attempting a reconnect in 3.51s
Traceback (most recent call last):
  File "/opt/virtualenvs/python3/lib/python3.8/site-packages/discord/http.py", line 967, in get_gateway
    data = await self.request(Route('GET', '/gateway'))
  File "/opt/virtualenvs/python3/lib/python3.8/site-packages/discord/http.py", line 216, in request
    raise HTTPException(r, data)
discord.errors.HTTPException: 429 Too Many Requests (error code: 0): You are being blocked from accessing our API temporarily due to exceeding our rate limits frequently. Please read our docs at https://discord.com/developers/docs/topics/rate-limits to prevent this moving forward.

The above exception was the direct cause of the following exception:

Traceback (most recent call last):
  File "/opt/virtualenvs/python3/lib/python3.8/site-packages/discord/client.py", line 563, in connect
    self.ws = await asyncio.wait_for(coro, timeout=60.0)
  File "/usr/lib/python3.8/asyncio/tasks.py", line 494, in wait_for
    return fut.result()
  File "/opt/virtualenvs/python3/lib/python3.8/site-packages/discord/gateway.py", line 305, in from_client
    gateway = gateway or await client.http.get_gateway()
  File "/opt/virtualenvs/python3/lib/python3.8/site-packages/discord/http.py", line 969, in get_gateway
    raise GatewayNotFound() from exc
discord.errors.GatewayNotFound: The gateway to connect to discord was not found.
2022-10-02 20:31:44,174 ERROR: Attempting a reconnect in 9.20s
Traceback (most recent call last):
  File "/opt/virtualenvs/python3/lib/python3.8/site-packages/discord/http.py", line 967, in get_gateway
    data = await self.request(Route('GET', '/gateway'))
  File "/opt/virtualenvs/python3/lib/python3.8/site-packages/discord/http.py", line 216, in request
    raise HTTPException(r, data)
discord.errors.HTTPException: 429 Too Many Requests (error code: 0): You are being blocked from accessing our API temporarily due to exceeding our rate limits frequently. Please read our docs at https://discord.com/developers/docs/topics/rate-limits to prevent this moving forward.

The above exception was the direct cause of the following exception:

Traceback (most recent call last):
  File "/opt/virtualenvs/python3/lib/python3.8/site-packages/discord/client.py", line 563, in connect
    self.ws = await asyncio.wait_for(coro, timeout=60.0)
  File "/usr/lib/python3.8/asyncio/tasks.py", line 494, in wait_for
    return fut.result()
  File "/opt/virtualenvs/python3/lib/python3.8/site-packages/discord/gateway.py", line 305, in from_client
    gateway = gateway or await client.http.get_gateway()
  File "/opt/virtualenvs/python3/lib/python3.8/site-packages/discord/http.py", line 969, in get_gateway
    raise GatewayNotFound() from exc
discord.errors.GatewayNotFound: The gateway to connect to discord was not found.
2022-10-02 20:31:53,452 ERROR: Attempting a reconnect in 30.93s
Traceback (most recent call last):
  File "/opt/virtualenvs/python3/lib/python3.8/site-packages/discord/http.py", line 967, in get_gateway
    data = await self.request(Route('GET', '/gateway'))
  File "/opt/virtualenvs/python3/lib/python3.8/site-packages/discord/http.py", line 216, in request
    raise HTTPException(r, data)
discord.errors.HTTPException: 429 Too Many Requests (error code: 0): You are being blocked from accessing our API temporarily due to exceeding our rate limits frequently. Please read our docs at https://discord.com/developers/docs/topics/rate-limits to prevent this moving forward.

The above exception was the direct cause of the following exception:

Traceback (most recent call last):
  File "/opt/virtualenvs/python3/lib/python3.8/site-packages/discord/client.py", line 563, in connect
    self.ws = await asyncio.wait_for(coro, timeout=60.0)
  File "/usr/lib/python3.8/asyncio/tasks.py", line 494, in wait_for
    return fut.result()
  File "/opt/virtualenvs/python3/lib/python3.8/site-packages/discord/gateway.py", line 305, in from_client
    gateway = gateway or await client.http.get_gateway()
  File "/opt/virtualenvs/python3/lib/python3.8/site-packages/discord/http.py", line 969, in get_gateway
    raise GatewayNotFound() from exc
discord.errors.GatewayNotFound: The gateway to connect to discord was not found.
2022-10-02 20:32:24,474 ERROR: Attempting a reconnect in 39.95s
Traceback (most recent call last):
  File "/opt/virtualenvs/python3/lib/python3.8/site-packages/discord/http.py", line 967, in get_gateway
    data = await self.request(Route('GET', '/gateway'))
  File "/opt/virtualenvs/python3/lib/python3.8/site-packages/discord/http.py", line 216, in request
    raise HTTPException(r, data)
discord.errors.HTTPException: 429 Too Many Requests (error code: 0): You are being blocked from accessing our API temporarily due to exceeding our rate limits frequently. Please read our docs at https://discord.com/developers/docs/topics/rate-limits to prevent this moving forward.

The above exception was the direct cause of the following exception:

Traceback (most recent call last):
  File "/opt/virtualenvs/python3/lib/python3.8/site-packages/discord/client.py", line 563, in connect
    self.ws = await asyncio.wait_for(coro, timeout=60.0)
  File "/usr/lib/python3.8/asyncio/tasks.py", line 494, in wait_for
    return fut.result()
  File "/opt/virtualenvs/python3/lib/python3.8/site-packages/discord/gateway.py", line 305, in from_client
    gateway = gateway or await client.http.get_gateway()
  File "/opt/virtualenvs/python3/lib/python3.8/site-packages/discord/http.py", line 969, in get_gateway
    raise GatewayNotFound() from exc
discord.errors.GatewayNotFound: The gateway to connect to discord was not found.
2022-10-02 20:33:04,523 ERROR: Attempting a reconnect in 11.51s
Traceback (most recent call last):
  File "/opt/virtualenvs/python3/lib/python3.8/site-packages/discord/http.py", line 967, in get_gateway
    data = await self.request(Route('GET', '/gateway'))
  File "/opt/virtualenvs/python3/lib/python3.8/site-packages/discord/http.py", line 216, in request
    raise HTTPException(r, data)
discord.errors.HTTPException: 429 Too Many Requests (error code: 0): You are being blocked from accessing our API temporarily due to exceeding our rate limits frequently. Please read our docs at https://discord.com/developers/docs/topics/rate-limits to prevent this moving forward.

The above exception was the direct cause of the following exception:

Traceback (most recent call last):
  File "/opt/virtualenvs/python3/lib/python3.8/site-packages/discord/client.py", line 563, in connect
    self.ws = await asyncio.wait_for(coro, timeout=60.0)
  File "/usr/lib/python3.8/asyncio/tasks.py", line 494, in wait_for
    return fut.result()
  File "/opt/virtualenvs/python3/lib/python3.8/site-packages/discord/gateway.py", line 305, in from_client
    gateway = gateway or await client.http.get_gateway()
  File "/opt/virtualenvs/python3/lib/python3.8/site-packages/discord/http.py", line 969, in get_gateway
    raise GatewayNotFound() from exc
discord.errors.GatewayNotFound: The gateway to connect to discord was not found.
2022-10-02 20:33:16,087 ERROR: Attempting a reconnect in 125.96s
Traceback (most recent call last):
  File "/opt/virtualenvs/python3/lib/python3.8/site-packages/discord/http.py", line 967, in get_gateway
    data = await self.request(Route('GET', '/gateway'))
  File "/opt/virtualenvs/python3/lib/python3.8/site-packages/discord/http.py", line 216, in request
    raise HTTPException(r, data)
discord.errors.HTTPException: 429 Too Many Requests (error code: 0): You are being blocked from accessing our API temporarily due to exceeding our rate limits frequently. Please read our docs at https://discord.com/developers/docs/topics/rate-limits to prevent this moving forward.

The above exception was the direct cause of the following exception:

Traceback (most recent call last):
  File "/opt/virtualenvs/python3/lib/python3.8/site-packages/discord/client.py", line 563, in connect
    self.ws = await asyncio.wait_for(coro, timeout=60.0)
  File "/usr/lib/python3.8/asyncio/tasks.py", line 494, in wait_for
    return fut.result()
  File "/opt/virtualenvs/python3/lib/python3.8/site-packages/discord/gateway.py", line 305, in from_client
    gateway = gateway or await client.http.get_gateway()
  File "/opt/virtualenvs/python3/lib/python3.8/site-packages/discord/http.py", line 969, in get_gateway
    raise GatewayNotFound() from exc
discord.errors.GatewayNotFound: The gateway to connect to discord was not found.
2022-10-02 20:35:22,199 ERROR: Attempting a reconnect in 499.30s
Traceback (most recent call last):
  File "/opt/virtualenvs/python3/lib/python3.8/site-packages/discord/http.py", line 967, in get_gateway
    data = await self.request(Route('GET', '/gateway'))
  File "/opt/virtualenvs/python3/lib/python3.8/site-packages/discord/http.py", line 216, in request
    raise HTTPException(r, data)
discord.errors.HTTPException: 429 Too Many Requests (error code: 0): You are being blocked from accessing our API temporarily due to exceeding our rate limits frequently. Please read our docs at https://discord.com/developers/docs/topics/rate-limits to prevent this moving forward.

The above exception was the direct cause of the following exception:

Traceback (most recent call last):
  File "/opt/virtualenvs/python3/lib/python3.8/site-packages/discord/client.py", line 563, in connect
    self.ws = await asyncio.wait_for(coro, timeout=60.0)
  File "/usr/lib/python3.8/asyncio/tasks.py", line 494, in wait_for
    return fut.result()
  File "/opt/virtualenvs/python3/lib/python3.8/site-packages/discord/gateway.py", line 305, in from_client
    gateway = gateway or await client.http.get_gateway()
  File "/opt/virtualenvs/python3/lib/python3.8/site-packages/discord/http.py", line 969, in get_gateway
    raise GatewayNotFound() from exc
discord.errors.GatewayNotFound: The gateway to connect to discord was not found.
2022-10-02 20:43:41,790 INFO: Shard ID None has sent the RESUME payload.
2022-10-02 20:43:41,873 INFO: Shard ID None session has been invalidated.
2022-10-02 20:43:41,957 INFO: Got a request to IDENTIFY the websocket.
2022-10-02 20:43:47,111 INFO: Shard ID None has sent the IDENTIFY payload.
2022-10-02 20:43:47,311 INFO: Shard ID None has connected to Gateway: ["gateway-prd-us-east1-b-0mrc",{"micros":116459,"calls":["id_created",{"micros":1152,"calls":[]},"session_lookup_time",{"micros":381,"calls":[]},"session_lookup_finished",{"micros":16,"calls":[]},"discord-sessions-blue-prd-2-165",{"micros":114590,"calls":["start_session",{"micros":46259,"calls":["discord-api-7948bc9d7b-vzjq4",{"micros":41062,"calls":["get_user",{"micros":11277},"get_guilds",{"micros":6407},"send_scheduled_deletion_message",{"micros":12},"guild_join_requests",{"micros":2},"authorized_ip_coro",{"micros":14}]}]},"starting_guild_connect",{"micros":31,"calls":[]},"presence_started",{"micros":32825,"calls":[]},"guilds_started",{"micros":138,"calls":[]},"guilds_connect",{"micros":2,"calls":[]},"presence_connect",{"micros":35308,"calls":[]},"connect_finished",{"micros":35314,"calls":[]},"build_ready",{"micros":20,"calls":[]},"optimize_ready",{"micros":0,"calls":[]},"split_ready",{"micros":1,"calls":[]},"clean_ready",{"micros":1,"calls":[]}]}]}] (Session ID: f4a85fcde9f8107e9392637d45e8aaa4).
2022-10-02 20:43:49,405 INFO: 目前登入身份：神奇海螺#3847
